Workbook

Sheet suspicious_values
A1: fluid | B1: ID | C1: date | D1: ON | E1: OFF | F1: expected | G1: consumed | H1: why suspicious? | I1: transcription good? | J1: Problem | K1: fix
A2: W | B2: 40 | C2: 9/17 | D2: 464.1 | E2: 493.7 | G2: -30.1 | H2: negative consumed | I2: yes | J2: suspect OFF weight should have been 393.7, not 493.7 | K2: yes
A3: W | B3: 44 | C3: 9/10 | D3: 449.8 | E3: 454.2 | G3: -4.65 | H3: negative consumed | I3: yes | J3: ?? Guessing OFF should have been 445.2 | K3: yes
A4: W | B4: 60 | C4: 8/04 | D4: 456.6 | E4: 468.3 | G4: -8.65 | H4: negative consumed | I4: no audio | J4: ?? Guessing ON should have been 465.6 | K4: yes
A5: W | B5: 48 | C5: 45873 | D5: 463.6 | E5: 426.1 | G5: 40.5 | H5: unusually high consumed | I5: no audio | J5: ?? Guessing OFF weight is actually ethanol bottle | K5: yes
A6: E | B6: 48 | C6: 45873 | D6: 438.7 | E6: 452.7 | G6: -11 | H6: negative consumed | I6: no audio | J6: ?? Guessing OFF weight is actually water bottle | K6: yes
A7: W | B7: 9 | C7: 45919 | D7: 454.9 | E7: 484 | G7: -29.45 | H7: negative consumed | I7: yes | J7: suspect OFF weight should have been 384, not 484 | K7: yes
A8: E | B8: 41 | C8: X | D8: 463.3 | E8: 468.2 | G8: -5.5 | H8: negative consumed | I8: yes
A9: E | B9: 3 | C9: AF | D9: 484.6 | E9: 477.3 | G9: =D9-E9 -> 7.3 | H9: negative consumed | I9: No | J9: On was actually 484.6 | K9: Yes
A10: E | B10: 8 | C10: AJ | D10: 467.8 | E10: 488.2 | G10: =D10-E10 -> -20.4 | H10: negative consumed | I10: Yes | J10: ?? Guessing Acciddentaly repeated 8 instead of 4 in off weight (488.2 -> 448.2) | K10: Yes
A11: W | B11: 24 | C11: AJ | D11: =water_ON!AJ24 -> 462.7 | E11: =water_OFF!AJ24 -> 445.1 | G11: =D11-E11 -> 17.6 | H11: Spoke row 28 (below) | I11: yes | J11: Not sure. Maybe just mispoke row? W_g value actually looks normal | K11: drop
A12: W | B12: 29 | C12: AJ | D12: 451.5 | E12: 466.6 | G12: =D12-E12 -> -15.1 | H12: negative consumed | I12: yes | J12: Maybe repeated 6 instead of 4? (446.6->466.6) | K12: drop
A13: W | B13: 30 | C13: AJ | D13: =water_ON!AJ30 -> 438.6 | E13: =water_OFF!AJ30 -> 395.5 | G13: =D13-E13 -> 43.1 | H13: High value + comes right after low value | I13: yes | J13: Weirdly low starting, maybe bottle leak?? | K13: drop

Sheet notes
A1: ID | B1: 45873 | C1: 45875 | D1: 45877 | E1: 45880 | F1: 45882 | G1: 45884 | H1: 45887 | I1: 45889 | J1: 45891 | K1: 45894 | L1: 45896 | M1: 45898 | N1: 45901 | O1: 45903 | P1: 45905 | Q1: 45908 | R1: 45910 | S1: 45912 | T1: 45915 | U1: 45917 | V1: 45919 | W1: 45922 | X1: 45924 | Y1: 45926 | Z1: 45929 | AA1: 45931 | AB1: 45933 | AC1: 45936 | AD1: 45938 | AE1: 45940 | AF1: 45943 | AG1: 45945 | AH1: 45947 | AI1: 45950 | AJ1: 45952 | AK1: 45954
A2: Left fluid (cages 1-30) | B2: water | C2: 20% ethanol | D2: water | E2: 20% ethanol | F2: water | G2: 20% ethanol | H2: water | I2: 20% ethanol | J2: water | K2: 20% ethanol | L2: water | M2: 20% ethanol | N2: water | O2: 20% ethanol | P2: water | Q2: 20% ethanol | R2: water | S2: 20% ethanol | T2: water | U2: 20% ethanol | V2: water | W2: 20% ethanol | X2: water | Y2: 20% ethanol | Z2: water | AA2: 20% ethanol | AB2: water | AC2: 20% ethanol | AD2: water | AE2: 20% ethanol | AF2: water | AG2: 20% ethanol | AH2: water | AI2: 20% ethanol | AJ2: water | AK2: 20% ethanol
A3: Right fluid (cages 1-30) | B3: 20% ethanol | C3: water | D3: 20%ethanol | E3: water | F3: 20% ethanol | G3: water | H3: 20%ethanol | I3: water | J3: 20% ethanol | K3: water | L3: 20% ethanol | M3: water | N3: 20% ethanol | O3: water | P3: 20% ethanol | Q3: water | R3: 20% ethanol | S3: water | T3: 20% ethanol | U3: water | V3: 20% ethanol | W3: water | X3: 20% ethanol | Y3: water | Z3: 20% ethanol | AA3: water | AB3: 20% ethanol | AC3: water | AD3: 20% ethanol | AE3: water | AF3: 20% ethanol | AG3: water | AH3: 20% ethanol | AI3: water | AJ3: 20% ethanol | AK3: water
A4: bottles ON time | B4: 10:56-11:14 | C4: 10:56:11:06 | D4: 10:14-10:31 | E4: 10:30-10:50 | F4: 10:15-10:37 | G4: 10:15-10:46 | H4: 0.42708333 | I4: 10:17-10:47 | J4: 10:20-10:40 | K4: 10:34-10:55 | L4: 10:17-10:32 | M4: 8:45-9:37 | N4: 10:08-10:25 | O4: 10:05-10:18 | P4: 10:04-10:17 | Q4: 9:44-9:59 | R4: 10:02 - 10:18 | S4: 10:03-10:17 | T4: 10:02-10:17 | U4: 9:51-10:06 | V4: 10:02-10:16 | W4: 10:11-10:22 | X4: 10:00-10:14 | Y4: 10:03-10:19 | Z4: 10:10-10:22 | AA4: 10:02-10:14 | AB4: 10:03-10:17 | AC4: 10:11-10:23 | AD4: 10:00-10:12 | AE4: 9:57:10:10 | AF4: 10:07-10:19 | AG4: 10:00-10:12 | AH4: 10:03-10:19 | AI4: 10:09-10:23 | AJ4: 10:12-10:25 | AK4: 9:56-10:08
A5: bottles OFF time | B5: 0.45833333 | C5: 0.45694444 | D5: 0.43055556 | E5: 0.44097222 | F5: 0.42708333 | H5: 0.42708333 | I5: 0.42847222 | U5: 9:51-10:00 | Z5: 10:10-10:19 | AB5: 0.42152778 | AG5: 10:00-10:08 | AI5: 10:09-10:19
A6: other notes | B6: 23W bottle cap came off during insertion and dumped into cage. Swapped lids and re-weighed. | C6: 24E & 24W were switched after pulling bottles off. So the transcripted weights needed to be swapped. | E6: Washed all bottles at the end of 8/12/25 | H6: 48 ate the rubber stopper and dumped water bottle in cage | J6: 48 ate the rubber stopper and dumped water bottle in cage - AGAIN! | K6: Rat 24 cage seemed wet, so swapped for clean | L6: 2.7g scale offset when putting bottle ON. Corrected values. | M6: Anna did IAP. | N6: did not weigh rats (moving to once per week on Wed), will copy Wed weights from now on. | Q6: 2.7 offset in the scale when weighing the off bottles. | R6: 2.7 offset in the scale when weighing the off bottles. | S6: 2.8 offset | T6: #48 chewed through normal water bottle and dumped water in his cage on Sunday. 3rd Time | Y6: #48 normal water bottle had leaked into his cage. Did cage change before putting bottles ON. | AA6: changed the acrylic backing on #47 because it was chewed up. | AB6: #48 chewed the stopper and dumped his normal water again. Cage was changed before putting bottled ON. | AC6: #48 lifted the normal water bottle above acrylic and pulled acrylic through bars. David put bottle back into place for ~40 minutes and when he checked back, the rat had chewed through the stopper and dumped water into the cage. | AI6: #47 chewed through water bottle stopper, changed cage before putting bottles on | AJ6: Rat #40 had porphorin around eyes on 10/22/25 | AK6: broke Leak1 Ethonal before putting ON. New bottle weighed 449.4
B7: 21E, top came off and dumped into cage | E7: 14e ,25e, 37e, 40e, 30e, 48e, 52e, 53e, 54e, 55e, 60e, 60w had w/e leaking on the stopper. | K7: bottle scale had -3.3g offset that would not zero out. (fixed) | M7: scale had +0.1 offset for bottle ON (fixed) | T7: Audio failure for Ethanol OFF bottles #39-L2. Estimated leak from averaging previous 10 days.
B8: 48E had -14g consumption, maybe flipped with 48W? | E8: #37 has #45W and #45 has #37W, swapped ON values and labels to make correct | M8: scale had +1g offset for bottle OFF (fixed) | N8: no scale offset for ON or OFF | O8: no scale offset for ON or OFF
B9: 60W has -12g consumption, but doesn't make sense for it to be flipped with 60E

Sheet rat_weight
A1: ID | B1: 45873 | C1: 45875 | D1: 45877 | E1: 45880 | F1: 45882 | G1: 45884 | H1: 45887 | I1: 45889 | J1: 45891 | K1: 45894 | L1: 45896 | M1: 45898 | N1: 45901 | O1: 45903 | P1: 45905 | Q1: 45908 | R1: 45910 | S1: 45912 | T1: 45915 | U1: 45917 | V1: 45919 | W1: 45922 | X1: 45924 | Y1: 45926 | Z1: 45929 | AA1: 45931 | AB1: 45933 | AC1: 45936 | AD1: 45938 | AE1: 45940 | AF1: 45943 | AG1: 45945 | AH1: 45947 | AI1: 45950 | AJ1: 45952 | AK1: 45954
A2: 1 | B2: 253 | C2: 257 | D2: 257 | E2: 256 | F2: 253 | G2: 258 | H2: 259 | I2: 262 | J2: 265 | K2: 262 | L2: 261 | M2: 263 | N2: 271 | O2: 271 | P2: 271 | Q2: 270 | R2: 270 | S2: 270 | T2: 271 | U2: 271 | V2: 271 | W2: 274 | X2: 274 | Y2: 274 | Z2: 278 | AA2: 278 | AB2: 278 | AC2: 285 | AD2: 285 | AE2: 285 | AF2: 287 | AG2: 287 | AH2: 287 | AI2: 292 | AJ2: 292 | AK2: 292
A3: 2 | B3: 162 | C3: 166 | D3: 162 | E3: 170 | F3: 165 | G3: 166 | H3: 163 | I3: 173 | J3: 170 | K3: 169 | L3: 165 | M3: 166 | N3: 169 | O3: 169 | P3: 169 | Q3: 175 | R3: 175 | S3: 175 | T3: 174 | U3: 174 | V3: 174 | W3: 176 | X3: 176 | Y3: 176 | Z3: 180 | AA3: 180 | AB3: 180 | AC3: 185 | AD3: 185 | AE3: 185 | AF3: 181 | AG3: 181 | AH3: 181 | AI3: 181 | AJ3: 181 | AK3: 181
A4: 3 | B4: 502 | C4: 505 | D4: 510 | E4: 519 | F4: 517 | G4: 522 | H4: 529 | I4: 537 | J4: 529 | K4: 533 | L4: 539 | M4: 531 | N4: 552 | O4: 552 | P4: 552 | Q4: 560 | R4: 560 | S4: 560 | T4: 559 | U4: 559 | V4: 559 | W4: 567 | X4: 567 | Y4: 567 | Z4: 563 | AA4: 563 | AB4: 563 | AC4: 575 | AD4: 575 | AE4: 575 | AF4: 580 | AG4: 580 | AH4: 580 | AI4: 587 | AJ4: 587 | AK4: 587
A5: 4 | B5: 280 | C5: 277 | D5: 283 | E5: 290 | F5: 289 | G5: 288 | H5: 292 | I5: 290 | J5: 287 | K5: 299 | L5: 295 | M5: 289 | N5: 295 | O5: 295 | P5: 295 | Q5: 299 | R5: 299 | S5: 299 | T5: 303 | U5: 303 | V5: 303 | W5: 307 | X5: 307 | Y5: 307 | Z5: 313 | AA5: 313 | AB5: 313 | AC5: 315 | AD5: 315 | AE5: 315 | AF5: 313 | AG5: 313 | AH5: 313 | AI5: 317 | AJ5: 317 | AK5: 317
A6: 5 | B6: 483 | C6: 480 | D6: 490 | E6: 498 | F6: 496 | G6: 505 | H6: 508 | I6: 508 | J6: 513 | K6: 520 | L6: 525 | M6: 537 | N6: 542 | O6: 542 | P6: 542 | Q6: 551 | R6: 551 | S6: 551 | T6: 560 | U6: 560 | V6: 560 | W6: 581 | X6: 581 | Y6: 581 | Z6: 576 | AA6: 576 | AB6: 576 | AC6: 588 | AD6: 588 | AE6: 588 | AF6: 599 | AG6: 599 | AH6: 599 | AI6: 606 | AJ6: 606 | AK6: 606
A7: 6 | B7: 332 | C7: 339 | D7: 330 | E7: 340 | F7: 340 | G7: 354 | H7: 361 | I7: 373 | J7: 378 | K7: 390 | L7: 394 | M7: 380 | N7: 384 | O7: 384 | P7: 384 | Q7: 386 | R7: 386 | S7: 386 | T7: 410 | U7: 410 | V7: 410 | W7: 415 | X7: 415 | Y7: 415 | Z7: 408 | AA7: 408 | AB7: 408 | AC7: 432 | AD7: 432 | AE7: 432 | AF7: 443 | AG7: 443 | AH7: 443 | AI7: 454 | AJ7: 454 | AK7: 454
A8: 7 | B8: 275 | C8: 304 | D8: 273 | E8: 266 | F8: 272 | G8: 277 | H8: 277 | I8: 286 | J8: 280 | K8: 287 | L8: 283 | M8: 284 | N8: 293 | O8: 293 | P8: 293 | Q8: 290 | R8: 290 | S8: 290 | T8: 295 | U8: 295 | V8: 295 | W8: 296 | X8: 296 | Y8: 296 | Z8: 294 | AA8: 294 | AB8: 294 | AC8: 294 | AD8: 294 | AE8: 294 | AF8: 296 | AG8: 296 | AH8: 296 | AI8: 296 | AJ8: 296 | AK8: 296
A9: 8 | B9: 470 | C9: 466 | D9: 472 | E9: 478 | F9: 475 | G9: 485 | H9: 487 | I9: 490 | J9: 491 | K9: 494 | L9: 599 | M9: 491 | N9: 503 | O9: 503 | P9: 503 | Q9: 515 | R9: 515 | S9: 515 | T9: 522 | U9: 522 | V9: 522 | W9: 534 | X9: 534 | Y9: 534 | Z9: 536 | AA9: 536 | AB9: 536 | AC9: 540 | AD9: 540 | AE9: 540 | AF9: 540 | AG9: 540 | AH9: 540 | AI9: 550 | AJ9: 550 | AK9: 550
A10: 9 | B10: 350 | C10: 356 | D10: 354 | E10: 348 | F10: 339 | G10: 345 | H10: 337 | I10: 348 | J10: 332 | K10: 355 | L10: 343 | M10: 366 | N10: 363 | O10: 363 | P10: 363 | Q10: 371 | R10: 371 | S10: 371 | T10: 396 | U10: 396 | V10: 396 | W10: 397 | X10: 397 | Y10: 397 | Z10: 405 | AA10: 405 | AB10: 405 | AC10: 418 | AD10: 418 | AE10: 418 | AF10: 417 | AG10: 417 | AH10: 417 | AI10: 439 | AJ10: 439 | AK10: 439
A11: 10 | B11: 367 | C11: 470 | D11: 470 | E11: 478 | F11: 474 | G11: 476 | H11: 483 | I11: 495 | J11: 490 | K11: 501 | L11: 505 | M11: 508 | N11: 512 | O11: 512 | P11: 512 | Q11: 529 | R11: 529 | S11: 529 | T11: 537 | U11: 537 | V11: 537 | W11: 541 | X11: 541 | Y11: 541 | Z11: 547 | AA11: 547 | AB11: 547 | AC11: 554 | AD11: 554 | AE11: 554 | AF11: 556 | AG11: 556 | AH11: 556 | AI11: 572 | AJ11: 572 | AK11: 572
A12: 11 | B12: 160 | C12: 162 | D12: 161 | E12: 165 | F12: 159 | G12: 168 | H12: 169 | I12: 165 | J12: 162 | K12: 163 | L12: 165 | M12: 165 | N12: 169 | O12: 169 | P12: 169 | Q12: 168 | R12: 168 | S12: 168 | T12: 171 | U12: 171 | V12: 171 | W12: 171 | X12: 171 | Y12: 171 | Z12: 175 | AA12: 175 | AB12: 175 | AC12: 180 | AD12: 180 | AE12: 180 | AF12: 175 | AG12: 175 | AH12: 175 | AI12: 177 | AJ12: 177 | AK12: 177
A13: 12 | B13: 281 | C13: 285 | D13: 289 | E13: 307 | F13: 303 | G13: 306 | H13: 306 | I13: 303 | J13: 295 | K13: 298 | L13: 298 | M13: 297 | N13: 301 | O13: 301 | P13: 301 | Q13: 309 | R13: 309 | S13: 309 | T13: 316 | U13: 316 | V13: 316 | W13: 317 | X13: 317 | Y13: 317 | Z13: 317 | AA13: 317 | AB13: 317 | AC13: 321 | AD13: 321 | AE13: 321 | AF13: 320 | AG13: 320 | AH13: 320 | AI13: 320 | AJ13: 320 | AK13: 320
... A61: 60 | B61: 486 | C61: 489 | D61: 491 | E61: 500 | F61: 503 | G61: 503 | H61: 512 | I61: 512 | J61: 516 | K61: 524 | L61: 531 | M61: 534 | N61: 544 | O61: 544 | P61: 544 | Q61: 555 | R61: 555 | S61: 555 | T61: 557 | U61: 557 | V61: 557 | W61: 567 | X61: 567 | Y61: 567 | Z61: 573 | AA61: 573 | AB61: 573 | AC61: 578 | AD61: 578 | AE61: 578 | AF61: 582 | AG61: 582 | AH61: 582 | AI61: 594 | AJ61: 594 | AK61: 594

Sheet eth_ON
A1: ID | B1: 45873 | C1: 45875 | D1: 45877 | E1: 45880 | F1: 45882 | G1: 45884 | H1: 45887 | I1: 45889 | J1: 45891 | K1: 45894 | L1: 45896 | M1: 45898 | N1: 45901 | O1: 45903 | P1: 45905 | Q1: 45908 | R1: 45910 | S1: 45912 | T1: 45915 | U1: 45917 | V1: 45919 | W1: 45922 | X1: 45924 | Y1: 45926 | Z1: 45929 | AA1: 45931 | AB1: 45933 | AC1: 45936 | AD1: 45938 | AE1: 45940 | AF1: 45943 | AG1: 45945 | AH1: 45947 | AI1: 45950 | AJ1: 45952 | AK1: 45954
A2: 1 | B2: 470.5 | C2: 469.1 | D2: 460.7 | E2: 450.7 | F2: 469.5 | G2: 483.2 | H2: 471 | I2: 476.6 | J2: 463.8 | K2: 478.6 | L2: 463.3 | M2: 482.7 | N2: 469.4 | O2: 456.5 | P2: 464.6 | Q2: 448.9 | R2: 470.1 | S2: 470.2 | T2: 474.1 | U2: 474.9 | V2: 463.5 | W2: 481 | X2: 468.7 | Y2: 457.4 | Z2: 486.2 | AA2: 475.5 | AB2: 475.7 | AC2: 480.5 | AD2: 470.2 | AE2: 475.4 | AF2: 476.7 | AG2: 464.8 | AH2: 476 | AI2: 460.5 | AJ2: 472.8 | AK2: 461.3
A3: 2 | B3: 459.7 | C3: 459.6 | D3: 458.8 | E3: 457.9 | F3: 473.3 | G3: 469 | H3: 473.1 | I3: 477.9 | J3: 473.2 | K3: 483.7 | L3: 477.2 | M3: 470.5 | N3: 462.9 | O3: 472.5 | P3: 478.1 | Q3: 468 | R3: 461.7 | S3: 475.7 | T3: 470 | U3: 465.2 | V3: 471.8 | W3: 487.1 | X3: 480.4 | Y3: 473.9 | Z3: 468.4 | AA3: 489.6 | AB3: 483.6 | AC3: 475.6 | AD3: 468.4 | AE3: 478.9 | AF3: 484.6 | AG3: 477.1 | AH3: 470.5 | AI3: 459.5 | AJ3: 495.8 | AK3: 488.9
A4: 3 | B4: 465.7 | C4: 470.5 | D4: 483.9 | E4: 468.3 | F4: 469.7 | G4: 471.8 | H4: 454 | I4: 472 | J4: 474.1 | K4: 476.2 | L4: 459.6 | M4: 477.1 | N4: 459.3 | O4: 466.3 | P4: 472.7 | Q4: 450.8 | R4: 465.9 | S4: 464.6 | T4: 467.9 | U4: 472.8 | V4: 455.8 | W4: 476.5 | X4: 475.9 | Y4: 458.5 | Z4: 440.3 | AA4: 464.9 | AB4: 471.1 | AC4: 478.5 | AD4: 458.3 | AE4: 471.5 | AF4: 476.9 | AG4: 476 | AH4: 455.6 | AI4: 466.5 | AJ4: 467.7 | AK4: 468.2
A5: 4 | B5: 459.9 | C5: 462.5 | D5: 453 | E5: 475.4 | F5: 468.5 | G5: 482.9 | H5: 469 | I5: 473.3 | J5: 456.1 | K5: 471 | L5: 451.9 | M5: 464.7 | N5: 447 | O5: 454.9 | P5: 468.7 | Q5: 446 | R5: 465.4 | S5: 447.7 | T5: 464.6 | U5: 465 | V5: 446.3 | W5: 473.4 | X5: 473.6 | Y5: 479.7 | Z5: 461.4 | AA5: 449.8 | AB5: 466.9 | AC5: 482.1 | AD5: 464.2 | AE5: 469.6 | AF5: 483 | AG5: 465.3 | AH5: 469.5 | AI5: 449.7 | AJ5: 481 | AK5: 461.8
A6: 5 | B6: 467.4 | C6: 468.3 | D6: 467.3 | E6: 465.6 | F6: 469.8 | G6: 469.2 | H6: 468.1 | I6: 467.2 | J6: 465.7 | K6: 464.3 | L6: 463.7 | M6: 462.9 | N6: 460.6 | O6: 459.7 | P6: 479.8 | Q6: 476.1 | R6: 475.3 | S6: 474.6 | T6: 472.5 | U6: 474.8 | V6: 473.9 | W6: 472.9 | X6: 472.1 | Y6: 471.6 | Z6: 471 | AA6: 469.9 | AB6: 469 | AC6: 467.8 | AD6: 466.7 | AE6: 465.6 | AF6: 476 | AG6: 475.5 | AH6: 474.4 | AI6: 471.3 | AJ6: 471.9 | AK6: 470.8
A7: 6 | B7: 457.9 | C7: 464.5 | D7: 476.2 | E7: 466 | F7: 462.3 | G7: 476.5 | H7: 459 | I7: 465.9 | J7: 474.3 | K7: 476.6 | L7: 476.2 | M7: 459.8 | N7: 451.7 | O7: 466.4 | P7: 483.5 | Q7: 474.2 | R7: 469.8 | S7: 463.2 | T7: 467.4 | U7: 460.8 | V7: 457 | W7: 484.4 | X7: 469.9 | Y7: 459.3 | Z7: 474 | AA7: 466.7 | AB7: 470.7 | AC7: 459.1 | AD7: 471.2 | AE7: 473.9 | AF7: 478.8 | AG7: 462.8 | AH7: 472.4 | AI7: 454.1 | AJ7: 471.1 | AK7: 471.8
A8: 7 | B8: 461 | C8: 469 | D8: 462.2 | E8: 477.1 | F8: 469.3 | G8: 475.8 | H8: 461.2 | I8: 477.4 | J8: 481.6 | K8: 481 | L8: 482.1 | M8: 480.4 | N8: 465.4 | O8: 478 | P8: 471.3 | Q8: 484.4 | R8: 468.2 | S8: 467.1 | T8: 472 | U8: 474.8 | V8: 463.8 | W8: 484.7 | X8: 481.5 | Y8: 475.1 | Z8: 455.3 | AA8: 480.4 | AB8: 474.2 | AC8: 455.9 | AD8: 473.5 | AE8: 476 | AF8: 487 | AG8: 470 | AH8: 478.7 | AI8: 456.3 | AJ8: 467.8 | AK8: 474.3
A9: 8 | B9: 460.9 | C9: 463.7 | D9: 473.9 | E9: 457.9 | F9: 473.5 | G9: 473.2 | H9: 476.3 | I9: 480.8 | J9: 482.2 | K9: 485.1 | L9: 467.8 | M9: 476.9 | N9: 460.2 | O9: 477 | P9: 475.7 | Q9: 480.5 | R9: 463 | S9: 466.4 | T9: 481.5 | U9: 479 | V9: 465.1 | W9: 479.3 | X9: 482.8 | Y9: 467.9 | Z9: 486.4 | AA9: 468.2 | AB9: 476.1 | AC9: 457.9 | AD9: 478.7 | AE9: 479.3 | AF9: 490.2 | AG9: 470.3 | AH9: 477.6 | AI9: 455.7 | AJ9: 464.6 | AK9: 481
A10: 9 | B10: 466 | C10: 442.6 | D10: 474 | E10: 465.5 | F10: 468.4 | G10: 467.7 | H10: 466 | I10: 465.1 | J10: 463.2 | K10: 462.1 | L10: 477.6 | M10: 476.8 | N10: 475.3 | O10: 474.6 | P10: 483.3 | Q10: 479.6 | R10: 478.3 | S10: 477.2 | T10: 475.4 | U10: 477.6 | V10: 476.4 | W10: 475.4 | X10: 471 | Y10: 470.3 | Z10: 469.2 | AA10: 468.3 | AB10: 467.4 | AC10: 466.5 | AD10: 465.4 | AE10: 464.2 | AF10: 485 | AG10: 484.2 | AH10: 482.1 | AI10: 479.4 | AJ10: 478.2 | AK10: 476.7
A11: 10 | B11: 465.3 | C11: 468.6 | D11: 467.9 | E11: 466.4 | F11: 476 | G11: 475.4 | H11: 474.3 | I11: 473.5 | J11: 471.9 | K11: 470.8 | L11: 470.1 | M11: 468.9 | N11: 467.4 | O11: 466.6 | P11: 481.3 | Q11: 477.4 | R11: 476.6 | S11: 475.8 | T11: 474.8 | U11: 476.8 | V11: 475.5 | W11: 474.5 | X11: 473.3 | Y11: 472.5 | Z11: 471.7 | AA11: 469.7 | AB11: 468.7 | AC11: 467.5 | AD11: 476.7 | AE11: 475.7 | AF11: 487.7 | AG11: 487 | AH11: 485.8 | AI11: 482.9 | AJ11: 483.5 | AK11: 482.4
A12: 11 | B12: 464.9 | C12: 463.8 | D12: 455.8 | E12: 472.6 | F12: 465 | G12: 465 | H12: 464.9 | I12: 464.9 | J12: 477.4 | K12: 477.3 | L12: 477.3 | M12: 477.3 | N12: 466.1 | O12: 456.3 | P12: 469.2 | Q12: 454.6 | R12: 468.3 | S12: 457.5 | T12: 464.8 | U12: 471.4 | V12: 460.1 | W12: 479.3 | X12: 470.5 | Y12: 460.1 | Z12: 491.2 | AA12: 480.2 | AB12: 472.6 | AC12: 463.2 | AD12: 470.4 | AE12: 461 | AF12: 485.3 | AG12: 474.7 | AH12: 464.5 | AI12: 452.7 | AJ12: 465.4 | AK12: 475.5
A13: 12 | B13: 461.8 | C13: 453.8 | D13: 477.8 | E13: 466.2 | F13: 472.2 | G13: 461.2 | H13: 471 | I13: 476.1 | J13: 465.2 | K13: 471.3 | L13: 474 | M13: 461.2 | N13: 445.9 | O13: 471.9 | P13: 471.5 | Q13: 453.7 | R13: 470.5 | S13: 469.6 | T13: 464.3 | U13: 464.1 | V13: 448.1 | W13: 474.6 | X13: 476 | Y13: 461.9 | Z13: 478.7 | AA13: 465.7 | AB13: 473.1 | AC13: 460.8 | AD13: 466.4 | AE13: 477.5 | AF13: 481.2 | AG13: 467.6 | AH13: 474.6 | AI13: 459.4 | AJ13: 449.5 | AK13: 474.9
... A21: 20 | B21: 455.2 | C21: 455.9 | D21: 453.2 | E21: 452.3 | F21: 463.3 | G21: 462.8 | H21: 461.6 | I21: 474.7 | J21: 471.8 | K21: 470.6 | L21: 470 | M21: 469.1 | N21: 467.7 | O21: 466.8 | P21: 483.2 | Q21: 479.6 | R21: 478.8 | S21: 478 | T21: 477 | U21: 479.5 | V21: 478.4 | W21: 477.6 | X21: 476.5 | Y21: 475.5 | Z21: 474.6 | AA21: 473.5 | AB21: 472.2 | AC21: 471.2 | AD21: 469.8 | AE21: 468.5 | AF21: 484.6 | AG21: 484.1 | AH21: 483 | AI21: 480.3 | AJ21: 480.9 | AK21: 479.5
A22: 21 | C22: 446.8 | D22: 465.4 | E22: 457.1 | F22: 446.9 | G22: 446.9 | H22: 464.4 | I22: 464.3 | J22: 456.1 | K22: 469.4 | L22: 459.1 | M22: 451.6 | N22: 440.7 | O22: 464.8 | P22: 466.1 | Q22: 451.9 | R22: 456.5 | S22: 458.9 | T22: 455.1 | U22: 461.1 | V22: 450.3 | W22: 438.5 | X22: 467.2 | Y22: 453.1 | Z22: 473.8 | AA22: 462.7 | AB22: 459.5 | AC22: 463.6 | AD22: 451.9 | AE22: 461 | AF22: 471.1 | AG22: 459.4 | AH22: 445.6 | AI22: 430.7 | AJ22: 455.9 | AK22: 463.6
A23: 22 | B23: 439.5 | C23: 433.1 | D23: 467.1 | E23: 453 | F23: 454.4 | G23: 466.3 | H23: 450.8 | I23: 466.3 | J23: 454.2 | K23: 468.4 | L23: 466.4 | M23: 452.3 | N23: 437.8 | O23: 459.3 | P23: 457.5 | Q23: 441.2 | R23: 454.9 | S23: 458.2 | T23: 456.9 | U23: 462.7 | V23: 448.6 | W23: 435.4 | X23: 466.9 | Y23: 453.6 | Z23: 472.9 | AA23: 460.1 | AB23: 457.2 | AC23: 467.6 | AD23: 453.6 | AE23: 458.9 | AF23: 468 | AG23: 466.4 | AH23: 449.8 | AI23: 432.1 | AJ23: 462.2 | AK23: 462.8
A24: 23 | B24: 472 | C24: 471.1 | D24: 464.6 | E24: 457.2 | F24: 448.9 | G24: 449 | H24: 458.9 | I24: 462.9 | J24: 456.7 | K24: 468.4 | L24: 457.5 | M24: 464.3 | N24: 453 | O24: 441.2 | P24: 455 | Q24: 440.4 | R24: 459 | S24: 448.6 | T24: 457.7 | U24: 461.7 | V24: 448.4 | W24: 471.5 | X24: 469 | Y24: 457.5 | Z24: 445 | AA24: 470.5 | AB24: 459.9 | AC24: 468.1 | AD24: 466.8 | AE24: 465.3 | AF24: 474.4 | AG24: 458.9 | AH24: 445 | AI24: 428.9 | AJ24: 456.5 | AK24: 463.5
A25: 24 | B25: 450.5 | C25: 445.8 | D25: 457.1 | E25: 464.4 | F25: 466.8 | G25: 467.8 | H25: 451.4 | I25: 462.4 | J25: 470.1 | K25: 449.6 | L25: 466 | M25: 464.8 | N25: 441.5 | O25: 460.5 | P25: 461.3 | Q25: 437.5 | R25: 451.5 | S25: 456.1 | T25: 460 | U25: 462.9 | V25: 447.3 | W25: 470.6 | X25: 462.9 | Y25: 444.4 | Z25: 477.8 | AA25: 456.1 | AB25: 454.4 | AC25: 467.5 | AD25: 463.8 | AE25: 462.2 | AF25: 469.7 | AG25: 459 | AH25: 459.3 | AI25: 430.9 | AJ25: 456.9 | AK25: 463
A26: 25 | B26: 454.3 | C26: 448.7 | D26: 469.5 | E26: 456.3 | F26: 465.7 | G26: 468.2 | H26: 462.5 | I26: 464.5 | J26: 468.3 | K26: 469.7 | L26: 469.5 | M26: 465.6 | N26: 444.8 | O26: 456.5 | P26: 464.5 | Q26: 437 | R26: 467 | S26: 461.1 | T26: 463.6 | U26: 466.7 | V26: 474.9 | W26: 452.4 | X26: 466.8 | Y26: 462.3 | Z26: 475.9 | AA26: 449.2 | AB26: 462.2 | AC26: 476.5 | AD26: 465.6 | AE26: 467.1 | AF26: 474.3 | AG26: 468.9 | AH26: 467.9 | AI26: 441.8 | AJ26: 471.2 | AK26: 464.6
A27: 26 | B27: 421.9 | C27: 457.2 | D27: 447.3 | E27: 460.4 | F27: 451.4 | G27: 451.3 | H27: 440.9 | I27: 461.3 | J27: 447 | K27: 458.7 | L27: 444.5 | M27: 460.4 | N27: 442.1 | O27: 445.5 | P27: 454.7 | Q27: 434.6 | R27: 456.5 | S27: 458.8 | T27: 465.4 | U27: 451.5 | V27: 459.3 | W27: 441.7 | X27: 465 | Y27: 449.9 | Z27: 471.6 | AA27: 452.8 | AB27: 456.9 | AC27: 471.2 | AD27: 452.4 | AE27: 463.2 | AF27: 473.5 | AG27: 455.2 | AH27: 438.3 | AI27: 455.2 | AJ27: 440.8 | AK27: 456.8
A28: 27 | B28: 453.2 | C28: 452.4 | D28: 470.8 | E28: 460.6 | F28: 452.2 | G28: 458.4 | H28: 448.3 | I28: 466.2 | J28: 456 | K28: 461.4 | L28: 450.8 | M28: 461.1 | N28: 449.8 | O28: 460.4 | P28: 458.7 | Q28: 442.3 | R28: 456.4 | S28: 460.5 | T28: 457.4 | U28: 462.7 | V28: 450.1 | W28: 439.8 | X28: 459.3 | Y28: 445.8 | Z28: 471 | AA28: 456.9 | AB28: 459.9 | AC28: 468.2 | AD28: 456.4 | AE28: 462.2 | AF28: 475.4 | AG28: 460.9 | AH28: 445.3 | AI28: 427.7 | AJ28: 469.3 | AK28: 456
A29: 28 | B29: 441.7 | C29: 441.3 | D29: 467.8 | E29: 461.7 | F29: 449.8 | G29: 470.8 | H29: 462.9 | I29: 453.7 | J29: 461.2 | K29: 462.9 | L29: 457 | M29: 467.6 | N29: 459.2 | O29: 448.7 | P29: 466.1 | Q29: 455.5 | R29: 451.1 | S29: 464.7 | T29: 464.9 | U29: 464.4 | V29: 476.5 | W29: 466.2 | X29: 468 | Y29: 459.7 | Z29: 474.1 | AA29: 467.9 | AB29: 456.8 | AC29: 473.6 | AD29: 463.2 | AE29: 465 | AF29: 474 | AG29: 465.6 | AH29: 457.1 | AI29: 467.9 | AJ29: 460.8 | AK29: 471.4
A30: 29 | B30: 448.3 | C30: 450.5 | D30: 447.5 | E30: 465.8 | F30: 462.6 | G30: 461.9 | H30: 459.8 | I30: 457.6 | J30: 456.1 | K30: 469.5 | L30: 467.8 | M30: 466.7 | N30: 465.4 | O30: 464.6 | P30: 479.7 | Q30: 476.3 | R30: 475.6 | S30: 474.7 | T30: 473.7 | U30: 475.9 | V30: 474.7 | W30: 474 | X30: 472.8 | Y30: 471.9 | Z30: 471 | AA30: 469.7 | AB30: 468.5 | AC30: 467 | AD30: 465 | AE30: 463.7 | AF30: 473.8 | AG30: 472.6 | AH30: 471.1 | AI30: 467.3 | AJ30: 466.1 | AK30: 464.3
A31: 30 | B31: 437.2 | C31: 440.5 | D31: 435 | E31: 462.7 | F31: 464.4 | G31: 462.9 | H31: 459.6 | I31: 471.3 | J31: 468.1 | K31: 460.8 | L31: 469.5 | M31: 465.3 | N31: 457 | O31: 448.3 | P31: 457.4 | Q31: 448.3 | R31: 458.5 | S31: 455.3 | T31: 457.1 | U31: 464.8 | V31: 459.1 | W31: 455 | X31: 462.9 | Y31: 459.6 | Z31: 454.6 | AA31: 448.1 | AB31: 460.2 | AC31: 456.6 | AD31: 465.7 | AE31: 459.7 | AF31: 473 | AG31: 468 | AH31: 461 | AI31: 453.4 | AJ31: 449.9 | AK31: 463.6
A32: 31 | B32: 455 | C32: 454.7 | D32: 444.8 | E32: 464.4 | F32: 472.6 | G32: 460 | H32: 448.6 | I32: 464.5 | J32: 467.3 | K32: 469.9 | L32: 470.3 | M32: 467.4 | N32: 453.6 | O32: 443.4 | P32: 462.3 | Q32: 447.9 | R32: 459 | S32: 464.8 | T32: 462.9 | U32: 454 | V32: 474.4 | W32: 468 | X32: 465.9 | Y32: 460.1 | Z32: 452 | AA32: 480 | AB32: 470.5 | AC32: 462.7 | AD32: 450.7 | AE32: 466.7 | AF32: 474.7 | AG32: 465.5 | AH32: 453.5 | AI32: 460.4 | AJ32: 463.3 | AK32: 450.6
A33: 32 | B33: 433.1 | C33: 451.8 | D33: 446.6 | E33: 463.3 | F33: 451.6 | G33: 450.8 | H33: 449.3 | I33: 446.6 | J33: 445.2 | K33: 466.3 | L33: 465.4 | M33: 462.3 | N33: 458.9 | O33: 455.7 | P33: 471.4 | Q33: 464.2 | R33: 459.3 | S33: 453.7 | T33: 449 | U33: 460.9 | V33: 452.9 | W33: 445.9 | X33: 462.7 | Y33: 457.1 | Z33: 449.4 | AA33: 441.6 | AB33: 456.9 | AC33: 452.8 | AD33: 459.3 | AE33: 450.5 | AF33: 473.3 | AG33: 468.6 | AH33: 462.5 | AI33: 451.7 | AJ33: 443.8 | AK33: 461.8
A34: 33 | B34: 453.6 | C34: 467.3 | D34: 465.6 | E34: 458.3 | F34: 471 | G34: 458.9 | H34: 448.3 | I34: 468 | J34: 466.4 | K34: 466.9 | L34: 468.3 | M34: 455.8 | N34: 439.3 | O34: 465.2 | P34: 468.2 | Q34: 451.2 | R34: 461.9 | S34: 464.9 | T34: 462.9 | U34: 450.8 | V34: 457.7 | W34: 442.2 | X34: 463.7 | Y34: 464 | Z34: 467.2 | AA34: 451 | AB34: 461.7 | AC34: 472.1 | AD34: 452.3 | AE34: 470.5 | AF34: 470.8 | AG34: 470.4 | AH34: 452.6 | AI34: 465.3 | AJ34: 451.1 | AK34: 465.9
... A61: 60 | B61: 452.9 | C61: 438.7 | D61: 463.8 | E61: 451.5 | F61: 466.4 | G61: 464.5 | H61: 462.7 | I61: 464.5 | J61: 469.7 | K61: 468 | L61: 465.1 | M61: 465.5 | N61: 438.8 | O61: 463.9 | P61: 464 | Q61: 468.3 | R61: 448 | S61: 463 | T61: 462.9 | U61: 455.4 | V61: 456.3 | W61: 471.8 | X61: 467.4 | Y61: 437.3 | Z61: 474.3 | AA61: 474 | AB61: 465.3 | AC61: 476.4 | AD61: 466.1 | AE61: 464.5 | AF61: 464.7 | AG61: 464.8 | AH61: 469.2 | AI61: 468.3 | AJ61: 466.6 | AK61: 463.7
A62: leak 1 | B62: 462.1 | C62: 465 | D62: 464 | E62: 463.1 | F62: 455.5 | G62: 454.7 | H62: 453.5 | I62: 452.7 | J62: 465 | K62: 464.2 | L62: 463.5 | M62: 462.8 | N62: 461.4 | O62: 460.7 | P62: 459.6 | Q62: 456.1 | R62: 455.3 | S62: 454.5 | T62: 453 | U62: 455 | V62: 453.7 | W62: 452.9 | X62: 451.5 | Y62: 450.7 | Z62: 481.4 | AA62: 480.7 | AB62: 480.2 | AC62: 474.9 | AD62: 474.3 | AE62: 473.1 | AF62: 477.9 | AG62: 477.6 | AH62: 476.6 | AI62: 473.5 | AJ62: 474.3 | AK62: 449.4
A63: leak 2 | B63: 462.1 | C63: 465 | D63: 463.6 | E63: 462.7 | F63: 453.7 | G63: 453.2 | H63: 452.3 | I63: 451.6 | J63: 463.3 | K63: 462.6 | L63: 462.1 | M63: 461.4 | N63: 459.8 | O63: 458.7 | P63: 457.9 | Q63: 454.4 | R63: 453.6 | S63: 453.1 | T63: 452.1 | U63: 454.5 | V63: 453.9 | W63: 453 | X63: 451.8 | Y63: 451.3 | Z63: 450.6 | AA63: 449.6 | AB63: 449 | AC63: 448.4 | AD63: 447.6 | AE63: 446.4 | AF63: 471.2 | AG63: 470.8 | AH63: 470.1 | AI63: 467 | AJ63: 467.8 | AK63: 467
A64: 500g calibration weight | B64: 500 | C64: 500 | D64: 500 | E64: 500 | F64: 500 | G64: 500 | H64: 500 | I64: 500 | J64: 500 | K64: 500 | L64: 500 | M64: 500 | N64: 500 | O64: 500 | P64: 500 | Q64: 497.2 | R64: 497.2 | S64: 497.2 | T64: 497 | U64: 500 | V64: 500.1 | W64: 500 | X64: 499.9 | Y64: 500.1 | Z64: 500 | AA64: 499.8 | AB64: 500 | AC64: 500.1 | AD64: 500 | AE64: 500 | AF64: 499.9 | AG64: 500 | AH64: 500 | AI64: 498.2 | AJ64: 500 | AK64: 500
A65: Scale offset | B65: =500-B64 -> 0 | C65: =500-C64 -> 0 | D65: =500-D64 -> 0 | E65: =500-E64 -> 0 | F65: =500-F64 -> 0 | G65: =500-G64 -> 0 | H65: =500-H64 -> 0 | I65: =500-I64 -> 0 | ... AK65: =500-AK64 -> 0

Sheet eth_OFF
A1: ID | B1: 45873 | C1: 45875 | D1: 45877 | E1: 45880 | F1: 45882 | G1: 45884 | H1: 45887 | I1: 45889 | J1: 45891 | K1: 45894 | L1: 45896 | M1: 45898 | N1: 45901 | O1: 45903 | P1: 45905 | Q1: 45908 | R1: 45910 | S1: 45912 | T1: 45915 | U1: 45917 | V1: 45919 | W1: 45922 | X1: 45924 | Y1: 45926 | Z1: 45929 | AA1: 45931 | AB1: 45933 | AC1: 45936 | AD1: 45938 | AE1: 45940 | AF1: 45943 | AG1: 45945 | AH1: 45947 | AI1: 45950 | AJ1: 45952 | AK1: 45954
A2: 1 | B2: 469.1 | C2: 460.8 | D2: 451 | E2: 440.1 | F2: 458.8 | G2: 471.3 | H2: 459.2 | I2: 464 | J2: 449.9 | K2: 463.6 | L2: 451.9 | M2: 468.9 | N2: 456.6 | O2: 444.4 | P2: 449.1 | Q2: 438.2 | R2: 458.7 | S2: 458 | T2: 464.5 | U2: 463.5 | V2: 449.7 | W2: 469 | X2: 457.6 | Y2: 444.4 | Z2: 475.9 | AA2: 463.7 | AB2: 465.2 | AC2: 470.5 | AD2: 458.8 | AE2: 463.7 | AF2: 464.9 | AG2: 453.4 | AH2: 462.6 | AI2: 445.4 | AJ2: 461.5 | AK2: 449.2
A3: 2 | B3: 462.5 | C3: 458.9 | D3: 458.1 | E3: 453.6 | F3: 469.2 | G3: 460.2 | H3: 466.8 | I3: 473.4 | J3: 465.9 | K3: 477.4 | L3: 470.7 | M3: 462.2 | N3: 456.7 | O3: 464.2 | P3: 468.4 | Q3: 461.8 | R3: 456.2 | S3: 470.5 | T3: 465.4 | U3: 457.7 | V3: 467.6 | W3: 480.7 | X3: 474.1 | Y3: 468.6 | Z3: 461.1 | AA3: 483.8 | AB3: 475.9 | AC3: 468.6 | AD3: 460.5 | AE3: 471.4 | AF3: 477.3 | AG3: 470.8 | AH3: 461.7 | AI3: 450.6 | AJ3: 489.2 | AK3: 481.2
A4: 3 | B4: 455.8 | C4: 457.7 | D4: 468.8 | E4: 449.2 | F4: 452.1 | G4: 454.3 | H4: 435.1 | I4: 454 | J4: 455.2 | K4: 459.8 | L4: 444 | M4: 458.5 | N4: 441.1 | O4: 451 | P4: 451 | Q4: 438.2 | R4: 446.5 | S4: 443.5 | T4: 453.9 | U4: 455.8 | V4: 441.3 | W4: 459.7 | X4: 458.7 | Y4: 440.5 | Z4: 422.6 | AA4: 443.6 | AB4: 451.3 | AC4: 458.5 | AD4: 440.5 | AE4: 452.8 | AF4: 454.9 | AG4: 455.8 | AH4: 432.6 | AI4: 442 | AJ4: 446.6 | AK4: 446.2
A5: 4 | B5: 450.8 | C5: 453.2 | D5: 443.5 | E5: 462.6 | F5: 455.4 | G5: 469.8 | H5: 451.4 | I5: 456.3 | J5: 437.1 | K5: 452.1 | L5: 434.3 | M5: 446.3 | N5: 427.5 | O5: 436.7 | P5: 446.3 | Q5: 427.9 | R5: 448 | S5: 429.5 | T5: 448.3 | U5: 446.3 | V5: 427.2 | W5: 455.1 | X5: 454.9 | Y5: 461.7 | Z5: 443.2 | AA5: 426.1 | AB5: 452.3 | AC5: 464.4 | AD5: 445 | AE5: 452.2 | AF5: 465.4 | AG5: 448.6 | AH5: 451.7 | AI5: 430.5 | AJ5: 462 | AK5: 442.6
A6: 5 | B6: 469 | C6: 467.4 | D6: 465.8 | E6: 464.9 | F6: 469.3 | G6: 468.4 | H6: 467.3 | I6: 465.7 | J6: 464.5 | K6: 463.8 | L6: 462.9 | M6: 459.8 | N6: 459.8 | O6: 459 | P6: 476.3 | Q6: 475.4 | R6: 474.8 | S6: 472.9 | T6: 474.8 | U6: 473.8 | V6: 463.1 | W6: 472.3 | X6: 471.8 | Y6: 471.2 | Z6: 470.2 | AA6: 469.1 | AB6: 468 | AC6: 466.8 | AD6: 465.8 | AE6: 464.7 | AF6: 475.6 | AG6: 474.5 | AH6: 473.2 | AI6: 469.3 | AJ6: 470.9 | AK6: 469.9
A7: 6 | B7: 443.9 | C7: 456.5 | D7: 466.3 | E7: 453.5 | F7: 445.3 | G7: 459.5 | H7: 443.7 | I7: 451.3 | J7: 461.8 | K7: 461.5 | L7: 460 | M7: 450.9 | N7: 441.7 | O7: 460.6 | P7: 474.5 | Q7: 469.9 | R7: 463.3 | S7: 455.2 | T7: 460.9 | U7: 450.2 | V7: 447 | W7: 470.1 | X7: 459.5 | Y7: 446.3 | Z7: 467.1 | AA7: 456.2 | AB7: 459.3 | AC7: 444.3 | AD7: 456.4 | AE7: 460.2 | AF7: 463 | AG7: 449.7 | AH7: 456.1 | AI7: 438 | AJ7: 455.1 | AK7: 453.8
A8: 7 | B8: 449.6 | C8: 462.3 | D8: 448.8 | E8: 462.3 | F8: 453.6 | G8: 461.6 | H8: 444.5 | I8: 462.6 | J8: 465.2 | K8: 464.7 | L8: 464.9 | M8: 464.7 | N8: 450.2 | O8: 462.5 | P8: 452.7 | Q8: 468.5 | R8: 448.8 | S8: 452.2 | T8: 459.3 | U8: 458.8 | V8: 445.4 | W8: 467.5 | X8: 462.3 | Y8: 455.5 | Z8: 434.3 | AA8: 462.3 | AB8: 456.2 | AC8: 434.2 | AD8: 453.9 | AE8: 456.3 | AF8: 470.1 | AG8: 453 | AH8: 458.4 | AI8: 434.1 | AJ8: 448.2 | AK8: 455
A9: 8 | B9: 443 | C9: 447.3 | D9: 458.2 | E9: 437.1 | F9: 458.4 | G9: 454.9 | H9: 458.4 | I9: 464.5 | J9: 465.7 | K9: 468.1 | L9: 451.6 | M9: 459.5 | N9: 441 | O9: 461 | P9: 452.2 | Q9: 463.2 | R9: 444.5 | S9: 449.2 | T9: 468.4 | U9: 461 | V9: 446.5 | W9: 461 | X9: 468 | Y9: 448.1 | Z9: 468.6 | AA9: 449.6 | AB9: 458.1 | AC9: 439.4 | AD9: 458.4 | AE9: 461.4 | AF9: 470.4 | AG9: 448.4 | AH9: 457.7 | AI9: 432.7 | AJ9: 444.2 | AK9: 461.8
A10: 9 | B10: 467.4 | C10: 441.3 | D10: 465.9 | E10: 464.6 | F10: 467.8 | G10: 466.3 | H10: 465.3 | I10: 463.3 | J10: 462.3 | K10: 460.8 | L10: 477 | M10: 474.5 | N10: 474.7 | O10: 473.6 | P10: 479.8 | Q10: 478.5 | R10: 477.5 | S10: 475.8 | T10: 477.7 | U10: 476.3 | V10: 475.7 | W10: 471.2 | X10: 470.5 | Y10: 469.4 | Z10: 468.7 | AA10: 467.5 | AB10: 466.6 | AC10: 465.6 | AD10: 464.3 | AE10: 462 | AF10: 484.3 | AG10: 482.3 | AH10: 481.4 | AI10: 475.7 | AJ10: 476.9 | AK10: 475
A11: 10 | B11: 468.6 | C11: 468 | D11: 466.5 | E11: 462 | F11: 475.4 | G11: 474.4 | H11: 473.6 | I11: 472 | J11: 471.1 | K11: 470.3 | L11: 469 | M11: 466.6 | N11: 466.7 | O11: 466 | P11: 477.7 | Q11: 476.8 | R11: 476.1 | S11: 475.2 | T11: 476.9 | U11: 475.5 | V11: 474.9 | W11: 473.5 | X11: 472.6 | Y11: 471.9 | Z11: 470 | AA11: 468.7 | AB11: 467.6 | AC11: 465.6 | AD11: 475.8 | AE11: 474.9 | AF11: 487.1 | AG11: 486 | AH11: 484.9 | AI11: 480.9 | AJ11: 482.5 | AK11: 481.3
A12: 11 | B12: 463.9 | C12: 456 | D12: 446.3 | E12: 462.9 | F12: 465 | G12: 465 | H12: 465 | I12: 455.3 | J12: 477.4 | K12: 477.4 | L12: 477.3 | M12: 465.4 | N12: 456.4 | O12: 445.1 | P12: 454.7 | Q12: 444.1 | R12: 457.6 | S12: 447.6 | T12: 457.5 | U12: 460 | V12: 450.1 | W12: 470.7 | X12: 460.2 | Y12: 449.9 | Z12: 480.6 | AA12: 472.7 | AB12: 463.4 | AC12: 454.9 | AD12: 461.1 | AE12: 449.5 | AF12: 474.8 | AG12: 464.7 | AH12: 455.6 | AI12: 441.1 | AJ12: 454.8 | AK12: 466.3
A13: 12 | B13: 454 | C13: 441.5 | D13: 466.5 | E13: 450.5 | F13: 461.4 | G13: 447.5 | H13: 456 | I13: 465.4 | J13: 450.7 | K13: 458.4 | L13: 461.4 | M13: 445.1 | N13: 431.4 | O13: 459.7 | P13: 453.9 | Q13: 438.1 | R13: 458.3 | S13: 454.3 | T13: 452.8 | U13: 448 | V13: 433 | W13: 460.5 | X13: 462 | Y13: 446.1 | Z13: 466.1 | AA13: 449.7 | AB13: 461 | AC13: 447 | AD13: 453.9 | AE13: 461.5 | AF13: 467.7 | AG13: 452.3 | AH13: 461.4 | AI13: 446.9 | AJ13: 437.2 | AK13: 461.2
... A21: 20 | B21: 457.6 | C21: 453.3 | D21: 452.4 | E21: 451.2 | F21: 462.9 | G21: 461.8 | H21: 460.4 | I21: 472 | J21: 470.8 | K21: 470.2 | L21: 469.2 | M21: 466.9 | N21: 467 | O21: 466.2 | P21: 479.8 | Q21: 479 | R21: 478.2 | S21: 477.5 | T21: 479.5 | U21: 478.4 | V21: 477.8 | W21: 476.7 | X21: 475.6 | Y21: 474.7 | Z21: 473.8 | AA21: 472.2 | AB21: 471.4 | AC21: 469.9 | AD21: 468.5 | AE21: 467.6 | AF21: 484.2 | AG21: 483.1 | AH21: 482.3 | AI21: 478.1 | AJ21: 479.6 | AK21: 478.8
A22: 21 | B22: nan | C22: 439.6 | D22: 457.3 | E22: 448.5 | F22: 446.9 | G22: 436.4 | H22: 464.4 | I22: 456.2 | J22: 448 | K22: 459.4 | L22: 451.7 | M22: 440 | N22: 431.2 | O22: 454.8 | P22: 452.1 | Q22: 439.5 | R22: 446.1 | S22: 447.3 | T22: 445.8 | U22: 450.3 | V22: 438.7 | W22: 427.8 | X22: 453.2 | Y22: 442.1 | Z22: 463.1 | AA22: 451.1 | AB22: 448.3 | AC22: 452 | AD22: 439.7 | AE22: 450.6 | AF22: 459.5 | AG22: 445.8 | AH22: 432.7 | AI22: 417.3 | AJ22: 442.1 | AK22: 449.7
A23: 22 | B23: 433.1 | C23: 419.9 | D23: 453.1 | E23: 439.1 | F23: 436.9 | G23: 451.1 | H23: 437.6 | I23: 454.3 | J23: 439.9 | K23: 456.1 | L23: 452.4 | M23: 436.9 | N23: 423.1 | O23: 447.3 | P23: 441.4 | Q23: 429.5 | R23: 441.8 | S23: 443.1 | T23: 445 | U23: 448.6 | V23: 435.6 | W23: 417.7 | X23: 453.7 | Y23: 437.3 | Z23: 460.5 | AA23: 446.4 | AB23: 443.2 | AC23: 453.8 | AD23: 439.5 | AE23: 442.8 | AF23: 453.7 | AG23: 449.9 | AH23: 434.1 | AI23: 417 | AJ23: 445.8 | AK23: 446.3
A24: 23 | B24: 471.3 | C24: 464.6 | D24: 457.4 | E24: 446.6 | F24: 449 | G24: 436 | H24: 446.7 | I24: 456.9 | J24: 447.3 | K24: 457.7 | L24: 448.3 | M24: 452.2 | N24: 441.3 | O24: 427.6 | P24: 440.5 | Q24: 425.9 | R24: 448.8 | S24: 436.4 | T24: 446.2 | U24: 448.4 | V24: 436.3 | W24: 457.9 | X24: 457.6 | Y24: 445.2 | Z24: 427 | AA24: 460 | AB24: 444.1 | AC24: 450.7 | AD24: 452.3 | AE24: 450.2 | AF24: 459 | AG24: 445.2 | AH24: 430.8 | AI24: 413.9 | AJ24: 444.2 | AK24: 450.4
A25: 24 | B25: 438.5 | C25: 427.4 | D25: 440.7 | E25: 444 | F25: 453.4 | G25: 451.7 | H25: 429.3 | I25: 442.5 | J25: 449.8 | K25: 424.6 | L25: 447.3 | M25: 440.8 | N25: 421 | O25: 434.5 | P25: 437.7 | Q25: 416.9 | R25: 428.4 | S25: 433.3 | T25: 440 | U25: 441.5 | V25: 423.1 | W25: 449 | X25: 444.6 | Y25: 421.1 | Z25: 456.6 | AA25: 430.8 | AB25: 437.2 | AC25: 449.9 | AD25: 438.8 | AE25: 435.7 | AF25: 442.5 | AG25: 433.4 | AH25: 433 | AI25: 403.8 | AJ25: 432.3 | AK25: 436.2
A26: 25 | B26: 448.8 | C26: 434.5 | D26: 456.5 | E26: 439.1 | F26: 443.9 | G26: 447.3 | H26: 436.7 | I26: 447.4 | J26: 448.3 | K26: 450.6 | L26: 450.7 | M26: 444.1 | N26: 423.2 | O26: 436.6 | P26: 437.2 | Q26: 412.6 | R26: 444 | S26: 427.3 | T26: 443.3 | U26: 442.9 | V26: 452.6 | W26: 428.2 | X26: 440.2 | Y26: 432.3 | Z26: 449.6 | AA26: 425.8 | AB26: 435.3 | AC26: 449.8 | AD26: 440.6 | AE26: 436.9 | AF26: 447.6 | AG26: 433.7 | AH26: 443.8 | AI26: 416.2 | AJ26: 446.9 | AK26: 437.3
A27: 26 | B27: 417.9 | C27: 447.4 | D27: 439.4 | E27: 450.3 | F27: 451.4 | G27: 441.1 | H27: 428.6 | I27: 447.1 | J27: 431.5 | K27: 444.8 | L27: 428.6 | M27: 441.3 | N27: 423.8 | O27: 431.9 | P27: 434.8 | Q27: 417.9 | R27: 443.2 | S27: 438.4 | T27: 451.6 | U27: 436.2 | V27: 441.9 | W27: 423.5 | X27: 450 | Y27: 430.9 | Z27: 453.1 | AA27: 434.2 | AB27: 439.2 | AC27: 452.6 | AD27: 433 | AE27: 446 | AF27: 455.3 | AG27: 438.4 | AH27: 422.4 | AI27: 438.2 | AJ27: 424.1 | AK27: 438.2
A28: 27 | B28: 452.4 | C28: 445 | D28: 460.9 | E28: 451.4 | F28: 449.4 | G28: 448.5 | H28: 437.4 | I28: 456.1 | J28: 444.5 | K28: 451 | L28: 439.1 | M28: 449 | N28: 436.9 | O28: 446.9 | P28: 442.5 | Q28: 430 | R28: 445 | S28: 448.6 | T28: 446.6 | U28: 450.1 | V28: 440 | W28: 424.5 | X28: 445.9 | Y28: 430.8 | Z28: 457.2 | AA28: 444.1 | AB28: 446.2 | AC28: 456.6 | AD28: 443.2 | AE28: 448.1 | AF28: 461 | AG28: 445.2 | AH28: 429.7 | AI28: 412.9 | AJ28: 456.1 | AK28: 442.6
A29: 28 | B29: 441.4 | C29: 438 | D29: 461.9 | E29: 455.7 | F29: 449.8 | G29: 463.1 | H29: 453.9 | I29: 446.3 | J29: 453.1 | K29: 457.1 | L29: 447.8 | M29: 458.4 | N29: 448.9 | O29: 439.3 | P29: 455.6 | Q29: 446 | R29: 451.2 | S29: 456.2 | T29: 458 | U29: 453.3 | V29: 466.6 | W29: 455.8 | X29: 459.8 | Y29: 450.9 | Z29: 468.3 | AA29: 456.9 | AB29: 446.1 | AC29: 463.3 | AD29: 451.7 | AE29: 455.4 | AF29: 465.7 | AG29: 457.3 | AH29: 447.7 | AI29: 458.1 | AJ29: 452.7 | AK29: 462.3
A30: 29 | B30: 450.5 | C30: 447.6 | D30: 446.1 | E30: 465 | F30: 462 | G30: 460.1 | H30: 457.8 | I30: 456.2 | J30: 454.5 | K30: 468 | L30: 466.8 | M30: 464.7 | N30: 464.7 | O30: 463.9 | P30: 476.6 | Q30: 475.7 | R30: 474.9 | S30: 474.2 | T30: 475.9 | U30: 474.7 | V30: 474.2 | W30: 473 | X30: 472 | Y30: 471.1 | Z30: 470 | AA30: 468.6 | AB30: 467.2 | AC30: 465.1 | AD30: 463.9 | AE30: 462.6 | AF30: 472.6 | AG30: 471.3 | AH30: 469.4 | AI30: 463.5 | AJ30: 464.4 | AK30: 461.7
A31: 30 | B31: 440.5 | C31: 435 | D31: 431.8 | E31: 461.2 | F31: 463 | G31: 459.9 | H31: 454.3 | I31: 468.2 | J31: 461.1 | K31: 452.6 | L31: 465.4 | M31: 456.3 | N31: 448.5 | O31: 442 | P31: 448.5 | Q31: 442.2 | R31: 455.5 | S31: 448.5 | T31: 454.9 | U31: 459.1 | V31: 455.2 | W31: 451.1 | X31: 459.7 | Y31: 454.7 | Z31: 448.3 | AA31: 441.3 | AB31: 456.8 | AC31: 448 | AD31: 459.9 | AE31: 450.8 | AF31: 468.1 | AG31: 461.2 | AH31: 455.4 | AI31: 447.3 | AJ31: 445.6 | AK31: 460.1
A32: 31 | B32: 454.7 | C32: 449.9 | D32: 434.7 | E32: 451.2 | F32: 460.1 | G32: 448.9 | H32: 434.2 | I32: 450.1 | J32: 450.3 | K32: 457.8 | L32: 455.6 | M32: 452.8 | N32: 443.6 | O32: 433.1 | P32: 448.1 | Q32: 438.7 | R32: 448.1 | S32: 451.2 | T32: 454.1 | U32: 445.7 | V32: 468.7 | W32: 457 | X32: 460.2 | Y32: 452.2 | Z32: 444 | AA32: 470.6 | AB32: 462.9 | AC32: 450.8 | AD32: 437.6 | AE32: 454.9 | AF32: 465.6 | AG32: 453.7 | AH32: 442.3 | AI32: 442.1 | AJ32: 450.8 | AK32: 441
A33: 32 | B33: 435.3 | C33: 446.6 | D33: 445.4 | E33: 462.4 | F33: 450.9 | G33: 449.5 | H33: 446.8 | I33: 445.3 | J33: 442.6 | K33: 465.6 | L33: 462.4 | M33: 458.2 | N33: 455.8 | O33: 453.3 | P33: 464.4 | Q33: 459.5 | R33: 453.9 | S33: 449.4 | T33: 443.3 | U33: 452.8 | V33: 446.1 | W33: 439.3 | X33: 457.2 | Y33: 449.5 | Z33: 441.9 | AA33: 434.8 | AB33: 452.9 | AC33: 447.5 | AD33: 450.6 | AE33: 446.7 | AF33: 468.7 | AG33: 462.6 | AH33: 453.7 | AI33: 441 | AJ33: 435.2 | AK33: 453.4
A34: 33 | B34: 454.1 | C34: 465.7 | D34: 458.6 | E34: 447.8 | F34: 459 | G34: 448.6 | H34: 434.4 | I34: 455.4 | J34: 452.6 | K34: 452.9 | L34: 456 | M34: 438.5 | N34: 422.9 | O34: 449.5 | P34: 451.3 | Q34: 437.6 | R34: 445.5 | S34: 449 | T34: 450.9 | U34: 436.7 | V34: 442.4 | W34: 424.7 | X34: 445.7 | Y34: 447.2 | Z34: 451.4 | AA34: 435.3 | AB34: 444.2 | AC34: 452.5 | AD34: 435 | AE34: 451.1 | AF34: 454.5 | AG34: 452.8 | AH34: 438.6 | AI34: 448.5 | AJ34: 430.1 | AK34: 445.4
... A39: 38 | B39: 417.3 | C39: 438.8 | D39: 426 | E39: 447.3 | F39: 449.6 | G39: 435.4 | H39: 443.3 | I39: 444 | J39: 449.8 | K39: 443.1 | L39: 427.5 | M39: 441.2 | N39: 424.9 | O39: 408.5 | P39: 432.1 | Q39: 448.7 | R39: 435 | S39: 440.9 | T39: 428.8 | U39: 443.4 | V39: 428.5 | W39: 452 | X39: 434.7 | Y39: 435.7 | Z39: 457.1 | AA39: 443.1 | AB39: 426.3 | AC39: 451.1 | AD39: 425 | AE39: 443 | AF39: 455.2 | AG39: 438.5 | AH39: 446.7 | AI39: 446.3 | AJ39: 431.8 | AK39: 445.5
A40: 39 | B40: 444.7 | C40: 443 | D40: 441.6 | E40: 464.9 | F40: 449.9 | G40: 448.9 | H40: 445 | I40: 462.5 | J40: 460.5 | K40: 457.6 | L40: 452.4 | M40: 448.1 | N40: 443 | O40: 434.4 | P40: 445.7 | Q40: 436.7 | R40: 452.2 | S40: 438.1 | T40: NAN | U40: 441 | V40: 445.7 | W40: 422.5 | X40: 439.5 | Y40: 417.1 | Z40: 454.1 | AA40: 434.1 | AB40: 442 | AC40: 454.3 | AD40: 430.4 | AE40: 438.4 | AF40: 445.1 | AG40: 435 | AH40: 434.3 | AI40: 430.9 | AJ40: 437.9 | AK40: 439.7
A41: 40 | B41: 449.8 | C41: 448.2 | D41: 447.1 | E41: 445.8 | F41: 447.1 | G41: 463.9 | H41: 462.8 | I41: 459.7 | J41: 457.7 | K41: 456.7 | L41: 455.2 | M41: 452.8 | N41: 452.8 | O41: 451.9 | P41: 456.7 | Q41: 455.5 | R41: 454.7 | S41: 465.2 | T41: NAN | U41: 465.3 | V41: 464.6 | W41: 463.5 | X41: 468.2 | Y41: 461.2 | Z41: 460 | AA41: 458.6 | AB41: 457.8 | AC41: 456.5 | AD41: 455 | AE41: 453.8 | AF41: 466.5 | AG41: 465.1 | AH41: 463.9 | AI41: 459.7 | AJ41: 461.1 | AK41: 460
A42: 41 | B42: 437.2 | C42: 442.2 | D42: 429.3 | E42: 457.9 | F42: 437.6 | G42: 443.3 | H42: 430 | I42: 447 | J42: 444.9 | K42: 446.9 | L42: 432.5 | M42: 440.8 | N42: 424.1 | O42: 443.8 | P42: 444.8 | Q42: 430 | R42: 444.1 | S42: 442.6 | T42: NAN | U42: 447.5 | V42: 430.6 | W42: 457.5 | X42: 441.7 | Y42: 439.9 | Z42: 459.3 | AA42: 443.2 | AB42: 445.6 | AC42: 428.6 | AD42: 439.7 | AE42: 451 | AF42: 451.3 | AG42: 449.8 | AH42: 431.9 | AI42: 437.2 | AJ42: 449.9 | AK42: 431.9
A43: 42 | B43: 445.8 | C43: 465.6 | D43: 458.3 | E43: 454.5 | F43: 450 | G43: 454.7 | H43: 447.6 | I43: 441.4 | J43: 459.3 | K43: 452.8 | L43: 443.8 | M43: 457.4 | N43: 448.6 | O43: 441 | P43: 456.3 | Q43: 448.3 | R43: 442.7 | S43: 458.7 | T43: NAN | U43: 447.7 | V43: 441.6 | W43: 433.8 | X43: 453.4 | Y43: 445.9 | Z43: 437.2 | AA43: 457.5 | AB43: 448.4 | AC43: 465.1 | AD43: 456.1 | AE43: 446.4 | AF43: 467.8 | AG43: 459.6 | AH43: 450.4 | AI43: 444.2 | AJ43: 437.7 | AK43: 455
A44: 43 | B44: 457.6 | C44: 456.9 | D44: 450.4 | E44: 443.6 | F44: 452.8 | G44: 443.9 | H44: 455.6 | I44: 447.6 | J44: 454.2 | K44: 445.4 | L44: 458.4 | M44: 446.9 | N44: 438 | O44: 429.9 | P44: 444.4 | Q44: 434.5 | R44: 453.5 | S44: 443.8 | T44: NAN | U44: 450.8 | V44: 439.8 | W44: 464.7 | X44: 450.3 | Y44: 437.2 | Z44: 426.7 | AA44: 456.4 | AB44: 443.4 | AC44: 464.9 | AD44: 452 | AE44: 452.8 | AF44: 455.9 | AG44: 456.3 | AH44: 442.9 | AI44: 435.9 | AJ44: 463.4 | AK44: 450.5
A45: 44 | B45: 454.2 | C45: 449.7 | D45: 441.4 | E45: 461.6 | F45: 454.7 | G45: 442.6 | H45: 451.7 | I45: 441.4 | J45: 459 | K45: 445.7 | L45: 452.9 | M45: 437.8 | N45: 425 | O45: 429 | P45: 439 | Q45: 460.3 | R45: 446.1 | S45: 450.7 | T45: NAN | U45: 442.3 | V45: 451.9 | W45: 436.7 | X45: 450.6 | Y45: 432.2 | Z45: 464.2 | AA45: 450.2 | AB45: 435 | AC45: 458.3 | AD45: 442.5 | AE45: 450.5 | AF45: 465.9 | AG45: 450.3 | AH45: 434 | AI45: 444.1 | AJ45: 457 | AK45: 442.3
A46: 45 | B46: 440.5 | C46: 436.9 | D46: 458.8 | E46: 447.1 | F46: 449.3 | G46: 445 | H46: 456.2 | I46: 445 | J46: 457.4 | K46: 453.9 | L46: 442.3 | M46: 446.4 | N46: 432.6 | O46: 440.2 | P46: 447.9 | Q46: 455.7 | R46: 441.2 | S46: 445.6 | T46: NAN | U46: 444.9 | V46: 447 | W46: 431.5 | X46: 445.3 | Y46: 431 | Z46: 456 | AA46: 442.5 | AB46: 446.8 | AC46: 429.9 | AD46: 448.3 | AE46: 433.2 | AF46: 458.8 | AG46: 441.9 | AH46: 426.8 | AI46: 447.4 | AJ46: 433.9 | AK46: 448.3
A47: 46 | B47: 427 | C47: 438.9 | D47: 450 | E47: 434.6 | F47: 445 | G47: 441.6 | H47: 447.2 | I47: 445.6 | J47: 445.1 | K47: 422.8 | L47: 445.9 | M47: 442.3 | N47: 411.7 | O47: 425.9 | P47: 450.3 | Q47: 423.7 | R47: 440.9 | S47: 446.2 | T47: NAN | U47: 449.2 | V47: 444.4 | W47: 452.4 | X47: 439.5 | Y47: 435.4 | Z47: 462.2 | AA47: 437.2 | AB47: 443.1 | AC47: 453.4 | AD47: 446.2 | AE47: 444.8 | AF47: 447.7 | AG47: 449 | AH47: 445.2 | AI47: 442.1 | AJ47: 444.5 | AK47: 441
A48: 47 | B48: 423.8 | C48: 452.3 | D48: 434.9 | E48: 463.3 | F48: 453.7 | G48: 466.2 | H48: 457.1 | I48: 441.8 | J48: 449.6 | K48: 435.9 | L48: 465.4 | M48: 456.3 | N48: 442.5 | O48: 431.1 | P48: 451.2 | Q48: 441.7 | R48: 436.6 | S48: 456.6 | T48: NAN | U48: 446.7 | V48: 441.2 | W48: 476 | X48: 469.1 | Y48: 458.7 | Z48: 443.6 | AA48: 454.4 | AB48: 435.2 | AC48: 471.9 | AD48: 456 | AE48: 457.6 | AF48: 460.3 | AG48: 444.9 | AH48: 430.9 | AI48: 461.3 | AJ48: 452.8 | AK48: 440.9
A49: 48 | B49: 426.1 | C49: 435.3 | D49: 462.2 | E49: 444.1 | F49: 431.2 | G49: 445.6 | H49: 417.7 | I49: 442.6 | J49: 440.5 | K49: 416.7 | L49: 435.3 | M49: 434.8 | N49: 407.3 | O49: 418.2 | P49: 424 | Q49: 441.9 | R49: 433.9 | S49: 436.9 | T49: NAN | U49: 432.2 | V49: 444.1 | W49: 413 | X49: 429.9 | Y49: 428.3 | Z49: 443.3 | AA49: 451.8 | AB49: 422.9 | AC49: 440.7 | AD49: 429.5 | AE49: 434.8 | AF49: 440.1 | AG49: 432.6 | AH49: 443.6 | AI49: 435 | AJ49: 404.5 | AK49: 431.2
A50: 49 | B50: 454 | C50: 464.4 | D50: 463.8 | E50: 462.5 | F50: 467.3 | G50: 465.8 | H50: 462.8 | I50: 457.8 | J50: 472.7 | K50: 465.5 | L50: 458 | M50: 464.6 | N50: 450.9 | O50: 443.3 | P50: 446.9 | Q50: 465.5 | R50: 455.3 | S50: 440.6 | T50: NAN | U50: 452.1 | V50: 440.3 | W50: 468 | X50: 456.4 | Y50: 442 | Z50: 468.5 | AA50: 454.1 | AB50: 454.5 | AC50: 466.9 | AD50: 450.9 | AE50: 453.4 | AF50: 463.1 | AG50: 449.4 | AH50: 441.1 | AI50: 454 | AJ50: 445.7 | AK50: 460.3
A51: 50 | B51: 425.6 | C51: 430.3 | D51: 451.2 | E51: 443.5 | F51: 446.2 | G51: 433.5 | H51: 456.8 | I51: 446.8 | J51: 453.5 | K51: 438.6 | L51: 447.9 | M51: 441.2 | N51: 428.6 | O51: 431.8 | P51: 435.4 | Q51: 452.9 | R51: 433 | S51: 439.3 | T51: NAN | U51: 436.4 | V51: 423.1 | W51: 455.3 | X51: 434.8 | Y51: 441.2 | Z51: 451.3 | AA51: 432.4 | AB51: 441.1 | AC51: 454.6 | AD51: 437.4 | AE51: 444 | AF51: 447 | AG51: 426.8 | AH51: 443.6 | AI51: 439.1 | AJ51: 426 | AK51: 437.5
...

Sheet E_g
A1: ID | B1: 45873 | C1: 45875 | D1: 45877 | E1: 45880 | F1: 45882 | G1: 45884 | H1: 45887 | I1: 45889 | J1: 45891 | K1: 45894 | L1: 45896 | M1: 45898 | N1: 45901 | O1: 45903 | P1: 45905 | Q1: 45908 | R1: 45910 | S1: 45912 | T1: 45915 | U1: 45917 | V1: 45919 | W1: 45922 | X1: 45924 | Y1: 45926 | Z1: 45929 | AA1: 45931 | AB1: 45933 | AC1: 45936 | AD1: 45938 | AE1: 45940 | AF1: 45943 | AG1: 45945 | AH1: 45947 | AI1: 45950 | AJ1: 45952 | AK1: 45954
A2: 1 | B2: =eth_ON!B2 - eth_OFF!B2 - AVERAGE(B$62:B$63) -> 4.35 | C2: =eth_ON!C2 - eth_OFF!C2 - AVERAGE(C$62:C$63) -> 7.15 | D2: =eth_ON!D2 - eth_OFF!D2 - AVERAGE(D$62:D$63) -> 9.05 | E2: =eth_ON!E2 - eth_OFF!E2 - AVERAGE(E$62:E$63) -> 9.95 | F2: =eth_ON!F2 - eth_OFF!F2 - AVERAGE(F$62:F$63) -> 10.1 | G2: =eth_ON!G2 - eth_OFF!G2 - AVERAGE(G$62:G$63) -> 11.15 | H2: =eth_ON!H2 - eth_OFF!H2 - AVERAGE(H$62:H$63) -> 11.15 | I2: =eth_ON!I2 - eth_OFF!I2 - AVERAGE(I$62:I$63) -> 11.75 | ... AK2: =eth_ON!AK2 - eth_OFF!AK2 - AVERAGE(AK$62:AK$63) -> 11.2
A3: 2 | B3: =eth_ON!B3 - eth_OFF!B3 - AVERAGE(B$62:B$63) -> 0.15 | C3: =eth_ON!C3 - eth_OFF!C3 - AVERAGE(C$62:C$63) -> -0.45 | D3: =eth_ON!D3 - eth_OFF!D3 - AVERAGE(D$62:D$63) -> 0.05 | E3: =eth_ON!E3 - eth_OFF!E3 - AVERAGE(E$62:E$63) -> 3.65 | F3: =eth_ON!F3 - eth_OFF!F3 - AVERAGE(F$62:F$63) -> 3.5 | G3: =eth_ON!G3 - eth_OFF!G3 - AVERAGE(G$62:G$63) -> 8.05 | H3: =eth_ON!H3 - eth_OFF!H3 - AVERAGE(H$62:H$63) -> 5.65 | I3: =eth_ON!I3 - eth_OFF!I3 - AVERAGE(I$62:I$63) -> 3.65 | ... AK3: =eth_ON!AK3 - eth_OFF!AK3 - AVERAGE(AK$62:AK$63) -> 6.8
A4: 3 | B4: =eth_ON!B4 - eth_OFF!B4 - AVERAGE(B$62:B$63) -> 12.85 | C4: =eth_ON!C4 - eth_OFF!C4 - AVERAGE(C$62:C$63) -> 11.65 | D4: =eth_ON!D4 - eth_OFF!D4 - AVERAGE(D$62:D$63) -> 14.45 | E4: =eth_ON!E4 - eth_OFF!E4 - AVERAGE(E$62:E$63) -> 18.45 | F4: =eth_ON!F4 - eth_OFF!F4 - AVERAGE(F$62:F$63) -> 17 | G4: =eth_ON!G4 - eth_OFF!G4 - AVERAGE(G$62:G$63) -> 16.75 | H4: =eth_ON!H4 - eth_OFF!H4 - AVERAGE(H$62:H$63) -> 18.25 | I4: =eth_ON!I4 - eth_OFF!I4 - AVERAGE(I$62:I$63) -> 17.15 | ... AK4: =eth_ON!AK4 - eth_OFF!AK4 - AVERAGE(AK$62:AK$63) -> 21.1
A5: 4 | B5: =eth_ON!B5 - eth_OFF!B5 - AVERAGE(B$62:B$63) -> 12.05 | C5: =eth_ON!C5 - eth_OFF!C5 - AVERAGE(C$62:C$63) -> 8.15 | D5: =eth_ON!D5 - eth_OFF!D5 - AVERAGE(D$62:D$63) -> 8.85 | E5: =eth_ON!E5 - eth_OFF!E5 - AVERAGE(E$62:E$63) -> 12.15 | F5: =eth_ON!F5 - eth_OFF!F5 - AVERAGE(F$62:F$63) -> 12.5 | G5: =eth_ON!G5 - eth_OFF!G5 - AVERAGE(G$62:G$63) -> 12.35 | H5: =eth_ON!H5 - eth_OFF!H5 - AVERAGE(H$62:H$63) -> 16.95 | I5: =eth_ON!I5 - eth_OFF!I5 - AVERAGE(I$62:I$63) -> 16.15 | ... AK5: =eth_ON!AK5 - eth_OFF!AK5 - AVERAGE(AK$62:AK$63) -> 18.3
A6: 5 | B6: =eth_ON!B6 - eth_OFF!B6 - AVERAGE(B$62:B$63) -> 1.35 | C6: =eth_ON!C6 - eth_OFF!C6 - AVERAGE(C$62:C$63) -> -0.25 | D6: =eth_ON!D6 - eth_OFF!D6 - AVERAGE(D$62:D$63) -> 0.85 | E6: =eth_ON!E6 - eth_OFF!E6 - AVERAGE(E$62:E$63) -> 0.05 | F6: =eth_ON!F6 - eth_OFF!F6 - AVERAGE(F$62:F$63) -> -0.1 | G6: =eth_ON!G6 - eth_OFF!G6 - AVERAGE(G$62:G$63) -> 0.05 | H6: =eth_ON!H6 - eth_OFF!H6 - AVERAGE(H$62:H$63) -> 0.15 | I6: =eth_ON!I6 - eth_OFF!I6 - AVERAGE(I$62:I$63) -> 0.65 | ... AK6: =eth_ON!AK6 - eth_OFF!AK6 - AVERAGE(AK$62:AK$63) -> 2.8421709e-14
A7: 6 | B7: =eth_ON!B7 - eth_OFF!B7 - AVERAGE(B$62:B$63) -> 16.95 | C7: =eth_ON!C7 - eth_OFF!C7 - AVERAGE(C$62:C$63) -> 6.85 | D7: =eth_ON!D7 - eth_OFF!D7 - AVERAGE(D$62:D$63) -> 9.25 | E7: =eth_ON!E7 - eth_OFF!E7 - AVERAGE(E$62:E$63) -> 11.85 | F7: =eth_ON!F7 - eth_OFF!F7 - AVERAGE(F$62:F$63) -> 16.4 | G7: =eth_ON!G7 - eth_OFF!G7 - AVERAGE(G$62:G$63) -> 16.25 | H7: =eth_ON!H7 - eth_OFF!H7 - AVERAGE(H$62:H$63) -> 14.65 | I7: =eth_ON!I7 - eth_OFF!I7 - AVERAGE(I$62:I$63) -> 13.75 | ... AK7: =eth_ON!AK7 - eth_OFF!AK7 - AVERAGE(AK$62:AK$63) -> 17.1
A8: 7 | B8: =eth_ON!B8 - eth_OFF!B8 - AVERAGE(B$62:B$63) -> 14.35 | C8: =eth_ON!C8 - eth_OFF!C8 - AVERAGE(C$62:C$63) -> 5.55 | D8: =eth_ON!D8 - eth_OFF!D8 - AVERAGE(D$62:D$63) -> 12.75 | E8: =eth_ON!E8 - eth_OFF!E8 - AVERAGE(E$62:E$63) -> 14.15 | F8: =eth_ON!F8 - eth_OFF!F8 - AVERAGE(F$62:F$63) -> 15.1 | G8: =eth_ON!G8 - eth_OFF!G8 - AVERAGE(G$62:G$63) -> 13.45 | H8: =eth_ON!H8 - eth_OFF!H8 - AVERAGE(H$62:H$63) -> 16.05 | I8: =eth_ON!I8 - eth_OFF!I8 - AVERAGE(I$62:I$63) -> 13.95 | ... AK8: =eth_ON!AK8 - eth_OFF!AK8 - AVERAGE(AK$62:AK$63) -> 18.4
A9: 8 | B9: =eth_ON!B9 - eth_OFF!B9 - AVERAGE(B$62:B$63) -> 20.85 | C9: =eth_ON!C9 - eth_OFF!C9 - AVERAGE(C$62:C$63) -> 15.25 | D9: =eth_ON!D9 - eth_OFF!D9 - AVERAGE(D$62:D$63) -> 15.05 | E9: =eth_ON!E9 - eth_OFF!E9 - AVERAGE(E$62:E$63) -> 20.15 | F9: =eth_ON!F9 - eth_OFF!F9 - AVERAGE(F$62:F$63) -> 14.5 | G9: =eth_ON!G9 - eth_OFF!G9 - AVERAGE(G$62:G$63) -> 17.55 | H9: =eth_ON!H9 - eth_OFF!H9 - AVERAGE(H$62:H$63) -> 17.25 | I9: =eth_ON!I9 - eth_OFF!I9 - AVERAGE(I$62:I$63) -> 15.45 | ... AK9: =eth_ON!AK9 - eth_OFF!AK9 - AVERAGE(AK$62:AK$63) -> 18.3
A10: 9 | B10: =eth_ON!B10 - eth_OFF!B10 - AVERAGE(B$62:B$63) -> 1.55 | C10: =eth_ON!C10 - eth_OFF!C10 - AVERAGE(C$62:C$63) -> 0.15 | D10: =eth_ON!D10 - eth_OFF!D10 - AVERAGE(D$62:D$63) -> 7.45 | E10: =eth_ON!E10 - eth_OFF!E10 - AVERAGE(E$62:E$63) -> 0.25 | F10: =eth_ON!F10 - eth_OFF!F10 - AVERAGE(F$62:F$63) -> -2.8421709e-14 | G10: =eth_ON!G10 - eth_OFF!G10 - AVERAGE(G$62:G$63) -> 0.65 | H10: =eth_ON!H10 - eth_OFF!H10 - AVERAGE(H$62:H$63) -> 0.05 | I10: =eth_ON!I10 - eth_OFF!I10 - AVERAGE(I$62:I$63) -> 0.95 | ... AK10: =eth_ON!AK10 - eth_OFF!AK10 - AVERAGE(AK$62:AK$63) -> 0.8
A11: 10 | B11: =eth_ON!B11 - eth_OFF!B11 - AVERAGE(B$62:B$63) -> -0.35 | C11: =eth_ON!C11 - eth_OFF!C11 - AVERAGE(C$62:C$63) -> -0.55 | D11: =eth_ON!D11 - eth_OFF!D11 - AVERAGE(D$62:D$63) -> 0.75 | E11: =eth_ON!E11 - eth_OFF!E11 - AVERAGE(E$62:E$63) -> 3.75 | F11: =eth_ON!F11 - eth_OFF!F11 - AVERAGE(F$62:F$63) -> 2.8421709e-14 | G11: =eth_ON!G11 - eth_OFF!G11 - AVERAGE(G$62:G$63) -> 0.25 | H11: =eth_ON!H11 - eth_OFF!H11 - AVERAGE(H$62:H$63) -> 0.05 | I11: =eth_ON!I11 - eth_OFF!I11 - AVERAGE(I$62:I$63) -> 0.65 | ... AK11: =eth_ON!AK11 - eth_OFF!AK11 - AVERAGE(AK$62:AK$63) -> 0.2
A12: 11 | B12: =eth_ON!B12 - eth_OFF!B12 - AVERAGE(B$62:B$63) -> 3.95 | C12: =eth_ON!C12 - eth_OFF!C12 - AVERAGE(C$62:C$63) -> 6.65 | D12: =eth_ON!D12 - eth_OFF!D12 - AVERAGE(D$62:D$63) -> 8.85 | E12: =eth_ON!E12 - eth_OFF!E12 - AVERAGE(E$62:E$63) -> 9.05 | F12: =eth_ON!F12 - eth_OFF!F12 - AVERAGE(F$62:F$63) -> -0.6 | G12: =eth_ON!G12 - eth_OFF!G12 - AVERAGE(G$62:G$63) -> -0.75 | H12: =eth_ON!H12 - eth_OFF!H12 - AVERAGE(H$62:H$63) -> -0.75 | I12: =eth_ON!I12 - eth_OFF!I12 - AVERAGE(I$62:I$63) -> 8.75 | ... AK12: =eth_ON!AK12 - eth_OFF!AK12 - AVERAGE(AK$62:AK$63) -> 8.3
A13: 12 | B13: =eth_ON!B13 - eth_OFF!B13 - AVERAGE(B$62:B$63) -> 10.75 | C13: =eth_ON!C13 - eth_OFF!C13 - AVERAGE(C$62:C$63) -> 11.15 | D13: =eth_ON!D13 - eth_OFF!D13 - AVERAGE(D$62:D$63) -> 10.65 | E13: =eth_ON!E13 - eth_OFF!E13 - AVERAGE(E$62:E$63) -> 15.05 | F13: =eth_ON!F13 - eth_OFF!F13 - AVERAGE(F$62:F$63) -> 10.2 | G13: =eth_ON!G13 - eth_OFF!G13 - AVERAGE(G$62:G$63) -> 12.95 | H13: =eth_ON!H13 - eth_OFF!H13 - AVERAGE(H$62:H$63) -> 14.35 | I13: =eth_ON!I13 - eth_OFF!I13 - AVERAGE(I$62:I$63) -> 9.85 | ... AK13: =eth_ON!AK13 - eth_OFF!AK13 - AVERAGE(AK$62:AK$63) -> 12.8
... A61: 60 | B61: =eth_ON!B61 - eth_OFF!B61 - AVERAGE(B$62:B$63) -> 17.15 | C61: =eth_ON!C61 - eth_OFF!C61 - AVERAGE(C$62:C$63) -> 17.45 | D61: =eth_ON!D61 - eth_OFF!D61 - AVERAGE(D$62:D$63) -> 11.55 | E61: =eth_ON!E61 - eth_OFF!E61 - AVERAGE(E$62:E$63) -> 17.45 | F61: =eth_ON!F61 - eth_OFF!F61 - AVERAGE(F$62:F$63) -> 15.6 | G61: =eth_ON!G61 - eth_OFF!G61 - AVERAGE(G$62:G$63) -> 18.75 | H61: =eth_ON!H61 - eth_OFF!H61 - AVERAGE(H$62:H$63) -> 25.85 | I61: =eth_ON!I61 - eth_OFF!I61 - AVERAGE(I$62:I$63) -> 26.35 | ... AK61: =eth_ON!AK61 - eth_OFF!AK61 - AVERAGE(AK$62:AK$63) -> 31.7
A62: leak1 | B62: =eth_ON!B62 - eth_OFF!B62 -> -2.9 | C62: =eth_ON!C62 - eth_OFF!C62 -> 0.9 | D62: =eth_ON!D62 - eth_OFF!D62 -> 0.7 | E62: =eth_ON!E62 - eth_OFF!E62 -> 0.8 | F62: =eth_ON!F62 - eth_OFF!F62 -> 0.8 | G62: =eth_ON!G62 - eth_OFF!G62 -> 0.9 | H62: =eth_ON!H62 - eth_OFF!H62 -> 0.7 | I62: =eth_ON!I62 - eth_OFF!I62 -> 1.1 | ... AK62: =eth_ON!AK62 - eth_OFF!AK62 -> 1.2
A63: leak2 | B63: =eth_ON!B63 - eth_OFF!B63 -> -3 | C63: =eth_ON!C63 - eth_OFF!C63 -> 1.4 | D63: =eth_ON!D63 - eth_OFF!D63 -> 0.6 | E63: =eth_ON!E63 - eth_OFF!E63 -> 0.5 | F63: =eth_ON!F63 - eth_OFF!F63 -> 0.4 | G63: =eth_ON!G63 - eth_OFF!G63 -> 0.6 | H63: =eth_ON!H63 - eth_OFF!H63 -> 0.6 | I63: =eth_ON!I63 - eth_OFF!I63 -> 0.6 | ... AK63: =eth_ON!AK63 - eth_OFF!AK63 -> 0.6

Sheet E_per_kg
A1: ID | B1: 45873 | C1: 45875 | D1: 45877 | E1: 45880 | F1: 45882 | G1: 45884 | H1: 45887 | I1: 45889 | J1: 45891 | K1: 45894 | L1: 45896 | M1: 45898 | N1: 45901 | O1: 45903 | P1: 45905 | Q1: 45908 | R1: 45910 | S1: 45912 | T1: 45915 | U1: 45917 | V1: 45919 | W1: 45922 | X1: 45924 | Y1: 45926 | Z1: 45929 | AA1: 45931 | AB1: 45933 | AC1: 45936 | AD1: 45938 | AE1: 45940 | AF1: 45943 | AG1: 45945 | AH1: 45947 | AI1: 45950 | AJ1: 45952 | AK1: 45954
A2: 1 | B2: =E_g!B2/(rat_weight!B2/1000)*0.1578 -> 2.7131621 | C2: =E_g!C2/(rat_weight!C2/1000)*0.1578 -> 4.3901556 | D2: =E_g!D2/(rat_weight!D2/1000)*0.1578 -> 5.5567704 | E2: =E_g!E2/(rat_weight!E2/1000)*0.1578 -> 6.1332422 | F2: =E_g!F2/(rat_weight!F2/1000)*0.1578 -> 6.2995257 | G2: =E_g!G2/(rat_weight!G2/1000)*0.1578 -> 6.8196512 | H2: =E_g!H2/(rat_weight!H2/1000)*0.1578 -> 6.7933205 | I2: =E_g!I2/(rat_weight!I2/1000)*0.1578 -> 7.0769084 | ... AK2: =E_g!AK2/(rat_weight!AK2/1000)*0.1578 -> 6.0526027
A3: 2 | B3: =E_g!B3/(rat_weight!B3/1000)*0.1578 -> 0.14611111 | C3: =E_g!C3/(rat_weight!C3/1000)*0.1578 -> -0.42777108 | D3: =E_g!D3/(rat_weight!D3/1000)*0.1578 -> 0.048703704 | E3: =E_g!E3/(rat_weight!E3/1000)*0.1578 -> 3.3880588 | F3: =E_g!F3/(rat_weight!F3/1000)*0.1578 -> 3.3472727 | G3: =E_g!G3/(rat_weight!G3/1000)*0.1578 -> 7.6523494 | H3: =E_g!H3/(rat_weight!H3/1000)*0.1578 -> 5.4697546 | I3: =E_g!I3/(rat_weight!I3/1000)*0.1578 -> 3.3293064 | ... AK3: =E_g!AK3/(rat_weight!AK3/1000)*0.1578 -> 5.9283978
A4: 3 | B4: =E_g!B4/(rat_weight!B4/1000)*0.1578 -> 4.0393028 | C4: =E_g!C4/(rat_weight!C4/1000)*0.1578 -> 3.6403366 | D4: =E_g!D4/(rat_weight!D4/1000)*0.1578 -> 4.471 | E4: =E_g!E4/(rat_weight!E4/1000)*0.1578 -> 5.6096532 | F4: =E_g!F4/(rat_weight!F4/1000)*0.1578 -> 5.1887814 | G4: =E_g!G4/(rat_weight!G4/1000)*0.1578 -> 5.0635057 | H4: =E_g!H4/(rat_weight!H4/1000)*0.1578 -> 5.4439509 | I4: =E_g!I4/(rat_weight!I4/1000)*0.1578 -> 5.0396089 | ... AK4: =E_g!AK4/(rat_weight!AK4/1000)*0.1578 -> 5.6721976
A5: 4 | B5: =E_g!B5/(rat_weight!B5/1000)*0.1578 -> 6.7910357 | C5: =E_g!C5/(rat_weight!C5/1000)*0.1578 -> 4.642852 | D5: =E_g!D5/(rat_weight!D5/1000)*0.1578 -> 4.934735 | E5: =E_g!E5/(rat_weight!E5/1000)*0.1578 -> 6.6112759 | F5: =E_g!F5/(rat_weight!F5/1000)*0.1578 -> 6.8252595 | G5: =E_g!G5/(rat_weight!G5/1000)*0.1578 -> 6.7667708 | H5: =E_g!H5/(rat_weight!H5/1000)*0.1578 -> 9.1599658 | I5: =E_g!I5/(rat_weight!I5/1000)*0.1578 -> 8.7878276 | ... AK5: =E_g!AK5/(rat_weight!AK5/1000)*0.1578 -> 9.1095899
A6: 5 | B6: =E_g!B6/(rat_weight!B6/1000)*0.1578 -> 0.4410559 | C6: =E_g!C6/(rat_weight!C6/1000)*0.1578 -> -0.0821875 | D6: =E_g!D6/(rat_weight!D6/1000)*0.1578 -> 0.27373469 | E6: =E_g!E6/(rat_weight!E6/1000)*0.1578 -> 0.015843373 | F6: =E_g!F6/(rat_weight!F6/1000)*0.1578 -> -0.031814516 | G6: =E_g!G6/(rat_weight!G6/1000)*0.1578 -> 0.015623762 | H6: =E_g!H6/(rat_weight!H6/1000)*0.1578 -> 0.046594488 | I6: =E_g!I6/(rat_weight!I6/1000)*0.1578 -> 0.20190945 | ... AK6: =E_g!AK6/(rat_weight!AK6/1000)*0.1578 -> 7.4009006e-15
A7: 6 | B7: =E_g!B7/(rat_weight!B7/1000)*0.1578 -> 8.0563554 | C7: =E_g!C7/(rat_weight!C7/1000)*0.1578 -> 3.1885841 | D7: =E_g!D7/(rat_weight!D7/1000)*0.1578 -> 4.4231818 | E7: =E_g!E7/(rat_weight!E7/1000)*0.1578 -> 5.4997941 | F7: =E_g!F7/(rat_weight!F7/1000)*0.1578 -> 7.6115294 | G7: =E_g!G7/(rat_weight!G7/1000)*0.1578 -> 7.2436441 | H7: =E_g!H7/(rat_weight!H7/1000)*0.1578 -> 6.403795 | I7: =E_g!I7/(rat_weight!I7/1000)*0.1578 -> 5.8170241 | ... AK7: =E_g!AK7/(rat_weight!AK7/1000)*0.1578 -> 5.9435683
A8: 7 | B8: =E_g!B8/(rat_weight!B8/1000)*0.1578 -> 8.2342909 | C8: =E_g!C8/(rat_weight!C8/1000)*0.1578 -> 2.8808882 | D8: =E_g!D8/(rat_weight!D8/1000)*0.1578 -> 7.3697802 | E8: =E_g!E8/(rat_weight!E8/1000)*0.1578 -> 8.3942481 | F8: =E_g!F8/(rat_weight!F8/1000)*0.1578 -> 8.7602206 | G8: =E_g!G8/(rat_weight!G8/1000)*0.1578 -> 7.66213 | H8: =E_g!H8/(rat_weight!H8/1000)*0.1578 -> 9.1432852 | I8: =E_g!I8/(rat_weight!I8/1000)*0.1578 -> 7.6968881 | ... AK8: =E_g!AK8/(rat_weight!AK8/1000)*0.1578 -> 9.8091892
A9: 8 | B9: =E_g!B9/(rat_weight!B9/1000)*0.1578 -> 7.0002766 | C9: =E_g!C9/(rat_weight!C9/1000)*0.1578 -> 5.1640558 | D9: =E_g!D9/(rat_weight!D9/1000)*0.1578 -> 5.0315466 | E9: =E_g!E9/(rat_weight!E9/1000)*0.1578 -> 6.6520293 | F9: =E_g!F9/(rat_weight!F9/1000)*0.1578 -> 4.8170526 | G9: =E_g!G9/(rat_weight!G9/1000)*0.1578 -> 5.7100825 | H9: =E_g!H9/(rat_weight!H9/1000)*0.1578 -> 5.5894251 | I9: =E_g!I9/(rat_weight!I9/1000)*0.1578 -> 4.9755306 | ... AK9: =E_g!AK9/(rat_weight!AK9/1000)*0.1578 -> 5.2504364
A10: 9 | B10: =E_g!B10/(rat_weight!B10/1000)*0.1578 -> 0.69882857 | C10: =E_g!C10/(rat_weight!C10/1000)*0.1578 -> 0.066488764 | D10: =E_g!D10/(rat_weight!D10/1000)*0.1578 -> 3.3209322 | E10: =E_g!E10/(rat_weight!E10/1000)*0.1578 -> 0.11336207 | F10: =E_g!F10/(rat_weight!F10/1000)*0.1578 -> -1.3229928e-14 | G10: =E_g!G10/(rat_weight!G10/1000)*0.1578 -> 0.29730435 | H10: =E_g!H10/(rat_weight!H10/1000)*0.1578 -> 0.023412463 | I10: =E_g!I10/(rat_weight!I10/1000)*0.1578 -> 0.43077586 | ... AK10: =E_g!AK10/(rat_weight!AK10/1000)*0.1578 -> 0.28756264
