Workbook

Sheet suspicious_values
A1: fluid | B1: ID | C1: date | D1: ON | E1: OFF | F1: consumed | G1: why suspicious? | H1: transcription good? | I1: Problem | J1: fix
A2: ethanol | B2: 52 | C2: 1028 | D2: =eth_ON!C53 -> 460.6 | E2: =eth_OFF!C53 -> 459.3 | F2: 11.05 | G2: high ethanol consumption | H2: yes | J2: Change OFF to 459.3
A3: ethanol | B3: 11 | C3: 45964 | D3: 459.6 | E3: 466.5 | F3: -6.9 | G3: negative consumption | H3: yes | I3: Nora said 469.6 in audio then corrected herself to 459.6. I suspect the correction was intended for the tenths digit and was accidentally said for the tens digit. | J3: switch ON to 469.5
A4: water | B4: Q | C4: 56 | D4: 466.6 | E4: 455 | F4: 11.53 | G4: high consumption | I4: Probably missed 6 on entry of OFF | J4: switch OFF to 465.5

Sheet notes
A1: ID | B1: 45957 | C1: 45958 | D1: 45959 | E1: 45960 | F1: 45961 | G1: 45964 | H1: 45965 | I1: 45966 | J1: 45967 | K1: 45968 | L1: 45971 | M1: 45972 | N1: 45973 | O1: 45974 | P1: 45975 | Q1: 45978 | R1: 45979 | S1: 45980 | T1: 45981
A2: Left fluid (cages 1-30) | B2: 20% ethanol | C2: water | D2: 20% ethanol | E2: water | F2: 20% ethanol | G2: water | H2: 20% ethanol | I2: water | J2: 20% ethanol | K2: water | L2: 20% ethanol | M2: water | N2: 20% ethanol + 185 uM quinine | O2: water | P2: 20% ethanol + 185 uM quinine | Q2: water | R2: 20% ethanol + 740 uM quinine | S2: water | T2: 20% ethanol + 740 uM quinine
A3: Right fluid (cages 1-30) | B3: water | C3: 20% ethanol | D3: water | E3: 20% ethanol | F3: water | G3: 20% ethanol | H3: water | I3: 20% ethanol | J3: water | K3: 20% ethanol | L3: water | M3: 20% ethanol + 185 uM quinine | N3: water | O3: 20% ethanol + 185 uM quinine | P3: water | Q3: 20% ethanol + 740 uM quinine | R3: water | S3: 20% ethanol + 740 uM quinine | T3: water
A4: Left fluid (cages 31-60) | B4: water | C4: 20% ethanol | D4: water | E4: 20% ethanol | F4: water | G4: 20% ethanol | H4: water | I4: 20% ethanol | J4: water | K4: 20% ethanol | L4: water | M4: 20% ethanol | N4: water | O4: 20% ethanol + 185 uM quinine | P4: water | Q4: 20% ethanol + 740 uM quinine | R4: water | S4: 20% ethanol + 740 uM quinine | T4: water
A5: Right fluid (cages 31-60) | B5: 20% ethanol | C5: water | D5: 20% ethanol | E5: water | F5: 20% ethanol | G5: water | H5: 20% ethanol | I5: water | J5: 20% ethanol | K5: water | L5: 20% ethanol + 185 uM quinine | M5: water | N5: 20% ethanol + 185 uM quinine | O5: water | P5: 20% ethanol + 185 uM quinine | Q5: water | R5: 20% ethanol + 740 uM quinine | S5: water | T5: 20% ethanol + 740 uM quinine
A6: bottles ON time | B6: 9:49-9:58 | C6: 9:42-9:51 | D6: 10:10-10:20 | E6: 9:47-9:57 | F6: 9:44-9:56 | G6: 9:49-9:59 | H6: 10:00-10:15 | I6: 10:06-10:16 | J6: 9:40-9:50 | K6: 9:30-9:40 | L6: 10:10-10:19 | M6: 9:54-10:05 | N6: 10:16-10:26 | O6: 9:48-10:01 | P6: 9:51-10:02 | S6: 10:12-10:22 | T6: 10:51-10:03
A7: bottles OFF time | B7: 10:09-10:18 | C7: 10:02-10:11 | D7: 10:20-10:40 | E7: 10:07-10:16 | F7: 10:04-10:16 | G7: 10:09-10:19 | H7: 10:20-10:35 | I7: 10:26-10:35 | J7: 10:00-10:10 | K7: 9:50-10:00 | L7: 10:30-10:39 | M7: 10:14-10:25 | N7: 10:36-10:46 | O7: 10:08-10:21 | P7: 10:11-10:23 | S7: 10:32-10:43 | T7: 10:11-10:23
A8: other notes | E8: #10 water and ethanol bottles switched during OFF weighing | G8: #6 chewed acrylic piece | I8: #6 chews on acrylic piece, took away after giving bottles | L8: #47 chewed through water bottle, cage changed before bottles
F9: I (David) timed myself putting bottles on (normal leisurly pace). Started Rack #2 @3:34, started rack #3 @9:30, finished @11:37. Taking bottles off, I was initially ~1 minute early to start rack #2. I slowed down and was still ~30s early for rack #3. I ended ~10 early. I am now fairly well calibrated. We will see if this calibration holds until next week. | G9: #47 chewed through water bottle, cage changed before bottles | K9: I (David) timed myself putting bottles on. Started Rack #2 @3:07, started rack #3 @8:26, finished @10:19. | L9: fresh quinine in E31-E60 | M9: fresh quinine in E1-E30 | N9: fresh quinine in E31-E60 | O9: fresh quinine in E1-E30 | P9: fresh quinine in E31-E60 | Q9: fresh quinine in E1-E60 | S9: fresh quinine in E1-E60

Sheet rat_weight
A1: ID | B1: 45959 | C1: 45959 | D1: 45959 | E1: 45959 | F1: 45959 | G1: 45966 | H1: 45966 | I1: 45966 | J1: 45966 | K1: 45966 | L1: 45973 | M1: 45973 | N1: 45973 | O1: 45973 | P1: 45973 | Q1: 45980 | R1: 45980 | S1: 45980 | T1: 45980
A2: 1 | B2: 288 | C2: 288 | D2: 288 | E2: 288 | F2: 288 | G2: 279 | H2: 279 | I2: 279 | J2: 279 | K2: 279 | L2: 286 | M2: 286 | N2: 286 | O2: 286 | P2: 286 | Q2: 288 | R2: 288 | S2: 288 | T2: 288
A3: 2 | B3: 182 | C3: 182 | D3: 182 | E3: 182 | F3: 182 | G3: 180 | H3: 180 | I3: 180 | J3: 180 | K3: 180 | L3: 187 | M3: 187 | N3: 187 | O3: 187 | P3: 187 | Q3: 181 | R3: 181 | S3: 181 | T3: 181
A4: 3 | B4: 584 | C4: 584 | D4: 584 | E4: 584 | F4: 584 | G4: 590 | H4: 590 | I4: 590 | J4: 590 | K4: 590 | L4: 597 | M4: 597 | N4: 597 | O4: 597 | P4: 597 | Q4: 594 | R4: 594 | S4: 594 | T4: 594
A5: 4 | B5: 316 | C5: 316 | D5: 316 | E5: 316 | F5: 316 | G5: 315 | H5: 315 | I5: 315 | J5: 315 | K5: 315 | L5: 315 | M5: 315 | N5: 315 | O5: 315 | P5: 315 | Q5: 319 | R5: 319 | S5: 319 | T5: 319
A6: 5 | B6: 613 | C6: 613 | D6: 613 | E6: 613 | F6: 613 | G6: 622 | H6: 622 | I6: 622 | J6: 622 | K6: 622 | L6: 635 | M6: 635 | N6: 635 | O6: 635 | P6: 635 | Q6: 643 | R6: 643 | S6: 643 | T6: 643
A7: 6 | B7: 452 | C7: 452 | D7: 452 | E7: 452 | F7: 452 | G7: 457 | H7: 457 | I7: 457 | J7: 457 | K7: 457 | L7: 465 | M7: 465 | N7: 465 | O7: 465 | P7: 465 | Q7: 470 | R7: 470 | S7: 470 | T7: 470
A8: 7 | B8: 295 | C8: 295 | D8: 295 | E8: 295 | F8: 295 | G8: 294 | H8: 294 | I8: 294 | J8: 294 | K8: 294 | L8: 303 | M8: 303 | N8: 303 | O8: 303 | P8: 303 | Q8: 306 | R8: 306 | S8: 306 | T8: 306
A9: 8 | B9: 552 | C9: 552 | D9: 552 | E9: 552 | F9: 552 | G9: 562 | H9: 562 | I9: 562 | J9: 562 | K9: 562 | L9: 562 | M9: 562 | N9: 562 | O9: 562 | P9: 562 | Q9: 563 | R9: 563 | S9: 563 | T9: 563
A10: 9 | B10: 430 | C10: 430 | D10: 430 | E10: 430 | F10: 430 | G10: 454 | H10: 454 | I10: 454 | J10: 454 | K10: 454 | L10: 445 | M10: 445 | N10: 445 | O10: 445 | P10: 445 | Q10: 451 | R10: 451 | S10: 451 | T10: 451
A11: 10 | B11: 571 | C11: 571 | D11: 571 | E11: 571 | F11: 571 | G11: 581 | H11: 581 | I11: 581 | J11: 581 | K11: 581 | L11: 580 | M11: 580 | N11: 580 | O11: 580 | P11: 580 | Q11: 588 | R11: 588 | S11: 588 | T11: 588
A12: 11 | B12: 178 | C12: 178 | D12: 178 | E12: 178 | F12: 178 | G12: 174 | H12: 174 | I12: 174 | J12: 174 | K12: 174 | L12: 176 | M12: 176 | N12: 176 | O12: 176 | P12: 176 | Q12: 176 | R12: 176 | S12: 176 | T12: 176
A13: 12 | B13: 323 | C13: 323 | D13: 323 | E13: 323 | F13: 323 | G13: 318 | H13: 318 | I13: 318 | J13: 318 | K13: 318 | L13: 319 | M13: 319 | N13: 319 | O13: 319 | P13: 319 | Q13: 322 | R13: 322 | S13: 322 | T13: 322
... A61: 60 | B61: 595 | C61: 595 | D61: 595 | E61: 595 | F61: 595 | G61: 603 | H61: 603 | I61: 603 | J61: 603 | K61: 603 | L61: 605 | M61: 605 | N61: 605 | O61: 605 | P61: 605 | Q61: 612 | R61: 612 | S61: 612 | T61: 612

Sheet eth_ON
A1: ID | B1: 45957 | C1: 45958 | D1: 45959 | E1: 45960 | F1: 45961 | G1: 45964 | H1: 45965 | I1: 45966 | J1: 45967 | K1: 45968 | L1: 45971 | M1: 45972 | N1: 45973 | O1: 45974 | P1: 45975 | Q1: 45978 | R1: 45979 | S1: 45980 | T1: 45981
A2: 1 | B2: 475 | C2: 471.5 | D2: 467.5 | E2: 463.8 | F2: 459.6 | G2: 479.1 | H2: 476.1 | I2: 472.4 | J2: 468.4 | K2: 466.5 | L2: 482.1 | M2: 481.1 | N2: 478.5 | O2: 473.2 | P2: 470.4 | Q2: 478 | R2: 476.8 | S2: 462.8 | T2: 460.9
A3: 2 | B3: 480.8 | C3: 478.6 | D3: 476.7 | E3: 475.2 | F3: 473 | G3: 470.8 | H3: 469.1 | I3: 467.7 | J3: 465.4 | K3: 463.9 | L3: 483 | M3: 478.5 | N3: 476.5 | O3: 472.2 | P3: 471 | Q3: 482.8 | R3: 481.9 | S3: 477.3 | T3: 476.9
A4: 3 | B4: 467.8 | C4: 464.6 | D4: 459.3 | E4: 473 | F4: 469.5 | G4: 466.3 | H4: 463.6 | I4: 458.7 | J4: 451.6 | K4: 449.4 | L4: 476.9 | M4: 467.9 | N4: 463.5 | O4: 460.5 | P4: 456.1 | Q4: 466.1 | R4: 462.5 | S4: 478.3 | T4: 474.2
A5: 4 | B5: 474.6 | C5: 470.1 | D5: 467.3 | E5: 464.8 | F5: 460.4 | G5: 456.4 | H5: 453.3 | I5: 449.6 | J5: 444.7 | K5: 441.1 | L5: 479.3 | M5: 467.3 | N5: 464 | O5: 464.4 | P5: 460.9 | Q5: 467.1 | R5: 463.9 | S5: 479.3 | T5: 475.1
A6: 5 | B6: 469.6 | C6: 469.1 | D6: 468.7 | E6: 468.3 | F6: 468 | G6: 467.2 | H6: 466.8 | I6: 466.1 | J6: 465.3 | K6: 464.7 | L6: 483.1 | M6: 470.6 | N6: 470.3 | O6: 463.7 | P6: 463.3 | Q6: 479.5 | R6: 479 | S6: 461.4 | T6: 461.1
A7: 6 | B7: 474.6 | C7: 471.3 | D7: 467.1 | E7: 465.3 | F7: 460.2 | G7: 476.4 | H7: 472.6 | I7: 468.2 | J7: 463 | K7: 459.9 | L7: 457.6 | M7: 469.7 | N7: 468.1 | O7: 467.6 | P7: 466.7 | Q7: 465.2 | R7: 464.3 | S7: 469.7 | T7: 468.8
A8: 7 | B8: 454.7 | C8: 451 | D8: 449.3 | E8: 474.6 | F8: 471.8 | G8: 488.5 | H8: 486.5 | I8: 482 | J8: 478.2 | K8: 474.2 | L8: 472 | M8: 472.1 | N8: 469 | O8: 480.2 | P8: 478.7 | Q8: 472 | R8: 470.6 | S8: 475 | T8: 472.9
A9: 8 | B9: 478.6 | C9: 476.1 | D9: 472.9 | E9: 468.9 | F9: 465.4 | G9: 486.4 | H9: 484 | I9: 479.8 | J9: 475.7 | K9: 471.9 | L9: 466.9 | M9: 475.5 | N9: 469.5 | O9: 478.1 | P9: 473.7 | Q9: 467.2 | R9: 463.8 | S9: 483.7 | T9: 481
A10: 9 | B10: 474.7 | C10: 473.9 | D10: 473.4 | E10: 472.9 | F10: 472.6 | G10: 471.5 | H10: 470.8 | I10: 470.2 | J10: 469.4 | K10: 468.7 | L10: 468 | M10: 467.7 | N10: 467.4 | O10: 460.9 | P10: 460.3 | Q10: 465.2 | R10: 464.8 | S10: 469.2 | T10: 468.7
A11: 10 | B11: 481 | C11: 480.5 | D11: 480.2 | E11: 479.5 | F11: 478.7 | G11: 478.2 | H11: 477.6 | I11: 476.8 | J11: 475.8 | K11: 475.1 | L11: 474.5 | M11: 470.5 | N11: 470.3 | O11: 468.9 | P11: 468.5 | Q11: 474.2 | R11: 473.7 | S11: 472.4 | T11: 472
A12: 11 | B12: 466 | C12: 462.7 | D12: 459.7 | E12: 474.4 | F12: 471.8 | G12: 469.5 | H12: 466.3 | I12: 463.8 | J12: 460.7 | K12: 459.1 | L12: 475.8 | M12: 475.1 | N12: 474.2 | O12: 477.3 | P12: 475.8 | Q12: 473.3 | R12: 472.3 | S12: 468.8 | T12: 467.4
A13: 12 | B13: 460.9 | C13: 456.4 | D13: 452 | E13: 471.5 | F13: 467.8 | G13: 462.2 | H13: 459.8 | I13: 457.6 | J13: 454.8 | K13: 452.5 | L13: 473.1 | M13: 463.4 | N13: 461.2 | O13: 462.3 | P13: 460.5 | Q13: 467.6 | R13: 466.3 | S13: 464.4 | T13: 463.7
... A61: 60 | B61: 471.6 | C61: 464.9 | D61: 458.3 | E61: 451.9 | F61: 446.9 | G61: 478.1 | H61: 474 | I61: 469.4 | J61: 462.8 | K61: 456.9 | L61: 469.7 | M61: 459.3 | N61: 470.5 | O61: 463.3 | P61: 460.5 | Q61: 468.8 | R61: 466.1 | S61: 468.5 | T61: 464.1
A62: leak 1 | B62: 448 | C62: 447.3 | D62: 446.9 | E62: 446.7 | F62: 446.3 | G62: 445.9 | H62: 445.6 | I62: 444.9 | J62: 444.5 | K62: 443.8 | L62: 452 | M62: 451.7 | N62: 451.3 | O62: 450.9 | P62: 449.6 | Q62: 456.7 | R62: 456.5 | S62: 453.3 | T62: 453
A63: leak 2 | B63: 466.1 | C63: 465.8 | D63: 465.4 | E63: 465.1 | F63: 464.9 | G63: 464.6 | H63: 464.3 | I63: 463.9 | J63: 463.5 | K63: 463.2 | L63: 465.3 | M63: 465.1 | N63: 464.3 | O63: 464 | P63: 462.6 | Q63: 460.7 | R63: 460.4 | S63: 456.4 | T63: 456.1
A64: 500g calibration weight | B64: 499.9 | C64: 499.9 | D64: 500 | E64: 500 | F64: 500 | G64: 500 | H64: 500 | I64: 500 | J64: 500 | K64: 500 | L64: 500 | M64: 500 | N64: 500 | O64: 500 | P64: 500 | Q64: 500 | R64: 500 | S64: 500 | T64: 499.9
A65: Scale offset | B65: =500-B64 -> 0.1 | C65: =500-C64 -> 0.1 | D65: =500-D64 -> 0 | E65: =500-E64 -> 0 | F65: =500-F64 -> 0 | G65: =500-G64 -> 0 | H65: =500-H64 -> 0 | I65: =500-I64 -> 0 | ... T65: =500-T64 -> 0.1

Sheet eth_OFF
A1: ID | B1: 45957 | C1: 45958 | D1: 45959 | E1: 45960 | F1: 45961 | G1: 45964 | H1: 45965 | I1: 45966 | J1: 45967 | K1: 45968 | L1: 45971 | M1: 45972 | N1: 45973 | O1: 45974 | P1: 45975 | Q1: 45978 | R1: 45979 | S1: 45980 | T1: 45981
A2: 1 | B2: 471.7 | C2: 467.8 | D2: 464.1 | E2: 459.9 | F2: 456.6 | G2: 476.4 | H2: 472.6 | I2: 468.7 | J2: 466.7 | K2: 463.2 | L2: 477.6 | M2: 478.8 | N2: 475.7 | O2: 470.6 | P2: 467.2 | Q2: 477 | R2: 476.1 | S2: 461.1 | T2: 459.9
A3: 2 | B3: 478.9 | C3: 477 | D3: 475.5 | E3: 473.2 | F3: 471.3 | G3: 469.4 | H3: 467.9 | I3: 465.7 | J3: 464.2 | K3: 461.8 | L3: 481.6 | M3: 476.7 | N3: 474.7 | O3: 471.2 | P3: 469.9 | Q3: 482.1 | R3: 481.5 | S3: 477.2 | T3: 476.5
A4: 3 | B4: 464.8 | C4: 459.6 | D4: 457.6 | E4: 469.7 | F4: 466.7 | G4: 463.8 | H4: 458.7 | I4: 451.8 | J4: 449.5 | K4: 446.4 | L4: 474 | M4: 463.6 | N4: 459 | O4: 456.2 | P4: 453.5 | Q4: 462.7 | R4: 459.9 | S4: 474.5 | T4: 471.2
A5: 4 | B5: 470.3 | C5: 467.6 | D5: 465.1 | E5: 460.7 | F5: 456.9 | G5: 453.6 | H5: 449.8 | I5: 445 | J5: 442.3 | K5: 437.9 | L5: 475.6 | M5: 464.1 | N5: 460.2 | O5: 461.1 | P5: 458.4 | Q5: 464.1 | R5: 460.9 | S5: 475.3 | T5: 472.2
A6: 5 | B6: 469.1 | C6: 468.9 | D6: 468.4 | E6: 468.1 | F6: 467.5 | G6: 466.9 | H6: 466.1 | I6: 465.4 | J6: 464.8 | K6: 464.4 | L6: 482.9 | M6: 470.4 | N6: 469.8 | O6: 463.4 | P6: 462.7 | Q6: 479.1 | R6: 478.9 | S6: 461.2 | T6: 460.8
A7: 6 | B7: 471.5 | C7: 467.5 | D7: 462.7 | E7: 460.5 | F7: 458 | G7: 472.9 | H7: 468.5 | I7: 463.2 | J7: 460.1 | K7: 458.1 | L7: 454.3 | M7: 468.2 | N7: 465.5 | O7: 466.9 | P7: 465 | Q7: 464.5 | R7: 463.2 | S7: 468.9 | T7: 467.1
A8: 7 | B8: 451.2 | C8: 449.6 | D8: 446.8 | E8: 472.1 | F8: 470.1 | G8: 486.8 | H8: 482.2 | I8: 478.5 | J8: 474.4 | K8: 472.6 | L8: 468.6 | M8: 469.2 | N8: 467.1 | O8: 478.9 | P8: 476.3 | Q8: 470.8 | R8: 468.5 | S8: 473.1 | T8: 470.4
A9: 8 | B9: 476.3 | C9: 473.2 | D9: 469.1 | E9: 465.6 | F9: 462 | G9: 484.2 | H9: 479.9 | I9: 476 | J9: 472.1 | K9: 467.3 | L9: 462 | M9: 469.6 | N9: 464.6 | O9: 473.9 | P9: 471.3 | Q9: 464 | R9: 459.9 | S9: 481.2 | T9: 478.6
A10: 9 | B10: 474.1 | C10: 473.7 | D10: 473.2 | E10: 472.8 | F10: 471.9 | G10: 470.9 | H10: 470.4 | I10: 469.7 | J10: 468.8 | K10: 468.4 | L10: 467.5 | M10: 467.5 | N10: 466.8 | O10: 460.6 | P10: 460 | Q10: 464.9 | R10: 464.3 | S10: 469 | T10: 468.3
A11: 10 | B11: 480.6 | C11: 480.3 | D11: 479.6 | E11: 478.9 | F11: 478.5 | G11: 477.7 | H11: 476.9 | I11: 476 | J11: 475.2 | K11: 474.8 | L11: 474.1 | M11: 470.4 | N11: 469.6 | O11: 468.6 | P11: 467.9 | Q11: 473.8 | R11: 473.1 | S11: 472.1 | T11: 471.4
A12: 11 | B12: 462.8 | C12: 459.9 | D12: 456.7 | E12: 472 | F12: 469.9 | G12: 466.5 | H12: 463.9 | I12: 460.9 | J12: 459.3 | K12: 458.7 | L12: 473.4 | M12: 474.3 | N12: 472.3 | O12: 475.9 | P12: 473.9 | Q12: 472.5 | R12: 471.3 | S12: 467.6 | T12: 466.9
A13: 12 | B13: 456.5 | C13: 452.2 | D13: 447.3 | E13: 468 | F13: 462.5 | G13: 460 | H13: 457.7 | I13: 455 | J13: 452.6 | K13: 450.3 | L13: 471.5 | M13: 461.3 | N13: 458.5 | O13: 460.6 | P13: 458.6 | Q13: 466.4 | R13: 465.4 | S13: 463.9 | T13: 462.4
... A51: 50 | B51: 459.6 | C51: 456.5 | D51: 453.4 | E51: 451.6 | F51: 448.8 | G51: 446.2 | H51: 443.8 | I51: 441.4 | J51: 438.9 | K51: 437.2 | L51: 452.1 | M51: 451.7 | N51: 457.2 | O51: 455.7 | P51: 463.7 | Q51: 465.2 | R51: 464.1 | S51: 463.1 | T51: 462
A52: 51 | B52: 446.9 | C52: 444.6 | D52: 442.1 | E52: 440.1 | F52: 437.9 | G52: 461.3 | H52: 457.2 | I52: 455 | J52: 453.8 | K52: broke | L52: 476.1 | M52: 466.9 | N52: 466.2 | O52: 464.7 | P52: 469.9 | Q52: 469.9 | R52: 468.9 | S52: 464.5 | T52: 463.3
A53: 52 | B53: 460.7 | C53: 459.3 | D53: 457.7 | E53: 456.4 | F53: 454.9 | G53: 453.6 | H53: 452.5 | I53: 450.9 | J53: 449.4 | K53: 447.8 | L53: 453.6 | M53: 460.8 | N53: 461.5 | O53: 460 | P53: 466.3 | Q53: 457.2 | R53: 456.8 | S53: 460.2 | T53: 459.4
A54: 53 | B54: 460.4 | C54: 453.8 | D54: 449.9 | E54: 444.9 | F54: 440.2 | G54: 466.9 | H54: 461.5 | I54: 455.2 | J54: 450 | K54: 446.2 | L54: 439.2 | M54: 453.8 | N54: 454.4 | O54: 445.3 | P54: 460.9 | Q54: 454.4 | R54: 450.8 | S54: 447.1 | T54: 441.7
A55: 54 | B55: 455.5 | C55: 453.7 | D55: 451.5 | E55: 448.3 | F55: 444.6 | G55: 476.5 | H55: 473 | I55: 469.6 | J55: 465.8 | K55: 462.5 | L55: 441.5 | M55: 459.8 | N55: 449.4 | O55: 445.7 | P55: 465.2 | Q55: 467 | R55: 464.8 | S55: 457.2 | T55: 455.8
A56: 55 | B56: 431.7 | C56: 430.3 | D56: 429.1 | E56: 459.6 | F56: 458.1 | G56: 456.3 | H56: 454.2 | I56: 452.5 | J56: 451.1 | K56: 450 | L56: 454.4 | M56: 460.1 | N56: 453.8 | O56: 452.5 | P56: 458.5 | Q56: 458.2 | R56: 457.6 | S56: 464.1 | T56: 463.5
A57: 56 | B57: 463.3 | C57: 461.5 | D57: 460 | E57: 458.2 | F57: 455.9 | G57: 479.4 | H57: 476.8 | I57: 475.1 | J57: 472.7 | K57: 472 | L57: 458 | M57: 467.9 | N57: 470.6 | O57: 469.1 | P57: 459.6 | Q57: 460.6 | R57: 459.6 | S57: 466.7 | T57: 465.9
A58: 57 | B58: 439.9 | C58: 436.7 | D58: 433.7 | E58: 458.4 | F58: 456 | G58: 451.9 | H58: 448.7 | I58: 445.4 | J58: 443.3 | K58: 442 | L58: 451.6 | M58: 452.8 | N58: 452.4 | O58: 451.6 | P58: 461 | Q58: 455.4 | R58: 454.9 | S58: 455.1 | T58: 454.8
A59: 58 | B59: 460.9 | C59: 460.7 | D59: 459.8 | E59: 459.4 | F59: 459.2 | G59: 458.4 | H59: 457.6 | I59: 457 | J59: 456.2 | K59: 456 | L59: 448.8 | M59: 455.8 | N59: 460 | O59: 459.6 | P59: 452.9 | Q59: 465.4 | R59: 464.7 | S59: 460.7 | T59: 460.3
A60: 59 | B60: 445.6 | C60: 443.2 | D60: 440.6 | E60: 463 | F60: 460.4 | G60: 457.8 | H60: 454.3 | I60: 450.5 | J60: 446.4 | K60: 444 | L60: 453.7 | M60: 459.9 | N60: 469.6 | O60: 465.9 | P60: 470.3 | Q60: 472.8 | R60: 470.9 | S60: 448.3 | T60: 446.8
A61: 60 | B61: 465.2 | C61: 458.6 | D61: 452.2 | E61: 447.1 | F61: 441.6 | G61: 474.2 | H61: 469.8 | I61: 463.1 | J61: 457.1 | K61: 452.1 | L61: 463.5 | M61: 454 | N61: 463.5 | O61: 458 | P61: 454.7 | Q61: 466.2 | R61: 462.1 | S61: 464.3 | T61: 459.2
A62: leak 1 | B62: 447.4 | C62: 447.1 | D62: 446.8 | E62: 446.4 | F62: 446.1 | G62: 445.6 | H62: 445.1 | I62: 444.6 | J62: 443.9 | K62: 443.6 | L62: 451.9 | M62: 451.4 | N62: 450.9 | O62: 450.6 | P62: 449.5 | Q62: 456.5 | R62: 455.9 | S62: 453.1 | T62: 452.9
A63: leak 2 | B63: 465.9 | C63: 465.5 | D63: 465.3 | E63: 465.1 | F63: 464.9 | G63: 464.3 | H63: 464.1 | I63: 463.6 | J63: 463.3 | K63: 463.1 | L63: 465.2 | M63: 464.5 | N63: 464 | O63: 463.7 | P63: 462.7 | Q63: 460.4 | R63: 459.9 | S63: 456.3 | T63: 456.1
A64: 500g calibration weight | B64: 500 | C64: 500 | D64: 500 | E64: 500 | F64: 500 | G64: 500 | H64: 500 | I64: 500 | J64: 500 | K64: 500 | L64: 500 | M64: 500 | N64: 500 | O64: 500 | P64: 500 | Q64: 500 | R64: 500 | S64: 500 | T64: 500
A65: Scale offset | B65: =500-B64 -> 0 | C65: =500-C64 -> 0 | D65: =500-D64 -> 0 | E65: =500-E64 -> 0 | F65: =500-F64 -> 0 | G65: =500-G64 -> 0 | H65: =500-H64 -> 0 | I65: =500-I64 -> 0 | ... T65: =500-T64 -> 0

Sheet E_g
A1: ID | B1: 45957 | C1: 45958 | D1: 45959 | E1: 45960 | F1: 45961 | G1: 45964 | H1: 45965 | I1: 45966 | J1: 45967 | K1: 45968 | L1: 45971 | M1: 45972 | N1: 45973 | O1: 45974 | P1: 45975 | Q1: 45978 | R1: 45979 | S1: 45980 | T1: 45981
A2: 1 | B2: =eth_ON!B2 - eth_OFF!B2 - AVERAGE(B$62:B$63) -> 2.9 | C2: =eth_ON!C2 - eth_OFF!C2 - AVERAGE(C$62:C$63) -> 3.45 | D2: =eth_ON!D2 - eth_OFF!D2 - AVERAGE(D$62:D$63) -> 3.3 | E2: =eth_ON!E2 - eth_OFF!E2 - AVERAGE(E$62:E$63) -> 3.75 | F2: =eth_ON!F2 - eth_OFF!F2 - AVERAGE(F$62:F$63) -> 2.9 | G2: =eth_ON!G2 - eth_OFF!G2 - AVERAGE(G$62:G$63) -> 2.4 | H2: =eth_ON!H2 - eth_OFF!H2 - AVERAGE(H$62:H$63) -> 3.15 | I2: =eth_ON!I2 - eth_OFF!I2 - AVERAGE(I$62:I$63) -> 3.4 | ... T2: =eth_ON!T2 - eth_OFF!T2 - AVERAGE(T$62:T$63) -> 0.95 | U2: =IF(eth_OFF!U2, (eth_ON!U2+500-eth_ON!U$64) - (eth_OFF!U2+500-eth_OFF!U$64) - AVERAGE($B$62:$AK$63), "") | V2: =IF(eth_OFF!V2, (eth_ON!V2+500-eth_ON!V$64) - (eth_OFF!V2+500-eth_OFF!V$64) - AVERAGE(V$62:V$63), "") | W2: =IF(eth_OFF!W2, (eth_ON!W2+500-eth_ON!W$64) - (eth_OFF!W2+500-eth_OFF!W$64) - AVERAGE(W$62:W$63), "") | X2: =IF(eth_OFF!X2, (eth_ON!X2+500-eth_ON!X$64) - (eth_OFF!X2+500-eth_OFF!X$64) - AVERAGE(X$62:X$63), "") | Y2: =IF(eth_OFF!Y2, (eth_ON!Y2+500-eth_ON!Y$64) - (eth_OFF!Y2+500-eth_OFF!Y$64) - AVERAGE(Y$62:Y$63), "") | Z2: =IF(eth_OFF!Z2, (eth_ON!Z2+500-eth_ON!Z$64) - (eth_OFF!Z2+500-eth_OFF!Z$64) - AVERAGE(Z$62:Z$63), "") | AA2: =IF(eth_OFF!AA2, (eth_ON!AA2+500-eth_ON!AA$64) - (eth_OFF!AA2+500-eth_OFF!AA$64) - AVERAGE(AA$62:AA$63), "") | AB2: =IF(eth_OFF!AB2, (eth_ON!AB2+500-eth_ON!AB$64) - (eth_OFF!AB2+500-eth_OFF!AB$64) - AVERAGE(AB$62:AB$63), "") | AC2: =IF(eth_OFF!AC2, (eth_ON!AC2+500-eth_ON!AC$64) - (eth_OFF!AC2+500-eth_OFF!AC$64) - AVERAGE(AC$62:AC$63), "") | ... AK2: =IF(eth_OFF!AK2, (eth_ON!AK2+500-eth_ON!AK$64) - (eth_OFF!AK2+500-eth_OFF!AK$64) - AVERAGE(AK$62:AK$63), "")
A3: 2 | B3: =eth_ON!B3 - eth_OFF!B3 - AVERAGE(B$62:B$63) -> 1.5 | C3: =eth_ON!C3 - eth_OFF!C3 - AVERAGE(C$62:C$63) -> 1.35 | D3: =eth_ON!D3 - eth_OFF!D3 - AVERAGE(D$62:D$63) -> 1.1 | E3: =eth_ON!E3 - eth_OFF!E3 - AVERAGE(E$62:E$63) -> 1.85 | F3: =eth_ON!F3 - eth_OFF!F3 - AVERAGE(F$62:F$63) -> 1.6 | G3: =eth_ON!G3 - eth_OFF!G3 - AVERAGE(G$62:G$63) -> 1.1 | H3: =eth_ON!H3 - eth_OFF!H3 - AVERAGE(H$62:H$63) -> 0.85 | I3: =eth_ON!I3 - eth_OFF!I3 - AVERAGE(I$62:I$63) -> 1.7 | ... T3: =eth_ON!T3 - eth_OFF!T3 - AVERAGE(T$62:T$63) -> 0.35 | U3: =IF(eth_OFF!U3, (eth_ON!U3+500-eth_ON!U$64) - (eth_OFF!U3+500-eth_OFF!U$64) - AVERAGE($B$62:$AK$63), "") | V3: =IF(eth_OFF!V3, (eth_ON!V3+500-eth_ON!V$64) - (eth_OFF!V3+500-eth_OFF!V$64) - AVERAGE(V$62:V$63), "") | W3: =IF(eth_OFF!W3, (eth_ON!W3+500-eth_ON!W$64) - (eth_OFF!W3+500-eth_OFF!W$64) - AVERAGE(W$62:W$63), "") | X3: =IF(eth_OFF!X3, (eth_ON!X3+500-eth_ON!X$64) - (eth_OFF!X3+500-eth_OFF!X$64) - AVERAGE(X$62:X$63), "") | Y3: =IF(eth_OFF!Y3, (eth_ON!Y3+500-eth_ON!Y$64) - (eth_OFF!Y3+500-eth_OFF!Y$64) - AVERAGE(Y$62:Y$63), "") | Z3: =IF(eth_OFF!Z3, (eth_ON!Z3+500-eth_ON!Z$64) - (eth_OFF!Z3+500-eth_OFF!Z$64) - AVERAGE(Z$62:Z$63), "") | AA3: =IF(eth_OFF!AA3, (eth_ON!AA3+500-eth_ON!AA$64) - (eth_OFF!AA3+500-eth_OFF!AA$64) - AVERAGE(AA$62:AA$63), "") | AB3: =IF(eth_OFF!AB3, (eth_ON!AB3+500-eth_ON!AB$64) - (eth_OFF!AB3+500-eth_OFF!AB$64) - AVERAGE(AB$62:AB$63), "") | AC3: =IF(eth_OFF!AC3, (eth_ON!AC3+500-eth_ON!AC$64) - (eth_OFF!AC3+500-eth_OFF!AC$64) - AVERAGE(AC$62:AC$63), "") | ... AK3: =IF(eth_OFF!AK3, (eth_ON!AK3+500-eth_ON!AK$64) - (eth_OFF!AK3+500-eth_OFF!AK$64) - AVERAGE(AK$62:AK$63), "")
A4: 3 | B4: =eth_ON!B4 - eth_OFF!B4 - AVERAGE(B$62:B$63) -> 2.6 | C4: =eth_ON!C4 - eth_OFF!C4 - AVERAGE(C$62:C$63) -> 4.75 | D4: =eth_ON!D4 - eth_OFF!D4 - AVERAGE(D$62:D$63) -> 1.6 | E4: =eth_ON!E4 - eth_OFF!E4 - AVERAGE(E$62:E$63) -> 3.15 | F4: =eth_ON!F4 - eth_OFF!F4 - AVERAGE(F$62:F$63) -> 2.7 | G4: =eth_ON!G4 - eth_OFF!G4 - AVERAGE(G$62:G$63) -> 2.2 | H4: =eth_ON!H4 - eth_OFF!H4 - AVERAGE(H$62:H$63) -> 4.55 | I4: =eth_ON!I4 - eth_OFF!I4 - AVERAGE(I$62:I$63) -> 6.6 | ... T4: =eth_ON!T4 - eth_OFF!T4 - AVERAGE(T$62:T$63) -> 2.95 | U4: =IF(eth_OFF!U4, (eth_ON!U4+500-eth_ON!U$64) - (eth_OFF!U4+500-eth_OFF!U$64) - AVERAGE($B$62:$AK$63), "") | V4: =IF(eth_OFF!V4, (eth_ON!V4+500-eth_ON!V$64) - (eth_OFF!V4+500-eth_OFF!V$64) - AVERAGE(V$62:V$63), "") | W4: =IF(eth_OFF!W4, (eth_ON!W4+500-eth_ON!W$64) - (eth_OFF!W4+500-eth_OFF!W$64) - AVERAGE(W$62:W$63), "") | X4: =IF(eth_OFF!X4, (eth_ON!X4+500-eth_ON!X$64) - (eth_OFF!X4+500-eth_OFF!X$64) - AVERAGE(X$62:X$63), "") | Y4: =IF(eth_OFF!Y4, (eth_ON!Y4+500-eth_ON!Y$64) - (eth_OFF!Y4+500-eth_OFF!Y$64) - AVERAGE(Y$62:Y$63), "") | Z4: =IF(eth_OFF!Z4, (eth_ON!Z4+500-eth_ON!Z$64) - (eth_OFF!Z4+500-eth_OFF!Z$64) - AVERAGE(Z$62:Z$63), "") | AA4: =IF(eth_OFF!AA4, (eth_ON!AA4+500-eth_ON!AA$64) - (eth_OFF!AA4+500-eth_OFF!AA$64) - AVERAGE(AA$62:AA$63), "") | AB4: =IF(eth_OFF!AB4, (eth_ON!AB4+500-eth_ON!AB$64) - (eth_OFF!AB4+500-eth_OFF!AB$64) - AVERAGE(AB$62:AB$63), "") | AC4: =IF(eth_OFF!AC4, (eth_ON!AC4+500-eth_ON!AC$64) - (eth_OFF!AC4+500-eth_OFF!AC$64) - AVERAGE(AC$62:AC$63), "") | ... AK4: =IF(eth_OFF!AK4, (eth_ON!AK4+500-eth_ON!AK$64) - (eth_OFF!AK4+500-eth_OFF!AK$64) - AVERAGE(AK$62:AK$63), "")
A5: 4 | B5: =eth_ON!B5 - eth_OFF!B5 - AVERAGE(B$62:B$63) -> 3.9 | C5: =eth_ON!C5 - eth_OFF!C5 - AVERAGE(C$62:C$63) -> 2.25 | D5: =eth_ON!D5 - eth_OFF!D5 - AVERAGE(D$62:D$63) -> 2.1 | E5: =eth_ON!E5 - eth_OFF!E5 - AVERAGE(E$62:E$63) -> 3.95 | F5: =eth_ON!F5 - eth_OFF!F5 - AVERAGE(F$62:F$63) -> 3.4 | G5: =eth_ON!G5 - eth_OFF!G5 - AVERAGE(G$62:G$63) -> 2.5 | H5: =eth_ON!H5 - eth_OFF!H5 - AVERAGE(H$62:H$63) -> 3.15 | I5: =eth_ON!I5 - eth_OFF!I5 - AVERAGE(I$62:I$63) -> 4.3 | ... T5: =eth_ON!T5 - eth_OFF!T5 - AVERAGE(T$62:T$63) -> 2.85 | U5: =IF(eth_OFF!U5, (eth_ON!U5+500-eth_ON!U$64) - (eth_OFF!U5+500-eth_OFF!U$64) - AVERAGE($B$62:$AK$63), "") | V5: =IF(eth_OFF!V5, (eth_ON!V5+500-eth_ON!V$64) - (eth_OFF!V5+500-eth_OFF!V$64) - AVERAGE(V$62:V$63), "") | W5: =IF(eth_OFF!W5, (eth_ON!W5+500-eth_ON!W$64) - (eth_OFF!W5+500-eth_OFF!W$64) - AVERAGE(W$62:W$63), "") | X5: =IF(eth_OFF!X5, (eth_ON!X5+500-eth_ON!X$64) - (eth_OFF!X5+500-eth_OFF!X$64) - AVERAGE(X$62:X$63), "") | Y5: =IF(eth_OFF!Y5, (eth_ON!Y5+500-eth_ON!Y$64) - (eth_OFF!Y5+500-eth_OFF!Y$64) - AVERAGE(Y$62:Y$63), "") | Z5: =IF(eth_OFF!Z5, (eth_ON!Z5+500-eth_ON!Z$64) - (eth_OFF!Z5+500-eth_OFF!Z$64) - AVERAGE(Z$62:Z$63), "") | AA5: =IF(eth_OFF!AA5, (eth_ON!AA5+500-eth_ON!AA$64) - (eth_OFF!AA5+500-eth_OFF!AA$64) - AVERAGE(AA$62:AA$63), "") | AB5: =IF(eth_OFF!AB5, (eth_ON!AB5+500-eth_ON!AB$64) - (eth_OFF!AB5+500-eth_OFF!AB$64) - AVERAGE(AB$62:AB$63), "") | AC5: =IF(eth_OFF!AC5, (eth_ON!AC5+500-eth_ON!AC$64) - (eth_OFF!AC5+500-eth_OFF!AC$64) - AVERAGE(AC$62:AC$63), "") | ... AK5: =IF(eth_OFF!AK5, (eth_ON!AK5+500-eth_ON!AK$64) - (eth_OFF!AK5+500-eth_OFF!AK$64) - AVERAGE(AK$62:AK$63), "")
A6: 5 | B6: =eth_ON!B6 - eth_OFF!B6 - AVERAGE(B$62:B$63) -> 0.1 | C6: =eth_ON!C6 - eth_OFF!C6 - AVERAGE(C$62:C$63) -> -0.05 | D6: =eth_ON!D6 - eth_OFF!D6 - AVERAGE(D$62:D$63) -> 0.2 | E6: =eth_ON!E6 - eth_OFF!E6 - AVERAGE(E$62:E$63) -> 0.05 | F6: =eth_ON!F6 - eth_OFF!F6 - AVERAGE(F$62:F$63) -> 0.4 | G6: =eth_ON!G6 - eth_OFF!G6 - AVERAGE(G$62:G$63) -> 2.8421709e-14 | H6: =eth_ON!H6 - eth_OFF!H6 - AVERAGE(H$62:H$63) -> 0.35 | I6: =eth_ON!I6 - eth_OFF!I6 - AVERAGE(I$62:I$63) -> 0.4 | ... T6: =eth_ON!T6 - eth_OFF!T6 - AVERAGE(T$62:T$63) -> 0.25 | U6: =IF(eth_OFF!U6, (eth_ON!U6+500-eth_ON!U$64) - (eth_OFF!U6+500-eth_OFF!U$64) - AVERAGE($B$62:$AK$63), "") | V6: =IF(eth_OFF!V6, (eth_ON!V6+500-eth_ON!V$64) - (eth_OFF!V6+500-eth_OFF!V$64) - AVERAGE(V$62:V$63), "") | W6: =IF(eth_OFF!W6, (eth_ON!W6+500-eth_ON!W$64) - (eth_OFF!W6+500-eth_OFF!W$64) - AVERAGE(W$62:W$63), "") | X6: =IF(eth_OFF!X6, (eth_ON!X6+500-eth_ON!X$64) - (eth_OFF!X6+500-eth_OFF!X$64) - AVERAGE(X$62:X$63), "") | Y6: =IF(eth_OFF!Y6, (eth_ON!Y6+500-eth_ON!Y$64) - (eth_OFF!Y6+500-eth_OFF!Y$64) - AVERAGE(Y$62:Y$63), "") | Z6: =IF(eth_OFF!Z6, (eth_ON!Z6+500-eth_ON!Z$64) - (eth_OFF!Z6+500-eth_OFF!Z$64) - AVERAGE(Z$62:Z$63), "") | AA6: =IF(eth_OFF!AA6, (eth_ON!AA6+500-eth_ON!AA$64) - (eth_OFF!AA6+500-eth_OFF!AA$64) - AVERAGE(AA$62:AA$63), "") | AB6: =IF(eth_OFF!AB6, (eth_ON!AB6+500-eth_ON!AB$64) - (eth_OFF!AB6+500-eth_OFF!AB$64) - AVERAGE(AB$62:AB$63), "") | AC6: =IF(eth_OFF!AC6, (eth_ON!AC6+500-eth_ON!AC$64) - (eth_OFF!AC6+500-eth_OFF!AC$64) - AVERAGE(AC$62:AC$63), "") | ... AK6: =IF(eth_OFF!AK6, (eth_ON!AK6+500-eth_ON!AK$64) - (eth_OFF!AK6+500-eth_OFF!AK$64) - AVERAGE(AK$62:AK$63), "")
A7: 6 | B7: =eth_ON!B7 - eth_OFF!B7 - AVERAGE(B$62:B$63) -> 2.7 | C7: =eth_ON!C7 - eth_OFF!C7 - AVERAGE(C$62:C$63) -> 3.55 | D7: =eth_ON!D7 - eth_OFF!D7 - AVERAGE(D$62:D$63) -> 4.3 | E7: =eth_ON!E7 - eth_OFF!E7 - AVERAGE(E$62:E$63) -> 4.65 | F7: =eth_ON!F7 - eth_OFF!F7 - AVERAGE(F$62:F$63) -> 2.1 | G7: =eth_ON!G7 - eth_OFF!G7 - AVERAGE(G$62:G$63) -> 3.2 | H7: =eth_ON!H7 - eth_OFF!H7 - AVERAGE(H$62:H$63) -> 3.75 | I7: =eth_ON!I7 - eth_OFF!I7 - AVERAGE(I$62:I$63) -> 4.7 | ... T7: =eth_ON!T7 - eth_OFF!T7 - AVERAGE(T$62:T$63) -> 1.65 | U7: =IF(eth_OFF!U7, (eth_ON!U7+500-eth_ON!U$64) - (eth_OFF!U7+500-eth_OFF!U$64) - AVERAGE($B$62:$AK$63), "") | V7: =IF(eth_OFF!V7, (eth_ON!V7+500-eth_ON!V$64) - (eth_OFF!V7+500-eth_OFF!V$64) - AVERAGE(V$62:V$63), "") | W7: =IF(eth_OFF!W7, (eth_ON!W7+500-eth_ON!W$64) - (eth_OFF!W7+500-eth_OFF!W$64) - AVERAGE(W$62:W$63), "") | X7: =IF(eth_OFF!X7, (eth_ON!X7+500-eth_ON!X$64) - (eth_OFF!X7+500-eth_OFF!X$64) - AVERAGE(X$62:X$63), "") | Y7: =IF(eth_OFF!Y7, (eth_ON!Y7+500-eth_ON!Y$64) - (eth_OFF!Y7+500-eth_OFF!Y$64) - AVERAGE(Y$62:Y$63), "") | Z7: =IF(eth_OFF!Z7, (eth_ON!Z7+500-eth_ON!Z$64) - (eth_OFF!Z7+500-eth_OFF!Z$64) - AVERAGE(Z$62:Z$63), "") | AA7: =IF(eth_OFF!AA7, (eth_ON!AA7+500-eth_ON!AA$64) - (eth_OFF!AA7+500-eth_OFF!AA$64) - AVERAGE(AA$62:AA$63), "") | AB7: =IF(eth_OFF!AB7, (eth_ON!AB7+500-eth_ON!AB$64) - (eth_OFF!AB7+500-eth_OFF!AB$64) - AVERAGE(AB$62:AB$63), "") | AC7: =IF(eth_OFF!AC7, (eth_ON!AC7+500-eth_ON!AC$64) - (eth_OFF!AC7+500-eth_OFF!AC$64) - AVERAGE(AC$62:AC$63), "") | ... AK7: =IF(eth_OFF!AK7, (eth_ON!AK7+500-eth_ON!AK$64) - (eth_OFF!AK7+500-eth_OFF!AK$64) - AVERAGE(AK$62:AK$63), "")
A8: 7 | B8: =eth_ON!B8 - eth_OFF!B8 - AVERAGE(B$62:B$63) -> 3.1 | C8: =eth_ON!C8 - eth_OFF!C8 - AVERAGE(C$62:C$63) -> 1.15 | D8: =eth_ON!D8 - eth_OFF!D8 - AVERAGE(D$62:D$63) -> 2.4 | E8: =eth_ON!E8 - eth_OFF!E8 - AVERAGE(E$62:E$63) -> 2.35 | F8: =eth_ON!F8 - eth_OFF!F8 - AVERAGE(F$62:F$63) -> 1.6 | G8: =eth_ON!G8 - eth_OFF!G8 - AVERAGE(G$62:G$63) -> 1.4 | H8: =eth_ON!H8 - eth_OFF!H8 - AVERAGE(H$62:H$63) -> 3.95 | I8: =eth_ON!I8 - eth_OFF!I8 - AVERAGE(I$62:I$63) -> 3.2 | ... T8: =eth_ON!T8 - eth_OFF!T8 - AVERAGE(T$62:T$63) -> 2.45 | U8: =IF(eth_OFF!U8, (eth_ON!U8+500-eth_ON!U$64) - (eth_OFF!U8+500-eth_OFF!U$64) - AVERAGE($B$62:$AK$63), "") | V8: =IF(eth_OFF!V8, (eth_ON!V8+500-eth_ON!V$64) - (eth_OFF!V8+500-eth_OFF!V$64) - AVERAGE(V$62:V$63), "") | W8: =IF(eth_OFF!W8, (eth_ON!W8+500-eth_ON!W$64) - (eth_OFF!W8+500-eth_OFF!W$64) - AVERAGE(W$62:W$63), "") | X8: =IF(eth_OFF!X8, (eth_ON!X8+500-eth_ON!X$64) - (eth_OFF!X8+500-eth_OFF!X$64) - AVERAGE(X$62:X$63), "") | Y8: =IF(eth_OFF!Y8, (eth_ON!Y8+500-eth_ON!Y$64) - (eth_OFF!Y8+500-eth_OFF!Y$64) - AVERAGE(Y$62:Y$63), "") | Z8: =IF(eth_OFF!Z8, (eth_ON!Z8+500-eth_ON!Z$64) - (eth_OFF!Z8+500-eth_OFF!Z$64) - AVERAGE(Z$62:Z$63), "") | AA8: =IF(eth_OFF!AA8, (eth_ON!AA8+500-eth_ON!AA$64) - (eth_OFF!AA8+500-eth_OFF!AA$64) - AVERAGE(AA$62:AA$63), "") | AB8: =IF(eth_OFF!AB8, (eth_ON!AB8+500-eth_ON!AB$64) - (eth_OFF!AB8+500-eth_OFF!AB$64) - AVERAGE(AB$62:AB$63), "") | AC8: =IF(eth_OFF!AC8, (eth_ON!AC8+500-eth_ON!AC$64) - (eth_OFF!AC8+500-eth_OFF!AC$64) - AVERAGE(AC$62:AC$63), "") | ... AK8: =IF(eth_OFF!AK8, (eth_ON!AK8+500-eth_ON!AK$64) - (eth_OFF!AK8+500-eth_OFF!AK$64) - AVERAGE(AK$62:AK$63), "")
A9: 8 | B9: =eth_ON!B9 - eth_OFF!B9 - AVERAGE(B$62:B$63) -> 1.9 | C9: =eth_ON!C9 - eth_OFF!C9 - AVERAGE(C$62:C$63) -> 2.65 | D9: =eth_ON!D9 - eth_OFF!D9 - AVERAGE(D$62:D$63) -> 3.7 | E9: =eth_ON!E9 - eth_OFF!E9 - AVERAGE(E$62:E$63) -> 3.15 | F9: =eth_ON!F9 - eth_OFF!F9 - AVERAGE(F$62:F$63) -> 3.3 | G9: =eth_ON!G9 - eth_OFF!G9 - AVERAGE(G$62:G$63) -> 1.9 | H9: =eth_ON!H9 - eth_OFF!H9 - AVERAGE(H$62:H$63) -> 3.75 | I9: =eth_ON!I9 - eth_OFF!I9 - AVERAGE(I$62:I$63) -> 3.5 | ... T9: =eth_ON!T9 - eth_OFF!T9 - AVERAGE(T$62:T$63) -> 2.35 | U9: =IF(eth_OFF!U9, (eth_ON!U9+500-eth_ON!U$64) - (eth_OFF!U9+500-eth_OFF!U$64) - AVERAGE($B$62:$AK$63), "") | V9: =IF(eth_OFF!V9, (eth_ON!V9+500-eth_ON!V$64) - (eth_OFF!V9+500-eth_OFF!V$64) - AVERAGE(V$62:V$63), "") | W9: =IF(eth_OFF!W9, (eth_ON!W9+500-eth_ON!W$64) - (eth_OFF!W9+500-eth_OFF!W$64) - AVERAGE(W$62:W$63), "") | X9: =IF(eth_OFF!X9, (eth_ON!X9+500-eth_ON!X$64) - (eth_OFF!X9+500-eth_OFF!X$64) - AVERAGE(X$62:X$63), "") | Y9: =IF(eth_OFF!Y9, (eth_ON!Y9+500-eth_ON!Y$64) - (eth_OFF!Y9+500-eth_OFF!Y$64) - AVERAGE(Y$62:Y$63), "") | Z9: =IF(eth_OFF!Z9, (eth_ON!Z9+500-eth_ON!Z$64) - (eth_OFF!Z9+500-eth_OFF!Z$64) - AVERAGE(Z$62:Z$63), "") | AA9: =IF(eth_OFF!AA9, (eth_ON!AA9+500-eth_ON!AA$64) - (eth_OFF!AA9+500-eth_OFF!AA$64) - AVERAGE(AA$62:AA$63), "") | AB9: =IF(eth_OFF!AB9, (eth_ON!AB9+500-eth_ON!AB$64) - (eth_OFF!AB9+500-eth_OFF!AB$64) - AVERAGE(AB$62:AB$63), "") | AC9: =IF(eth_OFF!AC9, (eth_ON!AC9+500-eth_ON!AC$64) - (eth_OFF!AC9+500-eth_OFF!AC$64) - AVERAGE(AC$62:AC$63), "") | ... AK9: =IF(eth_OFF!AK9, (eth_ON!AK9+500-eth_ON!AK$64) - (eth_OFF!AK9+500-eth_OFF!AK$64) - AVERAGE(AK$62:AK$63), "")
A10: 9 | B10: =eth_ON!B10 - eth_OFF!B10 - AVERAGE(B$62:B$63) -> 0.2 | C10: =eth_ON!C10 - eth_OFF!C10 - AVERAGE(C$62:C$63) -> -0.05 | D10: =eth_ON!D10 - eth_OFF!D10 - AVERAGE(D$62:D$63) -> 0.1 | E10: =eth_ON!E10 - eth_OFF!E10 - AVERAGE(E$62:E$63) -> -0.05 | F10: =eth_ON!F10 - eth_OFF!F10 - AVERAGE(F$62:F$63) -> 0.6 | G10: =eth_ON!G10 - eth_OFF!G10 - AVERAGE(G$62:G$63) -> 0.3 | H10: =eth_ON!H10 - eth_OFF!H10 - AVERAGE(H$62:H$63) -> 0.05 | I10: =eth_ON!I10 - eth_OFF!I10 - AVERAGE(I$62:I$63) -> 0.2 | ... T10: =eth_ON!T10 - eth_OFF!T10 - AVERAGE(T$62:T$63) -> 0.35 | U10: =IF(eth_OFF!U10, (eth_ON!U10+500-eth_ON!U$64) - (eth_OFF!U10+500-eth_OFF!U$64) - AVERAGE($B$62:$AK$63), "") | V10: =IF(eth_OFF!V10, (eth_ON!V10+500-eth_ON!V$64) - (eth_OFF!V10+500-eth_OFF!V$64) - AVERAGE(V$62:V$63), "") | W10: =IF(eth_OFF!W10, (eth_ON!W10+500-eth_ON!W$64) - (eth_OFF!W10+500-eth_OFF!W$64) - AVERAGE(W$62:W$63), "") | X10: =IF(eth_OFF!X10, (eth_ON!X10+500-eth_ON!X$64) - (eth_OFF!X10+500-eth_OFF!X$64) - AVERAGE(X$62:X$63), "") | Y10: =IF(eth_OFF!Y10, (eth_ON!Y10+500-eth_ON!Y$64) - (eth_OFF!Y10+500-eth_OFF!Y$64) - AVERAGE(Y$62:Y$63), "") | Z10: =IF(eth_OFF!Z10, (eth_ON!Z10+500-eth_ON!Z$64) - (eth_OFF!Z10+500-eth_OFF!Z$64) - AVERAGE(Z$62:Z$63), "") | AA10: =IF(eth_OFF!AA10, (eth_ON!AA10+500-eth_ON!AA$64) - (eth_OFF!AA10+500-eth_OFF!AA$64) - AVERAGE(AA$62:AA$63), "") | AB10: =IF(eth_OFF!AB10, (eth_ON!AB10+500-eth_ON!AB$64) - (eth_OFF!AB10+500-eth_OFF!AB$64) - AVERAGE(AB$62:AB$63), "") | AC10: =IF(eth_OFF!AC10, (eth_ON!AC10+500-eth_ON!AC$64) - (eth_OFF!AC10+500-eth_OFF!AC$64) - AVERAGE(AC$62:AC$63), "") | ... AK10: =IF(eth_OFF!AK10, (eth_ON!AK10+500-eth_ON!AK$64) - (eth_OFF!AK10+500-eth_OFF!AK$64) - AVERAGE(AK$62:AK$63), "")
A11: 10 | B11: =eth_ON!B11 - eth_OFF!B11 - AVERAGE(B$62:B$63) -> -5.6843419e-14 | C11: =eth_ON!C11 - eth_OFF!C11 - AVERAGE(C$62:C$63) -> -0.05 | D11: =eth_ON!D11 - eth_OFF!D11 - AVERAGE(D$62:D$63) -> 0.5 | E11: =eth_ON!E11 - eth_OFF!E11 - AVERAGE(E$62:E$63) -> 0.45 | F11: =eth_ON!F11 - eth_OFF!F11 - AVERAGE(F$62:F$63) -> 0.1 | G11: =eth_ON!G11 - eth_OFF!G11 - AVERAGE(G$62:G$63) -> 0.2 | H11: =eth_ON!H11 - eth_OFF!H11 - AVERAGE(H$62:H$63) -> 0.35 | I11: =eth_ON!I11 - eth_OFF!I11 - AVERAGE(I$62:I$63) -> 0.5 | ... T11: =eth_ON!T11 - eth_OFF!T11 - AVERAGE(T$62:T$63) -> 0.55 | U11: =IF(eth_OFF!U11, (eth_ON!U11+500-eth_ON!U$64) - (eth_OFF!U11+500-eth_OFF!U$64) - AVERAGE($B$62:$AK$63), "") | V11: =IF(eth_OFF!V11, (eth_ON!V11+500-eth_ON!V$64) - (eth_OFF!V11+500-eth_OFF!V$64) - AVERAGE(V$62:V$63), "") | W11: =IF(eth_OFF!W11, (eth_ON!W11+500-eth_ON!W$64) - (eth_OFF!W11+500-eth_OFF!W$64) - AVERAGE(W$62:W$63), "") | X11: =IF(eth_OFF!X11, (eth_ON!X11+500-eth_ON!X$64) - (eth_OFF!X11+500-eth_OFF!X$64) - AVERAGE(X$62:X$63), "") | Y11: =IF(eth_OFF!Y11, (eth_ON!Y11+500-eth_ON!Y$64) - (eth_OFF!Y11+500-eth_OFF!Y$64) - AVERAGE(Y$62:Y$63), "") | Z11: =IF(eth_OFF!Z11, (eth_ON!Z11+500-eth_ON!Z$64) - (eth_OFF!Z11+500-eth_OFF!Z$64) - AVERAGE(Z$62:Z$63), "") | AA11: =IF(eth_OFF!AA11, (eth_ON!AA11+500-eth_ON!AA$64) - (eth_OFF!AA11+500-eth_OFF!AA$64) - AVERAGE(AA$62:AA$63), "") | AB11: =IF(eth_OFF!AB11, (eth_ON!AB11+500-eth_ON!AB$64) - (eth_OFF!AB11+500-eth_OFF!AB$64) - AVERAGE(AB$62:AB$63), "") | AC11: =IF(eth_OFF!AC11, (eth_ON!AC11+500-eth_ON!AC$64) - (eth_OFF!AC11+500-eth_OFF!AC$64) - AVERAGE(AC$62:AC$63), "") | ... AK11: =IF(eth_OFF!AK11, (eth_ON!AK11+500-eth_ON!AK$64) - (eth_OFF!AK11+500-eth_OFF!AK$64) - AVERAGE(AK$62:AK$63), "")
A12: 11 | B12: =eth_ON!B12 - eth_OFF!B12 - AVERAGE(B$62:B$63) -> 2.8 | C12: =eth_ON!C12 - eth_OFF!C12 - AVERAGE(C$62:C$63) -> 2.55 | D12: =eth_ON!D12 - eth_OFF!D12 - AVERAGE(D$62:D$63) -> 2.9 | E12: =eth_ON!E12 - eth_OFF!E12 - AVERAGE(E$62:E$63) -> 2.25 | F12: =eth_ON!F12 - eth_OFF!F12 - AVERAGE(F$62:F$63) -> 1.8 | G12: =eth_ON!G12 - eth_OFF!G12 - AVERAGE(G$62:G$63) -> 2.7 | H12: =eth_ON!H12 - eth_OFF!H12 - AVERAGE(H$62:H$63) -> 2.05 | I12: =eth_ON!I12 - eth_OFF!I12 - AVERAGE(I$62:I$63) -> 2.6 | ... T12: =eth_ON!T12 - eth_OFF!T12 - AVERAGE(T$62:T$63) -> 0.45 | U12: =IF(eth_OFF!U12, (eth_ON!U12+500-eth_ON!U$64) - (eth_OFF!U12+500-eth_OFF!U$64) - AVERAGE($B$62:$AK$63), "") | V12: =IF(eth_OFF!V12, (eth_ON!V12+500-eth_ON!V$64) - (eth_OFF!V12+500-eth_OFF!V$64) - AVERAGE(V$62:V$63), "") | W12: =IF(eth_OFF!W12, (eth_ON!W12+500-eth_ON!W$64) - (eth_OFF!W12+500-eth_OFF!W$64) - AVERAGE(W$62:W$63), "") | X12: =IF(eth_OFF!X12, (eth_ON!X12+500-eth_ON!X$64) - (eth_OFF!X12+500-eth_OFF!X$64) - AVERAGE(X$62:X$63), "") | Y12: =IF(eth_OFF!Y12, (eth_ON!Y12+500-eth_ON!Y$64) - (eth_OFF!Y12+500-eth_OFF!Y$64) - AVERAGE(Y$62:Y$63), "") | Z12: =IF(eth_OFF!Z12, (eth_ON!Z12+500-eth_ON!Z$64) - (eth_OFF!Z12+500-eth_OFF!Z$64) - AVERAGE(Z$62:Z$63), "") | AA12: =IF(eth_OFF!AA12, (eth_ON!AA12+500-eth_ON!AA$64) - (eth_OFF!AA12+500-eth_OFF!AA$64) - AVERAGE(AA$62:AA$63), "") | AB12: =IF(eth_OFF!AB12, (eth_ON!AB12+500-eth_ON!AB$64) - (eth_OFF!AB12+500-eth_OFF!AB$64) - AVERAGE(AB$62:AB$63), "") | AC12: =IF(eth_OFF!AC12, (eth_ON!AC12+500-eth_ON!AC$64) - (eth_OFF!AC12+500-eth_OFF!AC$64) - AVERAGE(AC$62:AC$63), "") | ... AK12: =IF(eth_OFF!AK12, (eth_ON!AK12+500-eth_ON!AK$64) - (eth_OFF!AK12+500-eth_OFF!AK$64) - AVERAGE(AK$62:AK$63), "")
A13: 12 | B13: =eth_ON!B13 - eth_OFF!B13 - AVERAGE(B$62:B$63) -> 4 | C13: =eth_ON!C13 - eth_OFF!C13 - AVERAGE(C$62:C$63) -> 3.95 | D13: =eth_ON!D13 - eth_OFF!D13 - AVERAGE(D$62:D$63) -> 4.6 | E13: =eth_ON!E13 - eth_OFF!E13 - AVERAGE(E$62:E$63) -> 3.35 | F13: =eth_ON!F13 - eth_OFF!F13 - AVERAGE(F$62:F$63) -> 5.2 | G13: =eth_ON!G13 - eth_OFF!G13 - AVERAGE(G$62:G$63) -> 1.9 | H13: =eth_ON!H13 - eth_OFF!H13 - AVERAGE(H$62:H$63) -> 1.75 | I13: =eth_ON!I13 - eth_OFF!I13 - AVERAGE(I$62:I$63) -> 2.3 | ... T13: =eth_ON!T13 - eth_OFF!T13 - AVERAGE(T$62:T$63) -> 1.25 | U13: =IF(eth_OFF!U13, (eth_ON!U13+500-eth_ON!U$64) - (eth_OFF!U13+500-eth_OFF!U$64) - AVERAGE($B$62:$AK$63), "") | V13: =IF(eth_OFF!V13, (eth_ON!V13+500-eth_ON!V$64) - (eth_OFF!V13+500-eth_OFF!V$64) - AVERAGE(V$62:V$63), "") | W13: =IF(eth_OFF!W13, (eth_ON!W13+500-eth_ON!W$64) - (eth_OFF!W13+500-eth_OFF!W$64) - AVERAGE(W$62:W$63), "") | X13: =IF(eth_OFF!X13, (eth_ON!X13+500-eth_ON!X$64) - (eth_OFF!X13+500-eth_OFF!X$64) - AVERAGE(X$62:X$63), "") | Y13: =IF(eth_OFF!Y13, (eth_ON!Y13+500-eth_ON!Y$64) - (eth_OFF!Y13+500-eth_OFF!Y$64) - AVERAGE(Y$62:Y$63), "") | Z13: =IF(eth_OFF!Z13, (eth_ON!Z13+500-eth_ON!Z$64) - (eth_OFF!Z13+500-eth_OFF!Z$64) - AVERAGE(Z$62:Z$63), "") | AA13: =IF(eth_OFF!AA13, (eth_ON!AA13+500-eth_ON!AA$64) - (eth_OFF!AA13+500-eth_OFF!AA$64) - AVERAGE(AA$62:AA$63), "") | AB13: =IF(eth_OFF!AB13, (eth_ON!AB13+500-eth_ON!AB$64) - (eth_OFF!AB13+500-eth_OFF!AB$64) - AVERAGE(AB$62:AB$63), "") | AC13: =IF(eth_OFF!AC13, (eth_ON!AC13+500-eth_ON!AC$64) - (eth_OFF!AC13+500-eth_OFF!AC$64) - AVERAGE(AC$62:AC$63), "") | ... AK13: =IF(eth_OFF!AK13, (eth_ON!AK13+500-eth_ON!AK$64) - (eth_OFF!AK13+500-eth_OFF!AK$64) - AVERAGE(AK$62:AK$63), "")
... A61: 60 | B61: =eth_ON!B61 - eth_OFF!B61 - AVERAGE(B$62:B$63) -> 6 | C61: =eth_ON!C61 - eth_OFF!C61 - AVERAGE(C$62:C$63) -> 6.05 | D61: =eth_ON!D61 - eth_OFF!D61 - AVERAGE(D$62:D$63) -> 6 | E61: =eth_ON!E61 - eth_OFF!E61 - AVERAGE(E$62:E$63) -> 4.65 | F61: =eth_ON!F61 - eth_OFF!F61 - AVERAGE(F$62:F$63) -> 5.2 | G61: =eth_ON!G61 - eth_OFF!G61 - AVERAGE(G$62:G$63) -> 3.6 | H61: =eth_ON!H61 - eth_OFF!H61 - AVERAGE(H$62:H$63) -> 3.85 | I61: =eth_ON!I61 - eth_OFF!I61 - AVERAGE(I$62:I$63) -> 6 | ... T61: =eth_ON!T61 - eth_OFF!T61 - AVERAGE(T$62:T$63) -> 4.85 | U61: =IF(eth_OFF!U61, (eth_ON!U61+500-eth_ON!U$64) - (eth_OFF!U61+500-eth_OFF!U$64) - AVERAGE($B$62:$AK$63), "") | V61: =IF(eth_OFF!V61, (eth_ON!V61+500-eth_ON!V$64) - (eth_OFF!V61+500-eth_OFF!V$64) - AVERAGE(V$62:V$63), "") | W61: =IF(eth_OFF!W61, (eth_ON!W61+500-eth_ON!W$64) - (eth_OFF!W61+500-eth_OFF!W$64) - AVERAGE(W$62:W$63), "") | X61: =IF(eth_OFF!X61, (eth_ON!X61+500-eth_ON!X$64) - (eth_OFF!X61+500-eth_OFF!X$64) - AVERAGE(X$62:X$63), "") | Y61: =IF(eth_OFF!Y61, (eth_ON!Y61+500-eth_ON!Y$64) - (eth_OFF!Y61+500-eth_OFF!Y$64) - AVERAGE(Y$62:Y$63), "") | Z61: =IF(eth_OFF!Z61, (eth_ON!Z61+500-eth_ON!Z$64) - (eth_OFF!Z61+500-eth_OFF!Z$64) - AVERAGE(Z$62:Z$63), "") | AA61: =IF(eth_OFF!AA61, (eth_ON!AA61+500-eth_ON!AA$64) - (eth_OFF!AA61+500-eth_OFF!AA$64) - AVERAGE(AA$62:AA$63), "") | AB61: =IF(eth_OFF!AB61, (eth_ON!AB61+500-eth_ON!AB$64) - (eth_OFF!AB61+500-eth_OFF!AB$64) - AVERAGE(AB$62:AB$63), "") | AC61: =IF(eth_OFF!AC61, (eth_ON!AC61+500-eth_ON!AC$64) - (eth_OFF!AC61+500-eth_OFF!AC$64) - AVERAGE(AC$62:AC$63), "") | ... AK61: =IF(eth_OFF!AK61, (eth_ON!AK61+500-eth_ON!AK$64) - (eth_OFF!AK61+500-eth_OFF!AK$64) - AVERAGE(AK$62:AK$63), "")
A62: leak1 | B62: =eth_ON!B62 - eth_OFF!B62 -> 0.6 | C62: =eth_ON!C62 - eth_OFF!C62 -> 0.2 | D62: =eth_ON!D62 - eth_OFF!D62 -> 0.1 | E62: =eth_ON!E62 - eth_OFF!E62 -> 0.3 | F62: =eth_ON!F62 - eth_OFF!F62 -> 0.2 | G62: =eth_ON!G62 - eth_OFF!G62 -> 0.3 | H62: =eth_ON!H62 - eth_OFF!H62 -> 0.5 | I62: =eth_ON!I62 - eth_OFF!I62 -> 0.3 | ... T62: =eth_ON!T62 - eth_OFF!T62 -> 0.1 | U62: =IF(eth_OFF!U62, (eth_ON!U62+500-eth_ON!U$64) - (eth_OFF!U62+500-eth_OFF!U$64), "") | V62: =IF(eth_OFF!V62, (eth_ON!V62+500-eth_ON!V$64) - (eth_OFF!V62+500-eth_OFF!V$64), "") | W62: =IF(eth_OFF!W62, (eth_ON!W62+500-eth_ON!W$64) - (eth_OFF!W62+500-eth_OFF!W$64), "") | X62: =IF(eth_OFF!X62, (eth_ON!X62+500-eth_ON!X$64) - (eth_OFF!X62+500-eth_OFF!X$64), "") | Y62: =IF(eth_OFF!Y62, (eth_ON!Y62+500-eth_ON!Y$64) - (eth_OFF!Y62+500-eth_OFF!Y$64), "") | Z62: =IF(eth_OFF!Z62, (eth_ON!Z62+500-eth_ON!Z$64) - (eth_OFF!Z62+500-eth_OFF!Z$64), "") | AA62: =IF(eth_OFF!AA62, (eth_ON!AA62+500-eth_ON!AA$64) - (eth_OFF!AA62+500-eth_OFF!AA$64), "") | AB62: =IF(eth_OFF!AB62, (eth_ON!AB62+500-eth_ON!AB$64) - (eth_OFF!AB62+500-eth_OFF!AB$64), "") | ... AK62: =IF(eth_OFF!AK62, (eth_ON!AK62+500-eth_ON!AK$64) - (eth_OFF!AK62+500-eth_OFF!AK$64), "")
A63: leak2 | B63: =eth_ON!B63 - eth_OFF!B63 -> 0.2 | C63: =eth_ON!C63 - eth_OFF!C63 -> 0.3 | D63: =eth_ON!D63 - eth_OFF!D63 -> 0.1 | E63: =eth_ON!E63 - eth_OFF!E63 -> 0 | F63: =eth_ON!F63 - eth_OFF!F63 -> 0 | G63: =eth_ON!G63 - eth_OFF!G63 -> 0.3 | H63: =eth_ON!H63 - eth_OFF!H63 -> 0.2 | I63: =eth_ON!I63 - eth_OFF!I63 -> 0.3 | ... T63: =eth_ON!T63 - eth_OFF!T63 -> 0 | U63: =IF(eth_OFF!U63, (eth_ON!U63+500-eth_ON!U$64) - (eth_OFF!U63+500-eth_OFF!U$64), "") | V63: =IF(eth_OFF!V63, (eth_ON!V63+500-eth_ON!V$64) - (eth_OFF!V63+500-eth_OFF!V$64), "") | W63: =IF(eth_OFF!W63, (eth_ON!W63+500-eth_ON!W$64) - (eth_OFF!W63+500-eth_OFF!W$64), "") | X63: =IF(eth_OFF!X63, (eth_ON!X63+500-eth_ON!X$64) - (eth_OFF!X63+500-eth_OFF!X$64), "") | Y63: =IF(eth_OFF!Y63, (eth_ON!Y63+500-eth_ON!Y$64) - (eth_OFF!Y63+500-eth_OFF!Y$64), "") | Z63: =IF(eth_OFF!Z63, (eth_ON!Z63+500-eth_ON!Z$64) - (eth_OFF!Z63+500-eth_OFF!Z$64), "") | AA63: =IF(eth_OFF!AA63, (eth_ON!AA63+500-eth_ON!AA$64) - (eth_OFF!AA63+500-eth_OFF!AA$64), "") | AB63: =IF(eth_OFF!AB63, (eth_ON!AB63+500-eth_ON!AB$64) - (eth_OFF!AB63+500-eth_OFF!AB$64), "") | ... AK63: =IF(eth_OFF!AK63, (eth_ON!AK63+500-eth_ON!AK$64) - (eth_OFF!AK63+500-eth_OFF!AK$64), "")

Sheet E_per_kg
A1: ID | B1: 45957 | C1: 45958 | D1: 45959 | E1: 45960 | F1: 45961 | G1: 45964 | H1: 45965 | I1: 45966 | J1: 45967 | K1: 45968 | L1: 45971 | M1: 45972 | N1: 45973 | O1: 45974 | P1: 45975 | Q1: 45978 | R1: 45979 | S1: 45980 | T1: 45981
A2: 1 | B2: =E_g!B2/(rat_weight!B2/1000)*0.1578 -> 1.5889583 | C2: =E_g!C2/(rat_weight!C2/1000)*0.1578 -> 1.8903125 | D2: =E_g!D2/(rat_weight!D2/1000)*0.1578 -> 1.808125 | E2: =E_g!E2/(rat_weight!E2/1000)*0.1578 -> 2.0546875 | F2: =E_g!F2/(rat_weight!F2/1000)*0.1578 -> 1.5889583 | G2: =E_g!G2/(rat_weight!G2/1000)*0.1578 -> 1.3574194 | H2: =E_g!H2/(rat_weight!H2/1000)*0.1578 -> 1.7816129 | I2: =E_g!I2/(rat_weight!I2/1000)*0.1578 -> 1.9230108 | ... T2: =E_g!T2/(rat_weight!T2/1000)*0.1578 -> 0.52052083 | X2: =E_g!AJ2 | Y2: =E_g!AK2
A3: 2 | B3: =E_g!B3/(rat_weight!B3/1000)*0.1578 -> 1.3005495 | C3: =E_g!C3/(rat_weight!C3/1000)*0.1578 -> 1.1704945 | D3: =E_g!D3/(rat_weight!D3/1000)*0.1578 -> 0.95373626 | E3: =E_g!E3/(rat_weight!E3/1000)*0.1578 -> 1.604011 | F3: =E_g!F3/(rat_weight!F3/1000)*0.1578 -> 1.3872527 | G3: =E_g!G3/(rat_weight!G3/1000)*0.1578 -> 0.96433333 | H3: =E_g!H3/(rat_weight!H3/1000)*0.1578 -> 0.74516667 | I3: =E_g!I3/(rat_weight!I3/1000)*0.1578 -> 1.4903333 | ... T3: =E_g!T3/(rat_weight!T3/1000)*0.1578 -> 0.30513812
A4: 3 | B4: =E_g!B4/(rat_weight!B4/1000)*0.1578 -> 0.70253425 | C4: =E_g!C4/(rat_weight!C4/1000)*0.1578 -> 1.283476 | D4: =E_g!D4/(rat_weight!D4/1000)*0.1578 -> 0.43232877 | E4: =E_g!E4/(rat_weight!E4/1000)*0.1578 -> 0.85114726 | F4: =E_g!F4/(rat_weight!F4/1000)*0.1578 -> 0.72955479 | G4: =E_g!G4/(rat_weight!G4/1000)*0.1578 -> 0.58840678 | H4: =E_g!H4/(rat_weight!H4/1000)*0.1578 -> 1.2169322 | I4: =E_g!I4/(rat_weight!I4/1000)*0.1578 -> 1.7652203 | ... T4: =E_g!T4/(rat_weight!T4/1000)*0.1578 -> 0.78368687
A5: 4 | B5: =E_g!B5/(rat_weight!B5/1000)*0.1578 -> 1.9475316 | C5: =E_g!C5/(rat_weight!C5/1000)*0.1578 -> 1.1235759 | D5: =E_g!D5/(rat_weight!D5/1000)*0.1578 -> 1.0486709 | E5: =E_g!E5/(rat_weight!E5/1000)*0.1578 -> 1.9725 | F5: =E_g!F5/(rat_weight!F5/1000)*0.1578 -> 1.6978481 | G5: =E_g!G5/(rat_weight!G5/1000)*0.1578 -> 1.252381 | H5: =E_g!H5/(rat_weight!H5/1000)*0.1578 -> 1.578 | I5: =E_g!I5/(rat_weight!I5/1000)*0.1578 -> 2.1540952 | ... T5: =E_g!T5/(rat_weight!T5/1000)*0.1578 -> 1.4098119
A6: 5 | B6: =E_g!B6/(rat_weight!B6/1000)*0.1578 -> 0.025742251 | C6: =E_g!C6/(rat_weight!C6/1000)*0.1578 -> -0.012871126 | D6: =E_g!D6/(rat_weight!D6/1000)*0.1578 -> 0.051484502 | E6: =E_g!E6/(rat_weight!E6/1000)*0.1578 -> 0.012871126 | F6: =E_g!F6/(rat_weight!F6/1000)*0.1578 -> 0.102969 | G6: =E_g!G6/(rat_weight!G6/1000)*0.1578 -> 7.2105237e-15 | H6: =E_g!H6/(rat_weight!H6/1000)*0.1578 -> 0.088794212 | I6: =E_g!I6/(rat_weight!I6/1000)*0.1578 -> 0.1014791 | ... T6: =E_g!T6/(rat_weight!T6/1000)*0.1578 -> 0.061353033
A7: 6 | B7: =E_g!B7/(rat_weight!B7/1000)*0.1578 -> 0.94261062 | C7: =E_g!C7/(rat_weight!C7/1000)*0.1578 -> 1.2393584 | D7: =E_g!D7/(rat_weight!D7/1000)*0.1578 -> 1.5011947 | E7: =E_g!E7/(rat_weight!E7/1000)*0.1578 -> 1.623385 | F7: =E_g!F7/(rat_weight!F7/1000)*0.1578 -> 0.73314159 | G7: =E_g!G7/(rat_weight!G7/1000)*0.1578 -> 1.1049453 | H7: =E_g!H7/(rat_weight!H7/1000)*0.1578 -> 1.2948578 | I7: =E_g!I7/(rat_weight!I7/1000)*0.1578 -> 1.6228884 | ... T7: =E_g!T7/(rat_weight!T7/1000)*0.1578 -> 0.55397872
A8: 7 | B8: =E_g!B8/(rat_weight!B8/1000)*0.1578 -> 1.6582373 | C8: =E_g!C8/(rat_weight!C8/1000)*0.1578 -> 0.61515254 | D8: =E_g!D8/(rat_weight!D8/1000)*0.1578 -> 1.2837966 | E8: =E_g!E8/(rat_weight!E8/1000)*0.1578 -> 1.2570508 | F8: =E_g!F8/(rat_weight!F8/1000)*0.1578 -> 0.85586441 | G8: =E_g!G8/(rat_weight!G8/1000)*0.1578 -> 0.75142857 | H8: =E_g!H8/(rat_weight!H8/1000)*0.1578 -> 2.120102 | I8: =E_g!I8/(rat_weight!I8/1000)*0.1578 -> 1.717551 | ... T8: =E_g!T8/(rat_weight!T8/1000)*0.1578 -> 1.2634314
A9: 8 | B9: =E_g!B9/(rat_weight!B9/1000)*0.1578 -> 0.54315217 | C9: =E_g!C9/(rat_weight!C9/1000)*0.1578 -> 0.75755435 | D9: =E_g!D9/(rat_weight!D9/1000)*0.1578 -> 1.0577174 | E9: =E_g!E9/(rat_weight!E9/1000)*0.1578 -> 0.90048913 | F9: =E_g!F9/(rat_weight!F9/1000)*0.1578 -> 0.94336957 | G9: =E_g!G9/(rat_weight!G9/1000)*0.1578 -> 0.53348754 | H9: =E_g!H9/(rat_weight!H9/1000)*0.1578 -> 1.0529359 | I9: =E_g!I9/(rat_weight!I9/1000)*0.1578 -> 0.98274021 | ... T9: =E_g!T9/(rat_weight!T9/1000)*0.1578 -> 0.65866785
A10: 9 | B10: =E_g!B10/(rat_weight!B10/1000)*0.1578 -> 0.073395349 | C10: =E_g!C10/(rat_weight!C10/1000)*0.1578 -> -0.018348837 | D10: =E_g!D10/(rat_weight!D10/1000)*0.1578 -> 0.036697674 | E10: =E_g!E10/(rat_weight!E10/1000)*0.1578 -> -0.018348837 | F10: =E_g!F10/(rat_weight!F10/1000)*0.1578 -> 0.22018605 | G10: =E_g!G10/(rat_weight!G10/1000)*0.1578 -> 0.10427313 | H10: =E_g!H10/(rat_weight!H10/1000)*0.1578 -> 0.017378855 | I10: =E_g!I10/(rat_weight!I10/1000)*0.1578 -> 0.069515419 | ... T10: =E_g!T10/(rat_weight!T10/1000)*0.1578 -> 0.1224612
A11: 10 | B11: =E_g!B11/(rat_weight!B11/1000)*0.1578 -> -1.5709092e-14 | C11: =E_g!C11/(rat_weight!C11/1000)*0.1578 -> -0.013817863 | D11: =E_g!D11/(rat_weight!D11/1000)*0.1578 -> 0.13817863 | E11: =E_g!E11/(rat_weight!E11/1000)*0.1578 -> 0.12436077 | F11: =E_g!F11/(rat_weight!F11/1000)*0.1578 -> 0.027635727 | G11: =E_g!G11/(rat_weight!G11/1000)*0.1578 -> 0.054320138 | H11: =E_g!H11/(rat_weight!H11/1000)*0.1578 -> 0.095060241 | I11: =E_g!I11/(rat_weight!I11/1000)*0.1578 -> 0.13580034 | ... T11: =E_g!T11/(rat_weight!T11/1000)*0.1578 -> 0.14760204
A12: 11 | B12: =E_g!B12/(rat_weight!B12/1000)*0.1578 -> 2.4822472 | C12: =E_g!C12/(rat_weight!C12/1000)*0.1578 -> 2.260618 | D12: =E_g!D12/(rat_weight!D12/1000)*0.1578 -> 2.5708989 | E12: =E_g!E12/(rat_weight!E12/1000)*0.1578 -> 1.9946629 | F12: =E_g!F12/(rat_weight!F12/1000)*0.1578 -> 1.5957303 | G12: =E_g!G12/(rat_weight!G12/1000)*0.1578 -> 2.4486207 | H12: =E_g!H12/(rat_weight!H12/1000)*0.1578 -> 1.8591379 | I12: =E_g!I12/(rat_weight!I12/1000)*0.1578 -> 2.357931 | ... T12: =E_g!T12/(rat_weight!T12/1000)*0.1578 -> 0.40346591
A13: 12 | B13: =E_g!B13/(rat_weight!B13/1000)*0.1578 -> 1.9541796 | C13: =E_g!C13/(rat_weight!C13/1000)*0.1578 -> 1.9297523 | D13: =E_g!D13/(rat_weight!D13/1000)*0.1578 -> 2.2473065 | E13: =E_g!E13/(rat_weight!E13/1000)*0.1578 -> 1.6366254 | F13: =E_g!F13/(rat_weight!F13/1000)*0.1578 -> 2.5404334 | G13: =E_g!G13/(rat_weight!G13/1000)*0.1578 -> 0.94283019 | H13: =E_g!H13/(rat_weight!H13/1000)*0.1578 -> 0.86839623 | I13: =E_g!I13/(rat_weight!I13/1000)*0.1578 -> 1.1413208 | ... T13: =E_g!T13/(rat_weight!T13/1000)*0.1578 -> 0.61257764
A14: 13 | B14: =E_g!B14/(rat_weight!B14/1000)*0.1578 -> 2.2690196 | C14: =E_g!C14/(rat_weight!C14/1000)*0.1578 -> 2.0369608 | D14: =E_g!D14/(rat_weight!D14/1000)*0.1578 -> 2.1143137 | E14: =E_g!E14/(rat_weight!E14/1000)*0.1578 -> 1.727549 | F14: =E_g!F14/(rat_weight!F14/1000)*0.1578 -> 1.3923529 | G14: =E_g!G14/(rat_weight!G14/1000)*0.1578 -> 2.6641558 | H14: =E_g!H14/(rat_weight!H14/1000)*0.1578 -> 2.1774351 | I14: =E_g!I14/(rat_weight!I14/1000)*0.1578 -> 2.9203247 | ... T14: =E_g!T14/(rat_weight!T14/1000)*0.1578 -> 1.0023127
... A61: 60 | B61: =E_g!B61/(rat_weight!B61/1000)*0.1578 -> 1.5912605 | C61: =E_g!C61/(rat_weight!C61/1000)*0.1578 -> 1.604521 | D61: =E_g!D61/(rat_weight!D61/1000)*0.1578 -> 1.5912605 | E61: =E_g!E61/(rat_weight!E61/1000)*0.1578 -> 1.2332269 | F61: =E_g!F61/(rat_weight!F61/1000)*0.1578 -> 1.3790924 | G61: =E_g!G61/(rat_weight!G61/1000)*0.1578 -> 0.94208955 | H61: =E_g!H61/(rat_weight!H61/1000)*0.1578 -> 1.0075124 | I61: =E_g!I61/(rat_weight!I61/1000)*0.1578 -> 1.5701493 | ... T61: =E_g!T61/(rat_weight!T61/1000)*0.1578 -> 1.2505392

Sheet water_ON
A1: ID | B1: 45957 | C1: 45958 | D1: 45959 | E1: 45960 | F1: 45961 | G1: 45964 | H1: 45965 | I1: 45966 | J1: 45967 | K1: 45968 | L1: 45971 | M1: 45972 | N1: 45973 | O1: 45974 | P1: 45975 | Q1: 45978 | R1: 45979 | S1: 45980 | T1: 45981
A2: 1 | B2: 475.1 | C2: 473.3 | D2: 473.2 | E2: 471.9 | F2: 471.8 | G2: 471.6 | H2: 471.4 | I2: 481.1 | J2: 476.7 | K2: 472.6 | L2: 472.2 | M2: 470.5 | N2: 469.5 | O2: 468.5 | P2: 468.2 | Q2: 468 | R2: 464.4 | S2: 464.3 | T2: 463.6
A3: 2 | B3: 468.3 | C3: 468.1 | D3: 467.9 | E3: 467.8 | F3: 467.6 | G3: 467.4 | H3: 467.1 | I3: 482.5 | J3: 482.3 | K3: 482.2 | L3: 481.9 | M3: 481.7 | N3: 481.6 | O3: 481.3 | P3: 481.2 | Q3: 480.9 | R3: 480.8 | S3: 480.6 | T3: 480.4
A4: 3 | B4: 468.5 | C4: 468.2 | D4: 468.1 | E4: 467.9 | F4: 467.8 | G4: 467.6 | H4: 467.3 | I4: 467.1 | J4: 466.9 | K4: 466.4 | L4: 466.3 | M4: 466 | N4: 465.8 | O4: 465.4 | P4: 477.2 | Q4: 476.9 | R4: 476.7 | S4: 476.5 | T4: 476.4
A5: 4 | B5: 478 | C5: 477.8 | D5: 477.6 | E5: 477.4 | F5: 477.3 | G5: 477 | H5: 476.7 | I5: 476.6 | J5: 476.4 | K5: 475.8 | L5: 475.6 | M5: 475.4 | N5: 475.2 | O5: 475 | P5: 474.7 | Q5: 474.4 | R5: 474.2 | S5: 474.1 | T5: 473.9
A6: 5 | B6: 485.6 | C6: 479.6 | D6: 479.3 | E6: 478.6 | F6: 478.5 | G6: 478.3 | H6: 475.8 | I6: 470.9 | J6: 467 | K6: 466.9 | L6: 465.6 | M6: 464.1 | N6: 463.9 | O6: 463.3 | P6: 476.4 | Q6: 475 | R6: 474.6 | S6: 474.4 | T6: 474.2
A7: 6 | B7: 457.3 | C7: 457.1 | D7: 456.9 | E7: 456.6 | F7: 456.5 | G7: 473.5 | H7: 473.3 | I7: 473.2 | J7: 473 | K7: 472.8 | L7: 470.7 | M7: 470.5 | N7: 470.1 | O7: 469.9 | P7: 469.2 | Q7: 468.9 | R7: 468.4 | S7: 466.2 | T7: 466
A8: 7 | B8: 464.8 | C8: 464.5 | D8: 464.4 | E8: 464.2 | F8: 464 | G8: 463.7 | H8: 463.5 | I8: 472.3 | J8: 472 | K8: 471.8 | L8: 471.5 | M8: 471.3 | N8: 471.1 | O8: 470.9 | P8: 470.8 | Q8: 470.5 | R8: 470.2 | S8: 470.1 | T8: 469.8
A9: 8 | B9: 479.5 | C9: 479.2 | D9: 479 | E9: 478.8 | F9: 478.5 | G9: 478.2 | H9: 478.1 | I9: 477.9 | J9: 477.5 | K9: 477.4 | L9: 477.1 | M9: 476.8 | N9: 476.8 | O9: 476.5 | P9: 476.2 | Q9: 475.9 | R9: 475.7 | S9: 475.5 | T9: 475.3
A10: 9 | B10: 481.7 | C10: 478.8 | D10: 477.4 | E10: 472.2 | F10: 472 | G10: 470.8 | H10: 469.5 | I10: 464.3 | J10: 460.5 | K10: 459.1 | L10: 482 | M10: 474.7 | N10: 470.4 | O10: 465.1 | P10: 464.4 | Q10: 460.7 | R10: 454.5 | S10: 454.2 | T10: 449.4
A11: 10 | B11: 472.3 | C11: 471.8 | D11: 470.7 | E11: 468.2 | F11: 466.8 | G11: 466.5 | H11: 463.8 | I11: 478.9 | J11: 476.9 | K11: 476.2 | L11: 467.4 | M11: 466.6 | N11: 464.8 | O11: 460.8 | P11: 475.2 | Q11: 474.1 | R11: 470.4 | S11: 468.3 | T11: 465.8
A12: 11 | B12: 473 | C12: 472.7 | D12: 472.5 | E12: 471.4 | F12: 471.1 | G12: 470.7 | H12: 470.3 | I12: 483 | J12: 482.5 | K12: 482.4 | L12: 482.1 | M12: 481.3 | N12: 481.1 | O12: 480.8 | P12: 480.7 | Q12: 480.3 | R12: 479.2 | S12: 479.1 | T12: 478.4
A13: 12 | B13: 469.5 | C13: 469.3 | D13: 468.7 | E13: 468.5 | F13: 461.9 | G13: 461.5 | H13: 460.9 | I13: 471.1 | J13: 466.8 | K13: 466.7 | L13: 465.4 | M13: 464.9 | N13: 462.8 | O13: 459 | P13: 476.7 | Q13: 476.3 | R13: 471.7 | S13: 469.6 | T13: 467.6
... A61: 60 | B61: 454.2 | C61: 454 | D61: 453.7 | E61: 453.5 | F61: 453.4 | G61: 473.2 | H61: 473.1 | I61: 472.9 | J61: 472.7 | K61: 472.4 | L61: 472.2 | M61: 472 | N61: 471.9 | O61: 471.7 | P61: 471.5 | Q61: 471.1 | R61: 470.9 | S61: 470.7 | T61: 470.5
A62: leak 1 | B62: 456.3 | C62: 456.2 | D62: 456.1 | E62: 455.8 | F62: 455.8 | G62: 476.4 | H62: 476.3 | I62: 476.1 | J62: 475.9 | K62: 475.6 | L62: 475.4 | M62: 475.1 | N62: 474.9 | O62: 474.8 | P62: 474.6 | Q62: 474.3 | R62: 474 | S62: 473.9 | T62: 473.7
A63: leak 2 | B63: 458.3 | C63: 458 | D63: 457.9 | E63: 457.8 | F63: 457.7 | G63: 457.4 | H63: 457.1 | I63: 457 | J63: 456.8 | K63: 456.5 | L63: 456.4 | M63: 455.9 | N63: 455.9 | O63: 455.8 | P63: 455.6 | Q63: 455.4 | R63: 455.2 | S63: 455 | T63: 454.8
A64: 500g calibration weight | B64: 499.9 | C64: 500 | D64: 500 | E64: 500 | F64: 500 | G64: 500 | H64: 500 | I64: 500 | J64: 500 | K64: 500 | L64: 500 | M64: 500 | N64: 500 | O64: 500 | P64: 500 | Q64: 500 | R64: 500 | S64: 500 | T64: 499.9
A65: Scale offset | B65: =500-B64 -> 0.1 | C65: =500-C64 -> 0 | D65: =500-D64 -> 0 | E65: =500-E64 -> 0 | F65: =500-F64 -> 0 | G65: =500-G64 -> 0 | H65: =500-H64 -> 0 | I65: =500-I64 -> 0 | ... T65: =500-T64 -> 0.1

Sheet water_OFF
A1: ID | B1: 45957 | C1: 45958 | D1: 45959 | E1: 45960 | F1: 45961 | G1: 45964 | H1: 45965 | I1: 45966 | J1: 45967 | K1: 45968 | L1: 45971 | M1: 45972 | N1: 45973 | O1: 45974 | P1: 45975 | Q1: 45978 | R1: 45979 | S1: 45980 | T1: 45981
A2: 1 | B2: 473.3 | C2: 473.3 | D2: 472 | E2: 471.9 | F2: 471.8 | G2: 471.4 | H2: 471.2 | I2: 476.8 | J2: 472.7 | K2: 472.4 | L2: 471.2 | M2: 469.5 | N2: 468.4 | O2: 468.2 | P2: 468.2 | Q2: 464.5 | R2: 464.3 | S2: 463.7 | T2: 462.8
A3: 2 | B3: 468.2 | C3: 468 | D3: 467.9 | E3: 467.7 | F3: 467.6 | G3: 467.2 | H3: 466.9 | I3: 482.4 | J3: 482.3 | K3: 482.1 | L3: 481.8 | M3: 481.7 | N3: 481.3 | O3: 481.3 | P3: 481.2 | Q3: 480.9 | R3: 480.7 | S3: 480.6 | T3: 480.3
A4: 3 | B4: 468.3 | C4: 468.2 | D4: 468 | E4: 467.8 | F4: 467.7 | G4: 467.4 | H4: 467.2 | I4: 467 | J4: 466.5 | K4: 466.4 | L4: 466 | M4: 465.8 | N4: 465.5 | O4: 465.3 | P4: 477.1 | Q4: 476.8 | R4: 476.6 | S4: 476.5 | T4: 476.3
A5: 4 | B5: 477.9 | C5: 477.7 | D5: 477.5 | E5: 477.4 | F5: 477.2 | G5: 476.8 | H5: 476.7 | I5: 476.5 | J5: 475.9 | K5: 475.8 | L5: 475.5 | M5: 475.3 | N5: 475.1 | O5: 474.8 | P5: 474.7 | Q5: 474.4 | R5: 474.2 | S5: 474 | T5: 473.9
A6: 5 | B6: 479.7 | C6: 479.5 | D6: 478.7 | E6: 478.6 | F6: 478.5 | G6: 475.8 | H6: 471 | I6: 467.2 | J6: 467 | K6: 465.7 | L6: 464.1 | M6: 464 | N6: 463.3 | O6: 463.2 | P6: 475.2 | Q6: 474.7 | R6: 474.5 | S6: 474.3 | T6: 474.1
A7: 6 | B7: 457.2 | C7: 457 | D7: 456.7 | E7: 456.5 | F7: 456.2 | G7: 473.4 | H7: 473.2 | I7: 473.1 | J7: 472.9 | K7: 470.8 | L7: 470.5 | M7: 470.1 | N7: 469.9 | O7: 469.3 | P7: 469.2 | Q7: 468.5 | R7: 466.2 | S7: 466.1 | T7: 465.6
A8: 7 | B8: 464.6 | C8: 464.4 | D8: 464.3 | E8: 464.1 | F8: 463.8 | G8: 463.5 | H8: 463.3 | I8: 472.1 | J8: 471.9 | K8: 471.6 | L8: 471.4 | M8: 471.1 | N8: 470.9 | O8: 470.8 | P8: 470.7 | Q8: 470.4 | R8: 470.2 | S8: 470 | T8: 469.8
A9: 8 | B9: 479.3 | C9: 479.1 | D9: 478.8 | E9: 478.6 | F9: 478.4 | G9: 478.1 | H9: 478 | I9: 477.7 | J9: 477.5 | K9: 477.2 | L9: 476.9 | M9: 476.8 | N9: 476.5 | O9: 476.3 | P9: 476.1 | Q9: 475.8 | R9: 475.5 | S9: 475.4 | T9: 475.2
A10: 9 | B10: 478.8 | C10: 477.4 | D10: 472.3 | E10: 472 | F10: 470.9 | G10: 469.5 | H10: 464.3 | I10: 460.6 | J10: 459.1 | K10: 455.4 | L10: 474.8 | M10: 470.4 | N10: 465.2 | O10: 464.5 | P10: 460.9 | Q10: 454.6 | R10: 454.2 | S10: 449.5 | T10: 445.9
A11: 10 | B11: 471.8 | C11: 470.8 | D11: 468.3 | E11: 466.9 | F11: 466.7 | G11: 463.8 | H11: 462.9 | I11: 477 | J11: 476.3 | K11: 467.6 | L11: 466.6 | M11: 464.8 | N11: 460.7 | O11: 457.6 | P11: 474.3 | Q11: 470.5 | R11: 468.4 | S11: 465.9 | T11: 463.7
A12: 11 | B12: 472.9 | C12: 472.6 | D12: 471.5 | E12: 471.3 | F12: 470.9 | G12: 470.4 | H12: 469.8 | I12: 482.7 | J12: 482.5 | K12: 482.3 | L12: 481.4 | M12: 481.3 | N12: 480.8 | O12: 480.7 | P12: 480.6 | Q12: 479.4 | R12: 479.2 | S12: 478.6 | T12: 478.1
A13: 12 | B13: 469.4 | C13: 468.8 | D13: 468.7 | E13: 461.9 | F13: 461.7 | G13: 461 | H13: 458.9 | I13: 466.9 | J13: 466.7 | K13: 465.6 | L13: 464.9 | M13: 462.9 | N13: 459 | O13: 458.7 | P13: 476.6 | Q13: 471.9 | R13: 469.7 | S13: 467.7 | T13: 466.2
... A61: 60 | B61: 454.1 | C61: 453.8 | D61: 453.6 | E61: 453.5 | F61: 453.3 | G61: 473.1 | H61: 473.1 | I61: 472.9 | J61: 472.6 | K61: 472.5 | L61: 472.1 | M61: 472 | N61: 471.7 | O61: 471.7 | P61: 471.5 | Q61: 471.1 | R61: 470.9 | S61: 470.7 | T61: 470.5
A62: leak1 | B62: 456.3 | C62: 456.2 | D62: 456 | E62: 455.9 | F62: 455.7 | G62: 476.4 | H62: 476.3 | I62: 476 | J62: 475.8 | K62: 475.6 | L62: 475.2 | M62: 475.1 | N62: 474.9 | O62: 474.7 | P62: 474.6 | Q62: 474.1 | R62: 474 | S62: 473.9 | T62: 473.7
A63: leak2 | B63: 458.1 | C63: 458 | D63: 457.9 | E63: 457.8 | F63: 457.6 | G63: 457.2 | H63: 457.1 | I63: 457 | J63: 456.7 | K63: 456.5 | L63: 456.1 | M63: 456.1 | N63: 455.8 | O63: 455.7 | P63: 455.6 | Q63: 455.3 | R63: 455.1 | S63: 455 | T63: 454.8
A64: 500g calibration weight | B64: 500 | C64: 500 | D64: 500 | E64: 500 | F64: 500 | G64: 500 | H64: 500 | I64: 500 | J64: 500 | K64: 500 | L64: 500 | M64: 500 | N64: 500 | O64: 500 | P64: 500 | Q64: 500 | R64: 500 | S64: 500 | T64: 499.9
A65: Scale offset | B65: =500-B64 -> 0 | C65: =500-C64 -> 0 | D65: =500-D64 -> 0 | E65: =500-E64 -> 0 | F65: =500-F64 -> 0 | G65: =500-G64 -> 0 | H65: =500-H64 -> 0 | I65: =500-I64 -> 0 | ... T65: =500-T64 -> 0.1

Sheet W_g
A1: ID | B1: 45957 | C1: 45958 | D1: 45959 | E1: 45960 | F1: 45961 | G1: 45964 | H1: 45965 | I1: 45966 | J1: 45967 | K1: 45968 | L1: 45971 | M1: 45972 | N1: 45973 | O1: 45974 | P1: 45975 | Q1: 45978 | R1: 45979 | S1: 45980 | T1: 45981
